INFO 2019-02-19 11:07:08,378 [Dummy-1:11940] [apps:41] [urls:<module>] [INFO]- 日志输出测试
DEBUG 2019-02-19 11:07:08,593 [Dummy-1:11940] [django.db.backends:111] [utils:execute] [DEBUG]- (0.000) SELECT @@SQL_AUTO_IS_NULL; args=None
DEBUG 2019-02-19 11:07:08,594 [Dummy-1:11940] [django.db.backends:111] [utils:execute] [DEBUG]- (0.000) SET SESSION TRANSACTION ISOLATION LEVEL READ COMMITTED; args=None
DEBUG 2019-02-19 11:07:08,594 [Dummy-1:11940] [django.db.backends:111] [utils:execute] [DEBUG]- (0.001) SELECT VERSION(); args=None
DEBUG 2019-02-19 11:07:08,709 [Dummy-1:11940] [django.db.backends:111] [utils:execute] [DEBUG]- (0.001) SET SESSION TRANSACTION ISOLATION LEVEL READ COMMITTED; args=None
DEBUG 2019-02-19 11:07:08,712 [Dummy-1:11940] [django.db.backends:111] [utils:execute] [DEBUG]- (0.003) SHOW FULL TABLES; args=None
DEBUG 2019-02-19 11:07:08,721 [Dummy-1:11940] [django.db.backends:111] [utils:execute] [DEBUG]- (0.002) SELECT `django_migrations`.`app`, `django_migrations`.`name` FROM `django_migrations`; args=()
INFO 2019-02-19 11:08:39,626 [Dummy-1:5584] [apps:41] [urls:<module>] [INFO]- 日志输出测试
DEBUG 2019-02-19 11:08:39,828 [Dummy-1:5584] [django.db.backends:111] [utils:execute] [DEBUG]- (0.001) SELECT @@SQL_AUTO_IS_NULL; args=None
DEBUG 2019-02-19 11:08:39,829 [Dummy-1:5584] [django.db.backends:111] [utils:execute] [DEBUG]- (0.000) SET SESSION TRANSACTION ISOLATION LEVEL READ COMMITTED; args=None
DEBUG 2019-02-19 11:08:39,829 [Dummy-1:5584] [django.db.backends:111] [utils:execute] [DEBUG]- (0.000) SELECT VERSION(); args=None
DEBUG 2019-02-19 11:08:39,955 [Dummy-1:5584] [django.db.backends:111] [utils:execute] [DEBUG]- (0.000) SET SESSION TRANSACTION ISOLATION LEVEL READ COMMITTED; args=None
DEBUG 2019-02-19 11:08:39,958 [Dummy-1:5584] [django.db.backends:111] [utils:execute] [DEBUG]- (0.003) SHOW FULL TABLES; args=None
DEBUG 2019-02-19 11:08:39,965 [Dummy-1:5584] [django.db.backends:111] [utils:execute] [DEBUG]- (0.001) SELECT `django_migrations`.`app`, `django_migrations`.`name` FROM `django_migrations`; args=()
INFO 2019-02-19 11:09:00,021 [Dummy-1:21636] [apps:41] [urls:<module>] [INFO]- 日志输出测试
DEBUG 2019-02-19 11:09:00,217 [Dummy-1:21636] [django.db.backends:111] [utils:execute] [DEBUG]- (0.001) SELECT @@SQL_AUTO_IS_NULL; args=None
DEBUG 2019-02-19 11:09:00,218 [Dummy-1:21636] [django.db.backends:111] [utils:execute] [DEBUG]- (0.000) SET SESSION TRANSACTION ISOLATION LEVEL READ COMMITTED; args=None
DEBUG 2019-02-19 11:09:00,218 [Dummy-1:21636] [django.db.backends:111] [utils:execute] [DEBUG]- (0.000) SELECT VERSION(); args=None
DEBUG 2019-02-19 11:09:00,328 [Dummy-1:21636] [django.db.backends:111] [utils:execute] [DEBUG]- (0.000) SET SESSION TRANSACTION ISOLATION LEVEL READ COMMITTED; args=None
DEBUG 2019-02-19 11:09:00,330 [Dummy-1:21636] [django.db.backends:111] [utils:execute] [DEBUG]- (0.002) SHOW FULL TABLES; args=None
DEBUG 2019-02-19 11:09:00,338 [Dummy-1:21636] [django.db.backends:111] [utils:execute] [DEBUG]- (0.002) SELECT `django_migrations`.`app`, `django_migrations`.`name` FROM `django_migrations`; args=()
DEBUG 2019-02-19 11:09:55,178 [Dummy-6:9968] [django.db.backends:111] [utils:execute] [DEBUG]- (0.002) SELECT @@SQL_AUTO_IS_NULL; args=None
DEBUG 2019-02-19 11:09:55,180 [Dummy-6:9968] [django.db.backends:111] [utils:execute] [DEBUG]- (0.000) SET SESSION TRANSACTION ISOLATION LEVEL READ COMMITTED; args=None
DEBUG 2019-02-19 11:09:55,182 [Dummy-6:9968] [django.db.backends:111] [utils:execute] [DEBUG]- (0.001) SELECT VERSION(); args=None
INFO 2019-02-19 11:09:56,459 [Dummy-6:9968] [apps:41] [urls:<module>] [INFO]- 日志输出测试
DEBUG 2019-02-19 11:09:56,856 [Dummy-6:9968] [django.db.backends:111] [utils:execute] [DEBUG]- (0.000) SET SESSION TRANSACTION ISOLATION LEVEL READ COMMITTED; args=None
DEBUG 2019-02-19 11:09:56,860 [Dummy-6:9968] [django.db.backends:111] [utils:execute] [DEBUG]- (0.004) SHOW FULL TABLES; args=None
DEBUG 2019-02-19 11:09:56,871 [Dummy-6:9968] [django.db.backends:111] [utils:execute] [DEBUG]- (0.002) SELECT `django_migrations`.`app`, `django_migrations`.`name` FROM `django_migrations`; args=()
DEBUG 2019-02-19 11:10:15,989 [Dummy-6:15868] [django.db.backends:111] [utils:execute] [DEBUG]- (0.001) SELECT @@SQL_AUTO_IS_NULL; args=None
DEBUG 2019-02-19 11:10:15,990 [Dummy-6:15868] [django.db.backends:111] [utils:execute] [DEBUG]- (0.001) SET SESSION TRANSACTION ISOLATION LEVEL READ COMMITTED; args=None
DEBUG 2019-02-19 11:10:15,992 [Dummy-6:15868] [django.db.backends:111] [utils:execute] [DEBUG]- (0.000) SELECT VERSION(); args=None
DEBUG 2019-02-19 11:10:17,859 [Dummy-6:15868] [django.db.backends:111] [utils:execute] [DEBUG]- (0.001) SET SESSION TRANSACTION ISOLATION LEVEL READ COMMITTED; args=None
DEBUG 2019-02-19 11:10:17,864 [Dummy-6:15868] [django.db.backends:111] [utils:execute] [DEBUG]- (0.005) SHOW FULL TABLES; args=None
DEBUG 2019-02-19 11:10:17,877 [Dummy-6:15868] [django.db.backends:111] [utils:execute] [DEBUG]- (0.003) SELECT `django_migrations`.`app`, `django_migrations`.`name` FROM `django_migrations`; args=()
DEBUG 2019-02-19 11:10:37,575 [Thread-7:8784] [django.db.backends:111] [utils:execute] [DEBUG]- (0.002) SELECT @@SQL_AUTO_IS_NULL; args=None
DEBUG 2019-02-19 11:10:37,578 [Thread-7:8784] [django.db.backends:111] [utils:execute] [DEBUG]- (0.002) SET SESSION TRANSACTION ISOLATION LEVEL READ COMMITTED; args=None
DEBUG 2019-02-19 11:10:37,581 [Thread-7:8784] [django.db.backends:111] [utils:execute] [DEBUG]- (0.002) SELECT VERSION(); args=None
DEBUG 2019-02-19 11:10:37,589 [Thread-7:8784] [django.db.backends:111] [utils:execute] [DEBUG]- (0.001) SET SESSION TRANSACTION ISOLATION LEVEL READ COMMITTED; args=None
DEBUG 2019-02-19 11:10:37,594 [Thread-7:8784] [django.db.backends:111] [utils:execute] [DEBUG]- (0.003) SELECT `django_session`.`session_key`, `django_session`.`session_data`, `django_session`.`expire_date` FROM `django_session` WHERE (`django_session`.`session_key` = '0u5rozh3lc5qezdhht6wcg9rg9gi21ko' AND `django_session`.`expire_date` > '2019-02-19 11:10:37.543331'); args=('0u5rozh3lc5qezdhht6wcg9rg9gi21ko', '2019-02-19 11:10:37.543331')
DEBUG 2019-02-19 11:10:37,617 [Thread-7:8784] [django.db.backends:111] [utils:execute] [DEBUG]- (0.008) SELECT `repository_userprofile`.`password`, `repository_userprofile`.`last_login`, `repository_userprofile`.`is_superuser`, `repository_userprofile`.`username`, `repository_userprofile`.`first_name`, `repository_userprofile`.`last_name`, `repository_userprofile`.`email`, `repository_userprofile`.`is_staff`, `repository_userprofile`.`is_active`, `repository_userprofile`.`date_joined`, `repository_userprofile`.`id`, `repository_userprofile`.`nick_name`, `repository_userprofile`.`create_time`, `repository_userprofile`.`image`, `repository_userprofile`.`models_introdoction`, `repository_userprofile`.`is_admin`, `repository_userprofile`.`is_approver` FROM `repository_userprofile` WHERE `repository_userprofile`.`id` = 1; args=(1,)
INFO 2019-02-19 11:10:37,641 [Thread-7:8784] [django:60] [AddfileView:post] [INFO]- user
DEBUG 2019-02-19 11:10:37,651 [Thread-7:8784] [django.db.backends:111] [utils:execute] [DEBUG]- (0.006) SELECT `repository_userprofile`.`password`, `repository_userprofile`.`last_login`, `repository_userprofile`.`is_superuser`, `repository_userprofile`.`username`, `repository_userprofile`.`first_name`, `repository_userprofile`.`last_name`, `repository_userprofile`.`email`, `repository_userprofile`.`is_staff`, `repository_userprofile`.`is_active`, `repository_userprofile`.`date_joined`, `repository_userprofile`.`id`, `repository_userprofile`.`nick_name`, `repository_userprofile`.`create_time`, `repository_userprofile`.`image`, `repository_userprofile`.`models_introdoction`, `repository_userprofile`.`is_admin`, `repository_userprofile`.`is_approver` FROM `repository_userprofile` WHERE `repository_userprofile`.`id` = 1 LIMIT 1; args=(1,)
DEBUG 2019-02-19 11:10:37,723 [Thread-7:8784] [django.db.backends:111] [utils:execute] [DEBUG]- (0.002) SELECT `repository_u2d`.`id`, `repository_u2d`.`user_id`, `repository_u2d`.`dep_id` FROM `repository_u2d` WHERE `repository_u2d`.`user_id` = 1 LIMIT 21; args=(1,)
DEBUG 2019-02-19 11:10:37,747 [Thread-7:8784] [django.db.backends:111] [utils:execute] [DEBUG]- (0.004) SELECT `repository_u2d`.`id`, `repository_u2d`.`user_id`, `repository_u2d`.`dep_id` FROM `repository_u2d` WHERE `repository_u2d`.`user_id` = 1 LIMIT 21; args=(1,)
DEBUG 2019-02-19 11:10:37,755 [Thread-7:8784] [django.db.backends:111] [utils:execute] [DEBUG]- (0.003) SELECT `repository_u2d`.`id`, `repository_u2d`.`user_id`, `repository_u2d`.`dep_id` FROM `repository_u2d` WHERE `repository_u2d`.`user_id` = 1 LIMIT 21; args=(1,)
DEBUG 2019-02-19 11:10:37,778 [Thread-7:8784] [django.db.backends:111] [utils:execute] [DEBUG]- (0.004) SELECT `repository_u2d`.`id`, `repository_u2d`.`user_id`, `repository_u2d`.`dep_id` FROM `repository_u2d` WHERE `repository_u2d`.`user_id` = 1 LIMIT 21; args=(1,)
INFO 2019-02-19 11:10:37,856 [Thread-7:8784] [django:78] [AddfileView:post] [INFO]- 添加文件
INFO 2019-02-19 11:10:37,858 [Thread-7:8784] [django:79] [AddfileView:post] [INFO]- ********************
INFO 2019-02-19 11:10:37,872 [Thread-7:8784] [django:80] [AddfileView:post] [INFO]- <QueryDict: {'filename': ['test'], 'dep': ['信息部'], 'filedes': ['shangchaun ceshi '], 'filetype': ['内部'], 'fileproject': ['测试项目2'], 'csrfmiddlewaretoken': ['BMFAXLlOlOmpgGGhClhHpljy7XB2MZvP8ploPf5hDZbUp2Y0HFY4N74ZJIqJ86Fr']}>
DEBUG 2019-02-19 11:10:38,351 [Thread-12:13756] [django.db.backends:111] [utils:execute] [DEBUG]- (0.005) SELECT @@SQL_AUTO_IS_NULL; args=None
DEBUG 2019-02-19 11:10:38,355 [Thread-12:13756] [django.db.backends:111] [utils:execute] [DEBUG]- (0.001) SET SESSION TRANSACTION ISOLATION LEVEL READ COMMITTED; args=None
DEBUG 2019-02-19 11:10:38,364 [Thread-12:13756] [django.db.backends:111] [utils:execute] [DEBUG]- (0.005) SELECT VERSION(); args=None
DEBUG 2019-02-19 11:10:38,385 [Thread-12:13756] [django.db.backends:111] [utils:execute] [DEBUG]- (0.002) SET SESSION TRANSACTION ISOLATION LEVEL READ COMMITTED; args=None
DEBUG 2019-02-19 11:10:38,392 [Thread-12:13756] [django.db.backends:111] [utils:execute] [DEBUG]- (0.006) SELECT `repository_u2d`.`id`, `repository_u2d`.`user_id`, `repository_u2d`.`dep_id` FROM `repository_u2d` WHERE `repository_u2d`.`user_id` = 1 LIMIT 21; args=(1,)
DEBUG 2019-02-19 11:10:52,425 [Thread-18:9732] [django.db.backends:111] [utils:execute] [DEBUG]- (0.005) SELECT @@SQL_AUTO_IS_NULL; args=None
DEBUG 2019-02-19 11:10:52,429 [Thread-18:9732] [django.db.backends:111] [utils:execute] [DEBUG]- (0.001) SET SESSION TRANSACTION ISOLATION LEVEL READ COMMITTED; args=None
DEBUG 2019-02-19 11:10:52,434 [Thread-18:9732] [django.db.backends:111] [utils:execute] [DEBUG]- (0.003) SELECT VERSION(); args=None
DEBUG 2019-02-19 11:10:52,450 [Thread-18:9732] [django.db.backends:111] [utils:execute] [DEBUG]- (0.001) SET SESSION TRANSACTION ISOLATION LEVEL READ COMMITTED; args=None
DEBUG 2019-02-19 11:10:52,458 [Thread-18:9732] [django.db.backends:111] [utils:execute] [DEBUG]- (0.006) SELECT `repository_u2d`.`id`, `repository_u2d`.`user_id`, `repository_u2d`.`dep_id` FROM `repository_u2d` WHERE `repository_u2d`.`user_id` = 1 LIMIT 21; args=(1,)
DEBUG 2019-02-19 11:10:53,207 [Thread-24:19592] [django.db.backends:111] [utils:execute] [DEBUG]- (0.004) SELECT @@SQL_AUTO_IS_NULL; args=None
DEBUG 2019-02-19 11:10:53,211 [Thread-24:19592] [django.db.backends:111] [utils:execute] [DEBUG]- (0.001) SET SESSION TRANSACTION ISOLATION LEVEL READ COMMITTED; args=None
DEBUG 2019-02-19 11:10:53,216 [Thread-24:19592] [django.db.backends:111] [utils:execute] [DEBUG]- (0.003) SELECT VERSION(); args=None
DEBUG 2019-02-19 11:10:53,231 [Thread-24:19592] [django.db.backends:111] [utils:execute] [DEBUG]- (0.001) SET SESSION TRANSACTION ISOLATION LEVEL READ COMMITTED; args=None
DEBUG 2019-02-19 11:10:53,240 [Thread-24:19592] [django.db.backends:111] [utils:execute] [DEBUG]- (0.007) SELECT `repository_u2d`.`id`, `repository_u2d`.`user_id`, `repository_u2d`.`dep_id` FROM `repository_u2d` WHERE `repository_u2d`.`user_id` = 1 LIMIT 21; args=(1,)
DEBUG 2019-02-19 11:11:21,555 [Dummy-6:21072] [django.db.backends:111] [utils:execute] [DEBUG]- (0.001) SELECT @@SQL_AUTO_IS_NULL; args=None
DEBUG 2019-02-19 11:11:21,557 [Dummy-6:21072] [django.db.backends:111] [utils:execute] [DEBUG]- (0.001) SET SESSION TRANSACTION ISOLATION LEVEL READ COMMITTED; args=None
DEBUG 2019-02-19 11:11:21,558 [Dummy-6:21072] [django.db.backends:111] [utils:execute] [DEBUG]- (0.001) SELECT VERSION(); args=None
DEBUG 2019-02-19 11:11:23,564 [Dummy-6:21072] [django.db.backends:111] [utils:execute] [DEBUG]- (0.001) SET SESSION TRANSACTION ISOLATION LEVEL READ COMMITTED; args=None
DEBUG 2019-02-19 11:11:23,568 [Dummy-6:21072] [django.db.backends:111] [utils:execute] [DEBUG]- (0.004) SHOW FULL TABLES; args=None
DEBUG 2019-02-19 11:11:23,578 [Dummy-6:21072] [django.db.backends:111] [utils:execute] [DEBUG]- (0.002) SELECT `django_migrations`.`app`, `django_migrations`.`name` FROM `django_migrations`; args=()
DEBUG 2019-02-19 11:11:24,064 [Thread-7:4812] [django.db.backends:111] [utils:execute] [DEBUG]- (0.002) SELECT @@SQL_AUTO_IS_NULL; args=None
DEBUG 2019-02-19 11:11:24,066 [Thread-7:4812] [django.db.backends:111] [utils:execute] [DEBUG]- (0.001) SET SESSION TRANSACTION ISOLATION LEVEL READ COMMITTED; args=None
DEBUG 2019-02-19 11:11:24,069 [Thread-7:4812] [django.db.backends:111] [utils:execute] [DEBUG]- (0.002) SELECT VERSION(); args=None
DEBUG 2019-02-19 11:11:24,076 [Thread-7:4812] [django.db.backends:111] [utils:execute] [DEBUG]- (0.000) SET SESSION TRANSACTION ISOLATION LEVEL READ COMMITTED; args=None
DEBUG 2019-02-19 11:11:24,081 [Thread-7:4812] [django.db.backends:111] [utils:execute] [DEBUG]- (0.003) SELECT `django_session`.`session_key`, `django_session`.`session_data`, `django_session`.`expire_date` FROM `django_session` WHERE (`django_session`.`session_key` = '0u5rozh3lc5qezdhht6wcg9rg9gi21ko' AND `django_session`.`expire_date` > '2019-02-19 11:11:24.040815'); args=('0u5rozh3lc5qezdhht6wcg9rg9gi21ko', '2019-02-19 11:11:24.040815')
DEBUG 2019-02-19 11:11:24,103 [Thread-7:4812] [django.db.backends:111] [utils:execute] [DEBUG]- (0.008) SELECT `repository_userprofile`.`password`, `repository_userprofile`.`last_login`, `repository_userprofile`.`is_superuser`, `repository_userprofile`.`username`, `repository_userprofile`.`first_name`, `repository_userprofile`.`last_name`, `repository_userprofile`.`email`, `repository_userprofile`.`is_staff`, `repository_userprofile`.`is_active`, `repository_userprofile`.`date_joined`, `repository_userprofile`.`id`, `repository_userprofile`.`nick_name`, `repository_userprofile`.`create_time`, `repository_userprofile`.`image`, `repository_userprofile`.`models_introdoction`, `repository_userprofile`.`is_admin`, `repository_userprofile`.`is_approver` FROM `repository_userprofile` WHERE `repository_userprofile`.`id` = 1; args=(1,)
DEBUG 2019-02-19 11:11:24,353 [Thread-7:4812] [django.db.backends:111] [utils:execute] [DEBUG]- (0.003) SELECT `repository_dep`.`nid`, `repository_dep`.`title` FROM `repository_dep` LIMIT 21; args=()
DEBUG 2019-02-19 11:11:24,358 [Thread-7:4812] [django.db.backends:111] [utils:execute] [DEBUG]- (0.002) SELECT `repository_projectmodel`.`nid`, `repository_projectmodel`.`Project_name` FROM `repository_projectmodel` LIMIT 21; args=()
DEBUG 2019-02-19 11:11:24,369 [Thread-7:4812] [django.db.backends:111] [utils:execute] [DEBUG]- (0.003) SELECT `repository_dep`.`nid`, `repository_dep`.`title` FROM `repository_dep` LIMIT 21; args=()
DEBUG 2019-02-19 11:11:24,374 [Thread-7:4812] [django.db.backends:111] [utils:execute] [DEBUG]- (0.002) SELECT `repository_projectmodel`.`nid`, `repository_projectmodel`.`Project_name` FROM `repository_projectmodel` LIMIT 21; args=()
DEBUG 2019-02-19 11:11:24,435 [Thread-7:4812] [django.db.backends:111] [utils:execute] [DEBUG]- (0.002) SELECT `repository_dep`.`nid`, `repository_dep`.`title` FROM `repository_dep`; args=()
DEBUG 2019-02-19 11:11:24,441 [Thread-7:4812] [django.db.backends:111] [utils:execute] [DEBUG]- (0.002) SELECT `repository_projectmodel`.`nid`, `repository_projectmodel`.`Project_name` FROM `repository_projectmodel`; args=()
INFO 2019-02-19 11:11:24,462 [Thread-7:4812] [django.server:124] [basehttp:log_message] [INFO]- "GET /sharefile/addfile/ HTTP/1.1" 200 22974
DEBUG 2019-02-19 11:11:24,670 [Thread-8:18884] [django.template:878] [base:_resolve_lookup] [DEBUG]- Exception while resolving variable 'name' in template 'unknown'.
Traceback (most recent call last):
  File "C:\Python\Webproject\share2\env\lib\site-packages\django\core\handlers\exception.py", line 35, in inner
    response = get_response(request)
  File "C:\Python\Webproject\share2\env\lib\site-packages\django\core\handlers\base.py", line 113, in _get_response
    resolver_match = resolver.resolve(request.path_info)
  File "C:\Python\Webproject\share2\env\lib\site-packages\django\urls\resolvers.py", line 523, in resolve
    raise Resolver404({'tried': tried, 'path': new_path})
django.urls.exceptions.Resolver404: {'tried': [[<URLResolver <URLPattern list> (xadmin:xadmin) 'xadmin/'>], [<URLPattern '^$' [name='index']>], [<URLPattern 'index/' [name='index']>], [<URLPattern 'test/' [name='test']>], [<URLPattern 'login/' [name='login']>], [<URLPattern 'logout/' [name='logout']>], [<URLPattern 'register/' [name='register']>], [<URLPattern 'forget/' [name='forget_pwd']>], [<URLPattern 'reset/(?P<active_code>.*)/' [name='reset_pwd']>], [<URLPattern 'modify_pwd/' [name='modify_pwd']>], [<URLResolver <module 'captcha.urls' from 'C:\\Python\\Webproject\\share2\\env\\lib\\site-packages\\captcha\\urls.py'> (None:None) 'captcha/'>], [<URLPattern 'active/(?P<active_code>.*)/' [name='user_active']>], [<URLResolver <module 'sharefile.urls' from 'C:\\Python\\Webproject\\share2\\share2\\share2\\apps\\sharefile\\urls.py'> (sharefile:sharefile) 'sharefile/'>], [<URLResolver <module 'users.urls' from 'C:\\Python\\Webproject\\share2\\share2\\share2\\apps\\users\\urls.py'> (users:users) 'users/'>], [<URLPattern 'media/(?P<path>.*)$'>]], 'path': 'assets/images/custom-select.png'}

During handling of the above exception, another exception occurred:

Traceback (most recent call last):
  File "C:\Python\Webproject\share2\env\lib\site-packages\django\template\base.py", line 835, in _resolve_lookup
    current = current[bit]
TypeError: 'URLResolver' object is not subscriptable

During handling of the above exception, another exception occurred:

Traceback (most recent call last):
  File "C:\Python\Webproject\share2\env\lib\site-packages\django\template\base.py", line 843, in _resolve_lookup
    current = getattr(current, bit)
AttributeError: 'URLResolver' object has no attribute 'name'

During handling of the above exception, another exception occurred:

Traceback (most recent call last):
  File "C:\Python\Webproject\share2\env\lib\site-packages\django\template\base.py", line 849, in _resolve_lookup
    current = current[int(bit)]
ValueError: invalid literal for int() with base 10: 'name'

During handling of the above exception, another exception occurred:

Traceback (most recent call last):
  File "C:\Python\Webproject\share2\env\lib\site-packages\django\template\base.py", line 856, in _resolve_lookup
    (bit, current))  # missing attribute
django.template.base.VariableDoesNotExist: Failed lookup for key [name] in <URLResolver <URLPattern list> (xadmin:xadmin) 'xadmin/'>
DEBUG 2019-02-19 11:11:24,689 [Thread-8:18884] [django.template:878] [base:_resolve_lookup] [DEBUG]- Exception while resolving variable 'name' in template 'unknown'.
Traceback (most recent call last):
  File "C:\Python\Webproject\share2\env\lib\site-packages\django\core\handlers\exception.py", line 35, in inner
    response = get_response(request)
  File "C:\Python\Webproject\share2\env\lib\site-packages\django\core\handlers\base.py", line 113, in _get_response
    resolver_match = resolver.resolve(request.path_info)
  File "C:\Python\Webproject\share2\env\lib\site-packages\django\urls\resolvers.py", line 523, in resolve
    raise Resolver404({'tried': tried, 'path': new_path})
django.urls.exceptions.Resolver404: {'tried': [[<URLResolver <URLPattern list> (xadmin:xadmin) 'xadmin/'>], [<URLPattern '^$' [name='index']>], [<URLPattern 'index/' [name='index']>], [<URLPattern 'test/' [name='test']>], [<URLPattern 'login/' [name='login']>], [<URLPattern 'logout/' [name='logout']>], [<URLPattern 'register/' [name='register']>], [<URLPattern 'forget/' [name='forget_pwd']>], [<URLPattern 'reset/(?P<active_code>.*)/' [name='reset_pwd']>], [<URLPattern 'modify_pwd/' [name='modify_pwd']>], [<URLResolver <module 'captcha.urls' from 'C:\\Python\\Webproject\\share2\\env\\lib\\site-packages\\captcha\\urls.py'> (None:None) 'captcha/'>], [<URLPattern 'active/(?P<active_code>.*)/' [name='user_active']>], [<URLResolver <module 'sharefile.urls' from 'C:\\Python\\Webproject\\share2\\share2\\share2\\apps\\sharefile\\urls.py'> (sharefile:sharefile) 'sharefile/'>], [<URLResolver <module 'users.urls' from 'C:\\Python\\Webproject\\share2\\share2\\share2\\apps\\users\\urls.py'> (users:users) 'users/'>], [<URLPattern 'media/(?P<path>.*)$'>]], 'path': 'assets/images/custom-select.png'}

During handling of the above exception, another exception occurred:

Traceback (most recent call last):
  File "C:\Python\Webproject\share2\env\lib\site-packages\django\template\base.py", line 835, in _resolve_lookup
    current = current[bit]
TypeError: 'URLResolver' object is not subscriptable

During handling of the above exception, another exception occurred:

Traceback (most recent call last):
  File "C:\Python\Webproject\share2\env\lib\site-packages\django\template\base.py", line 843, in _resolve_lookup
    current = getattr(current, bit)
AttributeError: 'URLResolver' object has no attribute 'name'

During handling of the above exception, another exception occurred:

Traceback (most recent call last):
  File "C:\Python\Webproject\share2\env\lib\site-packages\django\template\base.py", line 849, in _resolve_lookup
    current = current[int(bit)]
ValueError: invalid literal for int() with base 10: 'name'

During handling of the above exception, another exception occurred:

Traceback (most recent call last):
  File "C:\Python\Webproject\share2\env\lib\site-packages\django\template\base.py", line 856, in _resolve_lookup
    (bit, current))  # missing attribute
django.template.base.VariableDoesNotExist: Failed lookup for key [name] in <URLResolver <module 'captcha.urls' from 'C:\\Python\\Webproject\\share2\\env\\lib\\site-packages\\captcha\\urls.py'> (None:None) 'captcha/'>
DEBUG 2019-02-19 11:11:24,705 [Thread-8:18884] [django.template:878] [base:_resolve_lookup] [DEBUG]- Exception while resolving variable 'name' in template 'unknown'.
Traceback (most recent call last):
  File "C:\Python\Webproject\share2\env\lib\site-packages\django\core\handlers\exception.py", line 35, in inner
    response = get_response(request)
  File "C:\Python\Webproject\share2\env\lib\site-packages\django\core\handlers\base.py", line 113, in _get_response
    resolver_match = resolver.resolve(request.path_info)
  File "C:\Python\Webproject\share2\env\lib\site-packages\django\urls\resolvers.py", line 523, in resolve
    raise Resolver404({'tried': tried, 'path': new_path})
django.urls.exceptions.Resolver404: {'tried': [[<URLResolver <URLPattern list> (xadmin:xadmin) 'xadmin/'>], [<URLPattern '^$' [name='index']>], [<URLPattern 'index/' [name='index']>], [<URLPattern 'test/' [name='test']>], [<URLPattern 'login/' [name='login']>], [<URLPattern 'logout/' [name='logout']>], [<URLPattern 'register/' [name='register']>], [<URLPattern 'forget/' [name='forget_pwd']>], [<URLPattern 'reset/(?P<active_code>.*)/' [name='reset_pwd']>], [<URLPattern 'modify_pwd/' [name='modify_pwd']>], [<URLResolver <module 'captcha.urls' from 'C:\\Python\\Webproject\\share2\\env\\lib\\site-packages\\captcha\\urls.py'> (None:None) 'captcha/'>], [<URLPattern 'active/(?P<active_code>.*)/' [name='user_active']>], [<URLResolver <module 'sharefile.urls' from 'C:\\Python\\Webproject\\share2\\share2\\share2\\apps\\sharefile\\urls.py'> (sharefile:sharefile) 'sharefile/'>], [<URLResolver <module 'users.urls' from 'C:\\Python\\Webproject\\share2\\share2\\share2\\apps\\users\\urls.py'> (users:users) 'users/'>], [<URLPattern 'media/(?P<path>.*)$'>]], 'path': 'assets/images/custom-select.png'}

During handling of the above exception, another exception occurred:

Traceback (most recent call last):
  File "C:\Python\Webproject\share2\env\lib\site-packages\django\template\base.py", line 835, in _resolve_lookup
    current = current[bit]
TypeError: 'URLResolver' object is not subscriptable

During handling of the above exception, another exception occurred:

Traceback (most recent call last):
  File "C:\Python\Webproject\share2\env\lib\site-packages\django\template\base.py", line 843, in _resolve_lookup
    current = getattr(current, bit)
AttributeError: 'URLResolver' object has no attribute 'name'

During handling of the above exception, another exception occurred:

Traceback (most recent call last):
  File "C:\Python\Webproject\share2\env\lib\site-packages\django\template\base.py", line 849, in _resolve_lookup
    current = current[int(bit)]
ValueError: invalid literal for int() with base 10: 'name'

During handling of the above exception, another exception occurred:

Traceback (most recent call last):
  File "C:\Python\Webproject\share2\env\lib\site-packages\django\template\base.py", line 856, in _resolve_lookup
    (bit, current))  # missing attribute
django.template.base.VariableDoesNotExist: Failed lookup for key [name] in <URLResolver <module 'sharefile.urls' from 'C:\\Python\\Webproject\\share2\\share2\\share2\\apps\\sharefile\\urls.py'> (sharefile:sharefile) 'sharefile/'>
DEBUG 2019-02-19 11:11:24,715 [Thread-8:18884] [django.template:878] [base:_resolve_lookup] [DEBUG]- Exception while resolving variable 'name' in template 'unknown'.
Traceback (most recent call last):
  File "C:\Python\Webproject\share2\env\lib\site-packages\django\core\handlers\exception.py", line 35, in inner
    response = get_response(request)
  File "C:\Python\Webproject\share2\env\lib\site-packages\django\core\handlers\base.py", line 113, in _get_response
    resolver_match = resolver.resolve(request.path_info)
  File "C:\Python\Webproject\share2\env\lib\site-packages\django\urls\resolvers.py", line 523, in resolve
    raise Resolver404({'tried': tried, 'path': new_path})
django.urls.exceptions.Resolver404: {'tried': [[<URLResolver <URLPattern list> (xadmin:xadmin) 'xadmin/'>], [<URLPattern '^$' [name='index']>], [<URLPattern 'index/' [name='index']>], [<URLPattern 'test/' [name='test']>], [<URLPattern 'login/' [name='login']>], [<URLPattern 'logout/' [name='logout']>], [<URLPattern 'register/' [name='register']>], [<URLPattern 'forget/' [name='forget_pwd']>], [<URLPattern 'reset/(?P<active_code>.*)/' [name='reset_pwd']>], [<URLPattern 'modify_pwd/' [name='modify_pwd']>], [<URLResolver <module 'captcha.urls' from 'C:\\Python\\Webproject\\share2\\env\\lib\\site-packages\\captcha\\urls.py'> (None:None) 'captcha/'>], [<URLPattern 'active/(?P<active_code>.*)/' [name='user_active']>], [<URLResolver <module 'sharefile.urls' from 'C:\\Python\\Webproject\\share2\\share2\\share2\\apps\\sharefile\\urls.py'> (sharefile:sharefile) 'sharefile/'>], [<URLResolver <module 'users.urls' from 'C:\\Python\\Webproject\\share2\\share2\\share2\\apps\\users\\urls.py'> (users:users) 'users/'>], [<URLPattern 'media/(?P<path>.*)$'>]], 'path': 'assets/images/custom-select.png'}

During handling of the above exception, another exception occurred:

Traceback (most recent call last):
  File "C:\Python\Webproject\share2\env\lib\site-packages\django\template\base.py", line 835, in _resolve_lookup
    current = current[bit]
TypeError: 'URLResolver' object is not subscriptable

During handling of the above exception, another exception occurred:

Traceback (most recent call last):
  File "C:\Python\Webproject\share2\env\lib\site-packages\django\template\base.py", line 843, in _resolve_lookup
    current = getattr(current, bit)
AttributeError: 'URLResolver' object has no attribute 'name'

During handling of the above exception, another exception occurred:

Traceback (most recent call last):
  File "C:\Python\Webproject\share2\env\lib\site-packages\django\template\base.py", line 849, in _resolve_lookup
    current = current[int(bit)]
ValueError: invalid literal for int() with base 10: 'name'

During handling of the above exception, another exception occurred:

Traceback (most recent call last):
  File "C:\Python\Webproject\share2\env\lib\site-packages\django\template\base.py", line 856, in _resolve_lookup
    (bit, current))  # missing attribute
django.template.base.VariableDoesNotExist: Failed lookup for key [name] in <URLResolver <module 'users.urls' from 'C:\\Python\\Webproject\\share2\\share2\\share2\\apps\\users\\urls.py'> (users:users) 'users/'>
WARNING 2019-02-19 11:11:24,749 [Thread-8:18884] [django.server:124] [basehttp:log_message] [WARNING]- "GET /assets/images/custom-select.png HTTP/1.1" 404 3763
DEBUG 2019-02-19 11:11:34,946 [Thread-13:20224] [django.db.backends:111] [utils:execute] [DEBUG]- (0.003) SELECT @@SQL_AUTO_IS_NULL; args=None
DEBUG 2019-02-19 11:11:34,951 [Thread-13:20224] [django.db.backends:111] [utils:execute] [DEBUG]- (0.001) SET SESSION TRANSACTION ISOLATION LEVEL READ COMMITTED; args=None
DEBUG 2019-02-19 11:11:34,954 [Thread-13:20224] [django.db.backends:111] [utils:execute] [DEBUG]- (0.002) SELECT VERSION(); args=None
DEBUG 2019-02-19 11:11:34,966 [Thread-13:20224] [django.db.backends:111] [utils:execute] [DEBUG]- (0.001) SET SESSION TRANSACTION ISOLATION LEVEL READ COMMITTED; args=None
DEBUG 2019-02-19 11:11:34,971 [Thread-13:20224] [django.db.backends:111] [utils:execute] [DEBUG]- (0.004) SELECT `django_session`.`session_key`, `django_session`.`session_data`, `django_session`.`expire_date` FROM `django_session` WHERE (`django_session`.`session_key` = '0u5rozh3lc5qezdhht6wcg9rg9gi21ko' AND `django_session`.`expire_date` > '2019-02-19 11:11:34.926683'); args=('0u5rozh3lc5qezdhht6wcg9rg9gi21ko', '2019-02-19 11:11:34.926683')
DEBUG 2019-02-19 11:11:34,991 [Thread-13:20224] [django.db.backends:111] [utils:execute] [DEBUG]- (0.010) SELECT `repository_userprofile`.`password`, `repository_userprofile`.`last_login`, `repository_userprofile`.`is_superuser`, `repository_userprofile`.`username`, `repository_userprofile`.`first_name`, `repository_userprofile`.`last_name`, `repository_userprofile`.`email`, `repository_userprofile`.`is_staff`, `repository_userprofile`.`is_active`, `repository_userprofile`.`date_joined`, `repository_userprofile`.`id`, `repository_userprofile`.`nick_name`, `repository_userprofile`.`create_time`, `repository_userprofile`.`image`, `repository_userprofile`.`models_introdoction`, `repository_userprofile`.`is_admin`, `repository_userprofile`.`is_approver` FROM `repository_userprofile` WHERE `repository_userprofile`.`id` = 1; args=(1,)
INFO 2019-02-19 11:11:35,025 [Thread-13:20224] [django:60] [AddfileView:post] [INFO]- user
DEBUG 2019-02-19 11:11:35,042 [Thread-13:20224] [django.db.backends:111] [utils:execute] [DEBUG]- (0.010) SELECT `repository_userprofile`.`password`, `repository_userprofile`.`last_login`, `repository_userprofile`.`is_superuser`, `repository_userprofile`.`username`, `repository_userprofile`.`first_name`, `repository_userprofile`.`last_name`, `repository_userprofile`.`email`, `repository_userprofile`.`is_staff`, `repository_userprofile`.`is_active`, `repository_userprofile`.`date_joined`, `repository_userprofile`.`id`, `repository_userprofile`.`nick_name`, `repository_userprofile`.`create_time`, `repository_userprofile`.`image`, `repository_userprofile`.`models_introdoction`, `repository_userprofile`.`is_admin`, `repository_userprofile`.`is_approver` FROM `repository_userprofile` WHERE `repository_userprofile`.`id` = 1 LIMIT 1; args=(1,)
DEBUG 2019-02-19 11:11:35,099 [Thread-13:20224] [django.db.backends:111] [utils:execute] [DEBUG]- (0.003) SELECT `repository_u2d`.`id`, `repository_u2d`.`user_id`, `repository_u2d`.`dep_id` FROM `repository_u2d` WHERE `repository_u2d`.`user_id` = 1 LIMIT 21; args=(1,)
DEBUG 2019-02-19 11:11:35,161 [Thread-13:20224] [django.db.backends:111] [utils:execute] [DEBUG]- (0.004) SELECT `repository_u2d`.`id`, `repository_u2d`.`user_id`, `repository_u2d`.`dep_id` FROM `repository_u2d` WHERE `repository_u2d`.`user_id` = 1 LIMIT 21; args=(1,)
DEBUG 2019-02-19 11:11:35,169 [Thread-13:20224] [django.db.backends:111] [utils:execute] [DEBUG]- (0.003) SELECT `repository_u2d`.`id`, `repository_u2d`.`user_id`, `repository_u2d`.`dep_id` FROM `repository_u2d` WHERE `repository_u2d`.`user_id` = 1 LIMIT 21; args=(1,)
DEBUG 2019-02-19 11:11:35,205 [Thread-13:20224] [django.db.backends:111] [utils:execute] [DEBUG]- (0.005) SELECT `repository_u2d`.`id`, `repository_u2d`.`user_id`, `repository_u2d`.`dep_id` FROM `repository_u2d` WHERE `repository_u2d`.`user_id` = 1 LIMIT 21; args=(1,)
INFO 2019-02-19 11:11:35,250 [Thread-13:20224] [django:78] [AddfileView:post] [INFO]- 添加文件
INFO 2019-02-19 11:11:35,251 [Thread-13:20224] [django:79] [AddfileView:post] [INFO]- ********************
INFO 2019-02-19 11:11:35,271 [Thread-13:20224] [django:80] [AddfileView:post] [INFO]- <QueryDict: {'filename': ['123'], 'filedes': ['的味道'], 'filetype': ['内部'], 'fileproject': ['测试项目1'], 'csrfmiddlewaretoken': ['OlI1YV1SZDNNKcGJfaFNQnDA5dUkinGAw2sBmWhP6eBr0CqCDKKEKr0OKxCqsQYg']}>
DEBUG 2019-02-19 11:11:35,467 [Thread-14:23248] [django.db.backends:111] [utils:execute] [DEBUG]- (0.003) SELECT @@SQL_AUTO_IS_NULL; args=None
DEBUG 2019-02-19 11:11:35,476 [Thread-14:23248] [django.db.backends:111] [utils:execute] [DEBUG]- (0.004) SET SESSION TRANSACTION ISOLATION LEVEL READ COMMITTED; args=None
DEBUG 2019-02-19 11:11:35,484 [Thread-14:23248] [django.db.backends:111] [utils:execute] [DEBUG]- (0.004) SELECT VERSION(); args=None
DEBUG 2019-02-19 11:11:35,503 [Thread-14:23248] [django.db.backends:111] [utils:execute] [DEBUG]- (0.002) SET SESSION TRANSACTION ISOLATION LEVEL READ COMMITTED; args=None
DEBUG 2019-02-19 11:11:35,513 [Thread-14:23248] [django.db.backends:111] [utils:execute] [DEBUG]- (0.008) SELECT `repository_u2d`.`id`, `repository_u2d`.`user_id`, `repository_u2d`.`dep_id` FROM `repository_u2d` WHERE `repository_u2d`.`user_id` = 1 LIMIT 21; args=(1,)
DEBUG 2019-02-19 11:11:40,535 [Thread-24:21552] [django.db.backends:111] [utils:execute] [DEBUG]- (0.007) SELECT @@SQL_AUTO_IS_NULL; args=None
DEBUG 2019-02-19 11:11:40,543 [Thread-24:21552] [django.db.backends:111] [utils:execute] [DEBUG]- (0.005) SET SESSION TRANSACTION ISOLATION LEVEL READ COMMITTED; args=None
DEBUG 2019-02-19 11:11:40,551 [Thread-24:21552] [django.db.backends:111] [utils:execute] [DEBUG]- (0.006) SELECT VERSION(); args=None
DEBUG 2019-02-19 11:11:40,571 [Thread-24:21552] [django.db.backends:111] [utils:execute] [DEBUG]- (0.002) SET SESSION TRANSACTION ISOLATION LEVEL READ COMMITTED; args=None
DEBUG 2019-02-19 11:11:40,580 [Thread-24:21552] [django.db.backends:111] [utils:execute] [DEBUG]- (0.006) SELECT `repository_u2d`.`id`, `repository_u2d`.`user_id`, `repository_u2d`.`dep_id` FROM `repository_u2d` WHERE `repository_u2d`.`user_id` = 1 LIMIT 21; args=(1,)
DEBUG 2019-02-19 11:11:40,637 [Thread-30:4240] [django.db.backends:111] [utils:execute] [DEBUG]- (0.006) SELECT @@SQL_AUTO_IS_NULL; args=None
DEBUG 2019-02-19 11:11:40,640 [Thread-30:4240] [django.db.backends:111] [utils:execute] [DEBUG]- (0.002) SET SESSION TRANSACTION ISOLATION LEVEL READ COMMITTED; args=None
DEBUG 2019-02-19 11:11:40,646 [Thread-30:4240] [django.db.backends:111] [utils:execute] [DEBUG]- (0.004) SELECT VERSION(); args=None
DEBUG 2019-02-19 11:11:40,657 [Thread-30:4240] [django.db.backends:111] [utils:execute] [DEBUG]- (0.002) SET SESSION TRANSACTION ISOLATION LEVEL READ COMMITTED; args=None
DEBUG 2019-02-19 11:11:40,668 [Thread-30:4240] [django.db.backends:111] [utils:execute] [DEBUG]- (0.005) SELECT `repository_u2d`.`id`, `repository_u2d`.`user_id`, `repository_u2d`.`dep_id` FROM `repository_u2d` WHERE `repository_u2d`.`user_id` = 1 LIMIT 21; args=(1,)
DEBUG 2019-02-19 11:11:40,736 [Thread-36:7764] [django.db.backends:111] [utils:execute] [DEBUG]- (0.003) SELECT @@SQL_AUTO_IS_NULL; args=None
DEBUG 2019-02-19 11:11:40,744 [Thread-36:7764] [django.db.backends:111] [utils:execute] [DEBUG]- (0.003) SET SESSION TRANSACTION ISOLATION LEVEL READ COMMITTED; args=None
DEBUG 2019-02-19 11:11:40,750 [Thread-36:7764] [django.db.backends:111] [utils:execute] [DEBUG]- (0.003) SELECT VERSION(); args=None
DEBUG 2019-02-19 11:11:40,779 [Thread-36:7764] [django.db.backends:111] [utils:execute] [DEBUG]- (0.002) SET SESSION TRANSACTION ISOLATION LEVEL READ COMMITTED; args=None
DEBUG 2019-02-19 11:11:40,788 [Thread-36:7764] [django.db.backends:111] [utils:execute] [DEBUG]- (0.006) SELECT `repository_u2d`.`id`, `repository_u2d`.`user_id`, `repository_u2d`.`dep_id` FROM `repository_u2d` WHERE `repository_u2d`.`user_id` = 1 LIMIT 21; args=(1,)
DEBUG 2019-02-19 11:11:40,795 [Thread-42:21060] [django.db.backends:111] [utils:execute] [DEBUG]- (0.002) SELECT @@SQL_AUTO_IS_NULL; args=None
DEBUG 2019-02-19 11:11:40,798 [Thread-42:21060] [django.db.backends:111] [utils:execute] [DEBUG]- (0.001) SET SESSION TRANSACTION ISOLATION LEVEL READ COMMITTED; args=None
DEBUG 2019-02-19 11:11:40,801 [Thread-42:21060] [django.db.backends:111] [utils:execute] [DEBUG]- (0.002) SELECT VERSION(); args=None
DEBUG 2019-02-19 11:11:40,811 [Thread-42:21060] [django.db.backends:111] [utils:execute] [DEBUG]- (0.001) SET SESSION TRANSACTION ISOLATION LEVEL READ COMMITTED; args=None
DEBUG 2019-02-19 11:11:40,816 [Thread-42:21060] [django.db.backends:111] [utils:execute] [DEBUG]- (0.004) SELECT `repository_u2d`.`id`, `repository_u2d`.`user_id`, `repository_u2d`.`dep_id` FROM `repository_u2d` WHERE `repository_u2d`.`user_id` = 1 LIMIT 21; args=(1,)
DEBUG 2019-02-19 11:12:02,149 [Thread-13:20224] [django.db.backends:111] [utils:execute] [DEBUG]- (0.002) SELECT `repository_u2d`.`id`, `repository_u2d`.`user_id`, `repository_u2d`.`dep_id` FROM `repository_u2d` WHERE `repository_u2d`.`user_id` = 1 LIMIT 1; args=(1,)
DEBUG 2019-02-19 11:12:02,171 [Thread-13:20224] [django.db.backends:111] [utils:execute] [DEBUG]- (0.001) SELECT `repository_projectmodel`.`nid`, `repository_projectmodel`.`Project_name` FROM `repository_projectmodel` WHERE `repository_projectmodel`.`Project_name` = '测试项目1'; args=('测试项目1',)
INFO 2019-02-19 11:12:02,190 [Thread-13:20224] [django:127] [AddfileView:post] [INFO]- 1
DEBUG 2019-02-19 11:12:02,203 [Thread-13:20224] [django.db.backends:111] [utils:execute] [DEBUG]- (0.002) INSERT INTO `repository_addfilemodel` (`models_Filename`, `models_Filedes`, `read_count`, `models_Fileupload`, `create_time`, `department_id`, `user_id_id`, `models_Filetype_type_id`, `status`, `models_Fileproject_id`, `reason`) VALUES ('123', '的味道', 0, 'file/2019/02/Login_rqS37o3.png', '2019-02-19 11:12:02.200680', NULL, 1, 2, '0', 1, '无'); args=['123', '的味道', 0, 'file/2019/02/Login_rqS37o3.png', '2019-02-19 11:12:02.200680', None, 1, 2, '0', 1, '无']
DEBUG 2019-02-19 11:12:02,330 [Thread-13:20224] [django.db.backends:111] [utils:execute] [DEBUG]- (0.001) SELECT `repository_u2d`.`id`, `repository_u2d`.`user_id`, `repository_u2d`.`dep_id` FROM `repository_u2d` WHERE `repository_u2d`.`user_id` = 1 LIMIT 21; args=(1,)
ERROR 2019-02-19 11:12:03,375 [Thread-13:20224] [django.server:124] [basehttp:log_message] [ERROR]- "POST /sharefile/addfile/ HTTP/1.1" 500 113484
DEBUG 2019-02-19 11:12:03,931 [Thread-45:5840] [django.template:878] [base:_resolve_lookup] [DEBUG]- Exception while resolving variable 'name' in template 'unknown'.
Traceback (most recent call last):
  File "C:\Python\Webproject\share2\env\lib\site-packages\django\core\handlers\exception.py", line 35, in inner
    response = get_response(request)
  File "C:\Python\Webproject\share2\env\lib\site-packages\django\core\handlers\base.py", line 113, in _get_response
    resolver_match = resolver.resolve(request.path_info)
  File "C:\Python\Webproject\share2\env\lib\site-packages\django\urls\resolvers.py", line 523, in resolve
    raise Resolver404({'tried': tried, 'path': new_path})
django.urls.exceptions.Resolver404: {'tried': [[<URLResolver <URLPattern list> (xadmin:xadmin) 'xadmin/'>], [<URLPattern '^$' [name='index']>], [<URLPattern 'index/' [name='index']>], [<URLPattern 'test/' [name='test']>], [<URLPattern 'login/' [name='login']>], [<URLPattern 'logout/' [name='logout']>], [<URLPattern 'register/' [name='register']>], [<URLPattern 'forget/' [name='forget_pwd']>], [<URLPattern 'reset/(?P<active_code>.*)/' [name='reset_pwd']>], [<URLPattern 'modify_pwd/' [name='modify_pwd']>], [<URLResolver <module 'captcha.urls' from 'C:\\Python\\Webproject\\share2\\env\\lib\\site-packages\\captcha\\urls.py'> (None:None) 'captcha/'>], [<URLPattern 'active/(?P<active_code>.*)/' [name='user_active']>], [<URLResolver <module 'sharefile.urls' from 'C:\\Python\\Webproject\\share2\\share2\\share2\\apps\\sharefile\\urls.py'> (sharefile:sharefile) 'sharefile/'>], [<URLResolver <module 'users.urls' from 'C:\\Python\\Webproject\\share2\\share2\\share2\\apps\\users\\urls.py'> (users:users) 'users/'>], [<URLPattern 'media/(?P<path>.*)$'>]], 'path': 'favicon.ico'}

During handling of the above exception, another exception occurred:

Traceback (most recent call last):
  File "C:\Python\Webproject\share2\env\lib\site-packages\django\template\base.py", line 835, in _resolve_lookup
    current = current[bit]
TypeError: 'URLResolver' object is not subscriptable

During handling of the above exception, another exception occurred:

Traceback (most recent call last):
  File "C:\Python\Webproject\share2\env\lib\site-packages\django\template\base.py", line 843, in _resolve_lookup
    current = getattr(current, bit)
AttributeError: 'URLResolver' object has no attribute 'name'

During handling of the above exception, another exception occurred:

Traceback (most recent call last):
  File "C:\Python\Webproject\share2\env\lib\site-packages\django\template\base.py", line 849, in _resolve_lookup
    current = current[int(bit)]
ValueError: invalid literal for int() with base 10: 'name'

During handling of the above exception, another exception occurred:

Traceback (most recent call last):
  File "C:\Python\Webproject\share2\env\lib\site-packages\django\template\base.py", line 856, in _resolve_lookup
    (bit, current))  # missing attribute
django.template.base.VariableDoesNotExist: Failed lookup for key [name] in <URLResolver <URLPattern list> (xadmin:xadmin) 'xadmin/'>
DEBUG 2019-02-19 11:12:03,946 [Thread-45:5840] [django.template:878] [base:_resolve_lookup] [DEBUG]- Exception while resolving variable 'name' in template 'unknown'.
Traceback (most recent call last):
  File "C:\Python\Webproject\share2\env\lib\site-packages\django\core\handlers\exception.py", line 35, in inner
    response = get_response(request)
  File "C:\Python\Webproject\share2\env\lib\site-packages\django\core\handlers\base.py", line 113, in _get_response
    resolver_match = resolver.resolve(request.path_info)
  File "C:\Python\Webproject\share2\env\lib\site-packages\django\urls\resolvers.py", line 523, in resolve
    raise Resolver404({'tried': tried, 'path': new_path})
django.urls.exceptions.Resolver404: {'tried': [[<URLResolver <URLPattern list> (xadmin:xadmin) 'xadmin/'>], [<URLPattern '^$' [name='index']>], [<URLPattern 'index/' [name='index']>], [<URLPattern 'test/' [name='test']>], [<URLPattern 'login/' [name='login']>], [<URLPattern 'logout/' [name='logout']>], [<URLPattern 'register/' [name='register']>], [<URLPattern 'forget/' [name='forget_pwd']>], [<URLPattern 'reset/(?P<active_code>.*)/' [name='reset_pwd']>], [<URLPattern 'modify_pwd/' [name='modify_pwd']>], [<URLResolver <module 'captcha.urls' from 'C:\\Python\\Webproject\\share2\\env\\lib\\site-packages\\captcha\\urls.py'> (None:None) 'captcha/'>], [<URLPattern 'active/(?P<active_code>.*)/' [name='user_active']>], [<URLResolver <module 'sharefile.urls' from 'C:\\Python\\Webproject\\share2\\share2\\share2\\apps\\sharefile\\urls.py'> (sharefile:sharefile) 'sharefile/'>], [<URLResolver <module 'users.urls' from 'C:\\Python\\Webproject\\share2\\share2\\share2\\apps\\users\\urls.py'> (users:users) 'users/'>], [<URLPattern 'media/(?P<path>.*)$'>]], 'path': 'favicon.ico'}

During handling of the above exception, another exception occurred:

Traceback (most recent call last):
  File "C:\Python\Webproject\share2\env\lib\site-packages\django\template\base.py", line 835, in _resolve_lookup
    current = current[bit]
TypeError: 'URLResolver' object is not subscriptable

During handling of the above exception, another exception occurred:

Traceback (most recent call last):
  File "C:\Python\Webproject\share2\env\lib\site-packages\django\template\base.py", line 843, in _resolve_lookup
    current = getattr(current, bit)
AttributeError: 'URLResolver' object has no attribute 'name'

During handling of the above exception, another exception occurred:

Traceback (most recent call last):
  File "C:\Python\Webproject\share2\env\lib\site-packages\django\template\base.py", line 849, in _resolve_lookup
    current = current[int(bit)]
ValueError: invalid literal for int() with base 10: 'name'

During handling of the above exception, another exception occurred:

Traceback (most recent call last):
  File "C:\Python\Webproject\share2\env\lib\site-packages\django\template\base.py", line 856, in _resolve_lookup
    (bit, current))  # missing attribute
django.template.base.VariableDoesNotExist: Failed lookup for key [name] in <URLResolver <module 'captcha.urls' from 'C:\\Python\\Webproject\\share2\\env\\lib\\site-packages\\captcha\\urls.py'> (None:None) 'captcha/'>
DEBUG 2019-02-19 11:12:03,954 [Thread-45:5840] [django.template:878] [base:_resolve_lookup] [DEBUG]- Exception while resolving variable 'name' in template 'unknown'.
Traceback (most recent call last):
  File "C:\Python\Webproject\share2\env\lib\site-packages\django\core\handlers\exception.py", line 35, in inner
    response = get_response(request)
  File "C:\Python\Webproject\share2\env\lib\site-packages\django\core\handlers\base.py", line 113, in _get_response
    resolver_match = resolver.resolve(request.path_info)
  File "C:\Python\Webproject\share2\env\lib\site-packages\django\urls\resolvers.py", line 523, in resolve
    raise Resolver404({'tried': tried, 'path': new_path})
django.urls.exceptions.Resolver404: {'tried': [[<URLResolver <URLPattern list> (xadmin:xadmin) 'xadmin/'>], [<URLPattern '^$' [name='index']>], [<URLPattern 'index/' [name='index']>], [<URLPattern 'test/' [name='test']>], [<URLPattern 'login/' [name='login']>], [<URLPattern 'logout/' [name='logout']>], [<URLPattern 'register/' [name='register']>], [<URLPattern 'forget/' [name='forget_pwd']>], [<URLPattern 'reset/(?P<active_code>.*)/' [name='reset_pwd']>], [<URLPattern 'modify_pwd/' [name='modify_pwd']>], [<URLResolver <module 'captcha.urls' from 'C:\\Python\\Webproject\\share2\\env\\lib\\site-packages\\captcha\\urls.py'> (None:None) 'captcha/'>], [<URLPattern 'active/(?P<active_code>.*)/' [name='user_active']>], [<URLResolver <module 'sharefile.urls' from 'C:\\Python\\Webproject\\share2\\share2\\share2\\apps\\sharefile\\urls.py'> (sharefile:sharefile) 'sharefile/'>], [<URLResolver <module 'users.urls' from 'C:\\Python\\Webproject\\share2\\share2\\share2\\apps\\users\\urls.py'> (users:users) 'users/'>], [<URLPattern 'media/(?P<path>.*)$'>]], 'path': 'favicon.ico'}

During handling of the above exception, another exception occurred:

Traceback (most recent call last):
  File "C:\Python\Webproject\share2\env\lib\site-packages\django\template\base.py", line 835, in _resolve_lookup
    current = current[bit]
TypeError: 'URLResolver' object is not subscriptable

During handling of the above exception, another exception occurred:

Traceback (most recent call last):
  File "C:\Python\Webproject\share2\env\lib\site-packages\django\template\base.py", line 843, in _resolve_lookup
    current = getattr(current, bit)
AttributeError: 'URLResolver' object has no attribute 'name'

During handling of the above exception, another exception occurred:

Traceback (most recent call last):
  File "C:\Python\Webproject\share2\env\lib\site-packages\django\template\base.py", line 849, in _resolve_lookup
    current = current[int(bit)]
ValueError: invalid literal for int() with base 10: 'name'

During handling of the above exception, another exception occurred:

Traceback (most recent call last):
  File "C:\Python\Webproject\share2\env\lib\site-packages\django\template\base.py", line 856, in _resolve_lookup
    (bit, current))  # missing attribute
django.template.base.VariableDoesNotExist: Failed lookup for key [name] in <URLResolver <module 'sharefile.urls' from 'C:\\Python\\Webproject\\share2\\share2\\share2\\apps\\sharefile\\urls.py'> (sharefile:sharefile) 'sharefile/'>
DEBUG 2019-02-19 11:12:03,962 [Thread-45:5840] [django.template:878] [base:_resolve_lookup] [DEBUG]- Exception while resolving variable 'name' in template 'unknown'.
Traceback (most recent call last):
  File "C:\Python\Webproject\share2\env\lib\site-packages\django\core\handlers\exception.py", line 35, in inner
    response = get_response(request)
  File "C:\Python\Webproject\share2\env\lib\site-packages\django\core\handlers\base.py", line 113, in _get_response
    resolver_match = resolver.resolve(request.path_info)
  File "C:\Python\Webproject\share2\env\lib\site-packages\django\urls\resolvers.py", line 523, in resolve
    raise Resolver404({'tried': tried, 'path': new_path})
django.urls.exceptions.Resolver404: {'tried': [[<URLResolver <URLPattern list> (xadmin:xadmin) 'xadmin/'>], [<URLPattern '^$' [name='index']>], [<URLPattern 'index/' [name='index']>], [<URLPattern 'test/' [name='test']>], [<URLPattern 'login/' [name='login']>], [<URLPattern 'logout/' [name='logout']>], [<URLPattern 'register/' [name='register']>], [<URLPattern 'forget/' [name='forget_pwd']>], [<URLPattern 'reset/(?P<active_code>.*)/' [name='reset_pwd']>], [<URLPattern 'modify_pwd/' [name='modify_pwd']>], [<URLResolver <module 'captcha.urls' from 'C:\\Python\\Webproject\\share2\\env\\lib\\site-packages\\captcha\\urls.py'> (None:None) 'captcha/'>], [<URLPattern 'active/(?P<active_code>.*)/' [name='user_active']>], [<URLResolver <module 'sharefile.urls' from 'C:\\Python\\Webproject\\share2\\share2\\share2\\apps\\sharefile\\urls.py'> (sharefile:sharefile) 'sharefile/'>], [<URLResolver <module 'users.urls' from 'C:\\Python\\Webproject\\share2\\share2\\share2\\apps\\users\\urls.py'> (users:users) 'users/'>], [<URLPattern 'media/(?P<path>.*)$'>]], 'path': 'favicon.ico'}

During handling of the above exception, another exception occurred:

Traceback (most recent call last):
  File "C:\Python\Webproject\share2\env\lib\site-packages\django\template\base.py", line 835, in _resolve_lookup
    current = current[bit]
TypeError: 'URLResolver' object is not subscriptable

During handling of the above exception, another exception occurred:

Traceback (most recent call last):
  File "C:\Python\Webproject\share2\env\lib\site-packages\django\template\base.py", line 843, in _resolve_lookup
    current = getattr(current, bit)
AttributeError: 'URLResolver' object has no attribute 'name'

During handling of the above exception, another exception occurred:

Traceback (most recent call last):
  File "C:\Python\Webproject\share2\env\lib\site-packages\django\template\base.py", line 849, in _resolve_lookup
    current = current[int(bit)]
ValueError: invalid literal for int() with base 10: 'name'

During handling of the above exception, another exception occurred:

Traceback (most recent call last):
  File "C:\Python\Webproject\share2\env\lib\site-packages\django\template\base.py", line 856, in _resolve_lookup
    (bit, current))  # missing attribute
django.template.base.VariableDoesNotExist: Failed lookup for key [name] in <URLResolver <module 'users.urls' from 'C:\\Python\\Webproject\\share2\\share2\\share2\\apps\\users\\urls.py'> (users:users) 'users/'>
WARNING 2019-02-19 11:12:03,977 [Thread-45:5840] [django.server:124] [basehttp:log_message] [WARNING]- "GET /favicon.ico HTTP/1.1" 404 3703
DEBUG 2019-02-19 11:12:21,917 [Dummy-6:9900] [django.db.backends:111] [utils:execute] [DEBUG]- (0.002) SELECT @@SQL_AUTO_IS_NULL; args=None
DEBUG 2019-02-19 11:12:21,919 [Dummy-6:9900] [django.db.backends:111] [utils:execute] [DEBUG]- (0.001) SET SESSION TRANSACTION ISOLATION LEVEL READ COMMITTED; args=None
DEBUG 2019-02-19 11:12:21,920 [Dummy-6:9900] [django.db.backends:111] [utils:execute] [DEBUG]- (0.001) SELECT VERSION(); args=None
DEBUG 2019-02-19 11:12:25,766 [Dummy-6:9900] [django.db.backends:111] [utils:execute] [DEBUG]- (0.000) SET SESSION TRANSACTION ISOLATION LEVEL READ COMMITTED; args=None
DEBUG 2019-02-19 11:12:25,771 [Dummy-6:9900] [django.db.backends:111] [utils:execute] [DEBUG]- (0.004) SHOW FULL TABLES; args=None
DEBUG 2019-02-19 11:12:25,786 [Dummy-6:9900] [django.db.backends:111] [utils:execute] [DEBUG]- (0.004) SELECT `django_migrations`.`app`, `django_migrations`.`name` FROM `django_migrations`; args=()
DEBUG 2019-02-19 11:12:34,259 [Thread-7:13316] [django.db.backends:111] [utils:execute] [DEBUG]- (0.002) SELECT @@SQL_AUTO_IS_NULL; args=None
DEBUG 2019-02-19 11:12:34,262 [Thread-7:13316] [django.db.backends:111] [utils:execute] [DEBUG]- (0.001) SET SESSION TRANSACTION ISOLATION LEVEL READ COMMITTED; args=None
DEBUG 2019-02-19 11:12:34,264 [Thread-7:13316] [django.db.backends:111] [utils:execute] [DEBUG]- (0.002) SELECT VERSION(); args=None
DEBUG 2019-02-19 11:12:34,280 [Thread-7:13316] [django.db.backends:111] [utils:execute] [DEBUG]- (0.001) SET SESSION TRANSACTION ISOLATION LEVEL READ COMMITTED; args=None
DEBUG 2019-02-19 11:12:34,284 [Thread-7:13316] [django.db.backends:111] [utils:execute] [DEBUG]- (0.003) SELECT `django_session`.`session_key`, `django_session`.`session_data`, `django_session`.`expire_date` FROM `django_session` WHERE (`django_session`.`session_key` = '0u5rozh3lc5qezdhht6wcg9rg9gi21ko' AND `django_session`.`expire_date` > '2019-02-19 11:12:34.240271'); args=('0u5rozh3lc5qezdhht6wcg9rg9gi21ko', '2019-02-19 11:12:34.240271')
DEBUG 2019-02-19 11:12:34,305 [Thread-7:13316] [django.db.backends:111] [utils:execute] [DEBUG]- (0.007) SELECT `repository_userprofile`.`password`, `repository_userprofile`.`last_login`, `repository_userprofile`.`is_superuser`, `repository_userprofile`.`username`, `repository_userprofile`.`first_name`, `repository_userprofile`.`last_name`, `repository_userprofile`.`email`, `repository_userprofile`.`is_staff`, `repository_userprofile`.`is_active`, `repository_userprofile`.`date_joined`, `repository_userprofile`.`id`, `repository_userprofile`.`nick_name`, `repository_userprofile`.`create_time`, `repository_userprofile`.`image`, `repository_userprofile`.`models_introdoction`, `repository_userprofile`.`is_admin`, `repository_userprofile`.`is_approver` FROM `repository_userprofile` WHERE `repository_userprofile`.`id` = 1; args=(1,)
DEBUG 2019-02-19 11:12:34,604 [Thread-7:13316] [django.db.backends:111] [utils:execute] [DEBUG]- (0.002) SELECT `repository_dep`.`nid`, `repository_dep`.`title` FROM `repository_dep` LIMIT 21; args=()
DEBUG 2019-02-19 11:12:34,609 [Thread-7:13316] [django.db.backends:111] [utils:execute] [DEBUG]- (0.002) SELECT `repository_projectmodel`.`nid`, `repository_projectmodel`.`Project_name` FROM `repository_projectmodel` LIMIT 21; args=()
DEBUG 2019-02-19 11:12:34,620 [Thread-7:13316] [django.db.backends:111] [utils:execute] [DEBUG]- (0.003) SELECT `repository_dep`.`nid`, `repository_dep`.`title` FROM `repository_dep` LIMIT 21; args=()
DEBUG 2019-02-19 11:12:34,628 [Thread-7:13316] [django.db.backends:111] [utils:execute] [DEBUG]- (0.003) SELECT `repository_projectmodel`.`nid`, `repository_projectmodel`.`Project_name` FROM `repository_projectmodel` LIMIT 21; args=()
DEBUG 2019-02-19 11:12:34,688 [Thread-7:13316] [django.db.backends:111] [utils:execute] [DEBUG]- (0.003) SELECT `repository_dep`.`nid`, `repository_dep`.`title` FROM `repository_dep`; args=()
DEBUG 2019-02-19 11:12:34,694 [Thread-7:13316] [django.db.backends:111] [utils:execute] [DEBUG]- (0.003) SELECT `repository_projectmodel`.`nid`, `repository_projectmodel`.`Project_name` FROM `repository_projectmodel`; args=()
INFO 2019-02-19 11:12:34,717 [Thread-7:13316] [django.server:124] [basehttp:log_message] [INFO]- "GET /sharefile/addfile/ HTTP/1.1" 200 22974
DEBUG 2019-02-19 11:12:34,865 [Thread-8:20840] [django.template:878] [base:_resolve_lookup] [DEBUG]- Exception while resolving variable 'name' in template 'unknown'.
Traceback (most recent call last):
  File "C:\Python\Webproject\share2\env\lib\site-packages\django\core\handlers\exception.py", line 35, in inner
    response = get_response(request)
  File "C:\Python\Webproject\share2\env\lib\site-packages\django\core\handlers\base.py", line 113, in _get_response
    resolver_match = resolver.resolve(request.path_info)
  File "C:\Python\Webproject\share2\env\lib\site-packages\django\urls\resolvers.py", line 523, in resolve
    raise Resolver404({'tried': tried, 'path': new_path})
django.urls.exceptions.Resolver404: {'tried': [[<URLResolver <URLPattern list> (xadmin:xadmin) 'xadmin/'>], [<URLPattern '^$' [name='index']>], [<URLPattern 'index/' [name='index']>], [<URLPattern 'test/' [name='test']>], [<URLPattern 'login/' [name='login']>], [<URLPattern 'logout/' [name='logout']>], [<URLPattern 'register/' [name='register']>], [<URLPattern 'forget/' [name='forget_pwd']>], [<URLPattern 'reset/(?P<active_code>.*)/' [name='reset_pwd']>], [<URLPattern 'modify_pwd/' [name='modify_pwd']>], [<URLResolver <module 'captcha.urls' from 'C:\\Python\\Webproject\\share2\\env\\lib\\site-packages\\captcha\\urls.py'> (None:None) 'captcha/'>], [<URLPattern 'active/(?P<active_code>.*)/' [name='user_active']>], [<URLResolver <module 'sharefile.urls' from 'C:\\Python\\Webproject\\share2\\share2\\share2\\apps\\sharefile\\urls.py'> (sharefile:sharefile) 'sharefile/'>], [<URLResolver <module 'users.urls' from 'C:\\Python\\Webproject\\share2\\share2\\share2\\apps\\users\\urls.py'> (users:users) 'users/'>], [<URLPattern 'media/(?P<path>.*)$'>]], 'path': 'assets/images/custom-select.png'}

During handling of the above exception, another exception occurred:

Traceback (most recent call last):
  File "C:\Python\Webproject\share2\env\lib\site-packages\django\template\base.py", line 835, in _resolve_lookup
    current = current[bit]
TypeError: 'URLResolver' object is not subscriptable

During handling of the above exception, another exception occurred:

Traceback (most recent call last):
  File "C:\Python\Webproject\share2\env\lib\site-packages\django\template\base.py", line 843, in _resolve_lookup
    current = getattr(current, bit)
AttributeError: 'URLResolver' object has no attribute 'name'

During handling of the above exception, another exception occurred:

Traceback (most recent call last):
  File "C:\Python\Webproject\share2\env\lib\site-packages\django\template\base.py", line 849, in _resolve_lookup
    current = current[int(bit)]
ValueError: invalid literal for int() with base 10: 'name'

During handling of the above exception, another exception occurred:

Traceback (most recent call last):
  File "C:\Python\Webproject\share2\env\lib\site-packages\django\template\base.py", line 856, in _resolve_lookup
    (bit, current))  # missing attribute
django.template.base.VariableDoesNotExist: Failed lookup for key [name] in <URLResolver <URLPattern list> (xadmin:xadmin) 'xadmin/'>
DEBUG 2019-02-19 11:12:34,884 [Thread-8:20840] [django.template:878] [base:_resolve_lookup] [DEBUG]- Exception while resolving variable 'name' in template 'unknown'.
Traceback (most recent call last):
  File "C:\Python\Webproject\share2\env\lib\site-packages\django\core\handlers\exception.py", line 35, in inner
    response = get_response(request)
  File "C:\Python\Webproject\share2\env\lib\site-packages\django\core\handlers\base.py", line 113, in _get_response
    resolver_match = resolver.resolve(request.path_info)
  File "C:\Python\Webproject\share2\env\lib\site-packages\django\urls\resolvers.py", line 523, in resolve
    raise Resolver404({'tried': tried, 'path': new_path})
django.urls.exceptions.Resolver404: {'tried': [[<URLResolver <URLPattern list> (xadmin:xadmin) 'xadmin/'>], [<URLPattern '^$' [name='index']>], [<URLPattern 'index/' [name='index']>], [<URLPattern 'test/' [name='test']>], [<URLPattern 'login/' [name='login']>], [<URLPattern 'logout/' [name='logout']>], [<URLPattern 'register/' [name='register']>], [<URLPattern 'forget/' [name='forget_pwd']>], [<URLPattern 'reset/(?P<active_code>.*)/' [name='reset_pwd']>], [<URLPattern 'modify_pwd/' [name='modify_pwd']>], [<URLResolver <module 'captcha.urls' from 'C:\\Python\\Webproject\\share2\\env\\lib\\site-packages\\captcha\\urls.py'> (None:None) 'captcha/'>], [<URLPattern 'active/(?P<active_code>.*)/' [name='user_active']>], [<URLResolver <module 'sharefile.urls' from 'C:\\Python\\Webproject\\share2\\share2\\share2\\apps\\sharefile\\urls.py'> (sharefile:sharefile) 'sharefile/'>], [<URLResolver <module 'users.urls' from 'C:\\Python\\Webproject\\share2\\share2\\share2\\apps\\users\\urls.py'> (users:users) 'users/'>], [<URLPattern 'media/(?P<path>.*)$'>]], 'path': 'assets/images/custom-select.png'}

During handling of the above exception, another exception occurred:

Traceback (most recent call last):
  File "C:\Python\Webproject\share2\env\lib\site-packages\django\template\base.py", line 835, in _resolve_lookup
    current = current[bit]
TypeError: 'URLResolver' object is not subscriptable

During handling of the above exception, another exception occurred:

Traceback (most recent call last):
  File "C:\Python\Webproject\share2\env\lib\site-packages\django\template\base.py", line 843, in _resolve_lookup
    current = getattr(current, bit)
AttributeError: 'URLResolver' object has no attribute 'name'

During handling of the above exception, another exception occurred:

Traceback (most recent call last):
  File "C:\Python\Webproject\share2\env\lib\site-packages\django\template\base.py", line 849, in _resolve_lookup
    current = current[int(bit)]
ValueError: invalid literal for int() with base 10: 'name'

During handling of the above exception, another exception occurred:

Traceback (most recent call last):
  File "C:\Python\Webproject\share2\env\lib\site-packages\django\template\base.py", line 856, in _resolve_lookup
    (bit, current))  # missing attribute
django.template.base.VariableDoesNotExist: Failed lookup for key [name] in <URLResolver <module 'captcha.urls' from 'C:\\Python\\Webproject\\share2\\env\\lib\\site-packages\\captcha\\urls.py'> (None:None) 'captcha/'>
DEBUG 2019-02-19 11:12:34,987 [Thread-8:20840] [django.template:878] [base:_resolve_lookup] [DEBUG]- Exception while resolving variable 'name' in template 'unknown'.
Traceback (most recent call last):
  File "C:\Python\Webproject\share2\env\lib\site-packages\django\core\handlers\exception.py", line 35, in inner
    response = get_response(request)
  File "C:\Python\Webproject\share2\env\lib\site-packages\django\core\handlers\base.py", line 113, in _get_response
    resolver_match = resolver.resolve(request.path_info)
  File "C:\Python\Webproject\share2\env\lib\site-packages\django\urls\resolvers.py", line 523, in resolve
    raise Resolver404({'tried': tried, 'path': new_path})
django.urls.exceptions.Resolver404: {'tried': [[<URLResolver <URLPattern list> (xadmin:xadmin) 'xadmin/'>], [<URLPattern '^$' [name='index']>], [<URLPattern 'index/' [name='index']>], [<URLPattern 'test/' [name='test']>], [<URLPattern 'login/' [name='login']>], [<URLPattern 'logout/' [name='logout']>], [<URLPattern 'register/' [name='register']>], [<URLPattern 'forget/' [name='forget_pwd']>], [<URLPattern 'reset/(?P<active_code>.*)/' [name='reset_pwd']>], [<URLPattern 'modify_pwd/' [name='modify_pwd']>], [<URLResolver <module 'captcha.urls' from 'C:\\Python\\Webproject\\share2\\env\\lib\\site-packages\\captcha\\urls.py'> (None:None) 'captcha/'>], [<URLPattern 'active/(?P<active_code>.*)/' [name='user_active']>], [<URLResolver <module 'sharefile.urls' from 'C:\\Python\\Webproject\\share2\\share2\\share2\\apps\\sharefile\\urls.py'> (sharefile:sharefile) 'sharefile/'>], [<URLResolver <module 'users.urls' from 'C:\\Python\\Webproject\\share2\\share2\\share2\\apps\\users\\urls.py'> (users:users) 'users/'>], [<URLPattern 'media/(?P<path>.*)$'>]], 'path': 'assets/images/custom-select.png'}

During handling of the above exception, another exception occurred:

Traceback (most recent call last):
  File "C:\Python\Webproject\share2\env\lib\site-packages\django\template\base.py", line 835, in _resolve_lookup
    current = current[bit]
TypeError: 'URLResolver' object is not subscriptable

During handling of the above exception, another exception occurred:

Traceback (most recent call last):
  File "C:\Python\Webproject\share2\env\lib\site-packages\django\template\base.py", line 843, in _resolve_lookup
    current = getattr(current, bit)
AttributeError: 'URLResolver' object has no attribute 'name'

During handling of the above exception, another exception occurred:

Traceback (most recent call last):
  File "C:\Python\Webproject\share2\env\lib\site-packages\django\template\base.py", line 849, in _resolve_lookup
    current = current[int(bit)]
ValueError: invalid literal for int() with base 10: 'name'

During handling of the above exception, another exception occurred:

Traceback (most recent call last):
  File "C:\Python\Webproject\share2\env\lib\site-packages\django\template\base.py", line 856, in _resolve_lookup
    (bit, current))  # missing attribute
django.template.base.VariableDoesNotExist: Failed lookup for key [name] in <URLResolver <module 'sharefile.urls' from 'C:\\Python\\Webproject\\share2\\share2\\share2\\apps\\sharefile\\urls.py'> (sharefile:sharefile) 'sharefile/'>
DEBUG 2019-02-19 11:12:34,997 [Thread-8:20840] [django.template:878] [base:_resolve_lookup] [DEBUG]- Exception while resolving variable 'name' in template 'unknown'.
Traceback (most recent call last):
  File "C:\Python\Webproject\share2\env\lib\site-packages\django\core\handlers\exception.py", line 35, in inner
    response = get_response(request)
  File "C:\Python\Webproject\share2\env\lib\site-packages\django\core\handlers\base.py", line 113, in _get_response
    resolver_match = resolver.resolve(request.path_info)
  File "C:\Python\Webproject\share2\env\lib\site-packages\django\urls\resolvers.py", line 523, in resolve
    raise Resolver404({'tried': tried, 'path': new_path})
django.urls.exceptions.Resolver404: {'tried': [[<URLResolver <URLPattern list> (xadmin:xadmin) 'xadmin/'>], [<URLPattern '^$' [name='index']>], [<URLPattern 'index/' [name='index']>], [<URLPattern 'test/' [name='test']>], [<URLPattern 'login/' [name='login']>], [<URLPattern 'logout/' [name='logout']>], [<URLPattern 'register/' [name='register']>], [<URLPattern 'forget/' [name='forget_pwd']>], [<URLPattern 'reset/(?P<active_code>.*)/' [name='reset_pwd']>], [<URLPattern 'modify_pwd/' [name='modify_pwd']>], [<URLResolver <module 'captcha.urls' from 'C:\\Python\\Webproject\\share2\\env\\lib\\site-packages\\captcha\\urls.py'> (None:None) 'captcha/'>], [<URLPattern 'active/(?P<active_code>.*)/' [name='user_active']>], [<URLResolver <module 'sharefile.urls' from 'C:\\Python\\Webproject\\share2\\share2\\share2\\apps\\sharefile\\urls.py'> (sharefile:sharefile) 'sharefile/'>], [<URLResolver <module 'users.urls' from 'C:\\Python\\Webproject\\share2\\share2\\share2\\apps\\users\\urls.py'> (users:users) 'users/'>], [<URLPattern 'media/(?P<path>.*)$'>]], 'path': 'assets/images/custom-select.png'}

During handling of the above exception, another exception occurred:

Traceback (most recent call last):
  File "C:\Python\Webproject\share2\env\lib\site-packages\django\template\base.py", line 835, in _resolve_lookup
    current = current[bit]
TypeError: 'URLResolver' object is not subscriptable

During handling of the above exception, another exception occurred:

Traceback (most recent call last):
  File "C:\Python\Webproject\share2\env\lib\site-packages\django\template\base.py", line 843, in _resolve_lookup
    current = getattr(current, bit)
AttributeError: 'URLResolver' object has no attribute 'name'

During handling of the above exception, another exception occurred:

Traceback (most recent call last):
  File "C:\Python\Webproject\share2\env\lib\site-packages\django\template\base.py", line 849, in _resolve_lookup
    current = current[int(bit)]
ValueError: invalid literal for int() with base 10: 'name'

During handling of the above exception, another exception occurred:

Traceback (most recent call last):
  File "C:\Python\Webproject\share2\env\lib\site-packages\django\template\base.py", line 856, in _resolve_lookup
    (bit, current))  # missing attribute
django.template.base.VariableDoesNotExist: Failed lookup for key [name] in <URLResolver <module 'users.urls' from 'C:\\Python\\Webproject\\share2\\share2\\share2\\apps\\users\\urls.py'> (users:users) 'users/'>
WARNING 2019-02-19 11:12:35,018 [Thread-8:20840] [django.server:124] [basehttp:log_message] [WARNING]- "GET /assets/images/custom-select.png HTTP/1.1" 404 3763
INFO 2019-02-19 11:12:35,049 [Thread-9:21284] [django.server:124] [basehttp:log_message] [INFO]- "GET /static/images/favicon.png HTTP/1.1" 200 1347
DEBUG 2019-02-19 11:12:44,446 [Thread-13:12164] [django.db.backends:111] [utils:execute] [DEBUG]- (0.002) SELECT @@SQL_AUTO_IS_NULL; args=None
DEBUG 2019-02-19 11:12:44,448 [Thread-13:12164] [django.db.backends:111] [utils:execute] [DEBUG]- (0.001) SET SESSION TRANSACTION ISOLATION LEVEL READ COMMITTED; args=None
DEBUG 2019-02-19 11:12:44,450 [Thread-13:12164] [django.db.backends:111] [utils:execute] [DEBUG]- (0.002) SELECT VERSION(); args=None
DEBUG 2019-02-19 11:12:44,460 [Thread-13:12164] [django.db.backends:111] [utils:execute] [DEBUG]- (0.001) SET SESSION TRANSACTION ISOLATION LEVEL READ COMMITTED; args=None
DEBUG 2019-02-19 11:12:44,464 [Thread-13:12164] [django.db.backends:111] [utils:execute] [DEBUG]- (0.003) SELECT `django_session`.`session_key`, `django_session`.`session_data`, `django_session`.`expire_date` FROM `django_session` WHERE (`django_session`.`session_key` = '0u5rozh3lc5qezdhht6wcg9rg9gi21ko' AND `django_session`.`expire_date` > '2019-02-19 11:12:44.419512'); args=('0u5rozh3lc5qezdhht6wcg9rg9gi21ko', '2019-02-19 11:12:44.419512')
DEBUG 2019-02-19 11:12:44,485 [Thread-13:12164] [django.db.backends:111] [utils:execute] [DEBUG]- (0.010) SELECT `repository_userprofile`.`password`, `repository_userprofile`.`last_login`, `repository_userprofile`.`is_superuser`, `repository_userprofile`.`username`, `repository_userprofile`.`first_name`, `repository_userprofile`.`last_name`, `repository_userprofile`.`email`, `repository_userprofile`.`is_staff`, `repository_userprofile`.`is_active`, `repository_userprofile`.`date_joined`, `repository_userprofile`.`id`, `repository_userprofile`.`nick_name`, `repository_userprofile`.`create_time`, `repository_userprofile`.`image`, `repository_userprofile`.`models_introdoction`, `repository_userprofile`.`is_admin`, `repository_userprofile`.`is_approver` FROM `repository_userprofile` WHERE `repository_userprofile`.`id` = 1; args=(1,)
INFO 2019-02-19 11:12:44,540 [Thread-13:12164] [django:60] [AddfileView:post] [INFO]- user
DEBUG 2019-02-19 11:12:44,555 [Thread-13:12164] [django.db.backends:111] [utils:execute] [DEBUG]- (0.010) SELECT `repository_userprofile`.`password`, `repository_userprofile`.`last_login`, `repository_userprofile`.`is_superuser`, `repository_userprofile`.`username`, `repository_userprofile`.`first_name`, `repository_userprofile`.`last_name`, `repository_userprofile`.`email`, `repository_userprofile`.`is_staff`, `repository_userprofile`.`is_active`, `repository_userprofile`.`date_joined`, `repository_userprofile`.`id`, `repository_userprofile`.`nick_name`, `repository_userprofile`.`create_time`, `repository_userprofile`.`image`, `repository_userprofile`.`models_introdoction`, `repository_userprofile`.`is_admin`, `repository_userprofile`.`is_approver` FROM `repository_userprofile` WHERE `repository_userprofile`.`id` = 1 LIMIT 1; args=(1,)
DEBUG 2019-02-19 11:12:44,612 [Thread-13:12164] [django.db.backends:111] [utils:execute] [DEBUG]- (0.003) SELECT `repository_u2d`.`id`, `repository_u2d`.`user_id`, `repository_u2d`.`dep_id` FROM `repository_u2d` WHERE `repository_u2d`.`user_id` = 1 LIMIT 21; args=(1,)
DEBUG 2019-02-19 11:12:44,632 [Thread-13:12164] [django.db.backends:111] [utils:execute] [DEBUG]- (0.003) SELECT `repository_u2d`.`id`, `repository_u2d`.`user_id`, `repository_u2d`.`dep_id` FROM `repository_u2d` WHERE `repository_u2d`.`user_id` = 1 LIMIT 21; args=(1,)
DEBUG 2019-02-19 11:12:44,639 [Thread-13:12164] [django.db.backends:111] [utils:execute] [DEBUG]- (0.003) SELECT `repository_u2d`.`id`, `repository_u2d`.`user_id`, `repository_u2d`.`dep_id` FROM `repository_u2d` WHERE `repository_u2d`.`user_id` = 1 LIMIT 21; args=(1,)
DEBUG 2019-02-19 11:12:44,711 [Thread-13:12164] [django.db.backends:111] [utils:execute] [DEBUG]- (0.003) SELECT `repository_u2d`.`id`, `repository_u2d`.`user_id`, `repository_u2d`.`dep_id` FROM `repository_u2d` WHERE `repository_u2d`.`user_id` = 1 LIMIT 21; args=(1,)
INFO 2019-02-19 11:12:44,758 [Thread-13:12164] [django:78] [AddfileView:post] [INFO]- 添加文件
INFO 2019-02-19 11:12:44,760 [Thread-13:12164] [django:79] [AddfileView:post] [INFO]- ********************
INFO 2019-02-19 11:12:44,775 [Thread-13:12164] [django:80] [AddfileView:post] [INFO]- <QueryDict: {'filename': ['对外'], 'filedes': ['对外'], 'filetype': ['内部'], 'fileproject': ['测试项目1'], 'csrfmiddlewaretoken': ['M9MkmFcoQYwT8TuPEckBtXDxTgfHjAGdfzpcQ8XMGCj2WDtVzuvkzn3s5khCs9Jt']}>
DEBUG 2019-02-19 11:12:44,989 [Thread-14:20848] [django.db.backends:111] [utils:execute] [DEBUG]- (0.004) SELECT @@SQL_AUTO_IS_NULL; args=None
DEBUG 2019-02-19 11:12:44,994 [Thread-14:20848] [django.db.backends:111] [utils:execute] [DEBUG]- (0.002) SET SESSION TRANSACTION ISOLATION LEVEL READ COMMITTED; args=None
DEBUG 2019-02-19 11:12:44,999 [Thread-14:20848] [django.db.backends:111] [utils:execute] [DEBUG]- (0.003) SELECT VERSION(); args=None
DEBUG 2019-02-19 11:12:45,014 [Thread-14:20848] [django.db.backends:111] [utils:execute] [DEBUG]- (0.001) SET SESSION TRANSACTION ISOLATION LEVEL READ COMMITTED; args=None
DEBUG 2019-02-19 11:12:45,026 [Thread-14:20848] [django.db.backends:111] [utils:execute] [DEBUG]- (0.010) SELECT `repository_u2d`.`id`, `repository_u2d`.`user_id`, `repository_u2d`.`dep_id` FROM `repository_u2d` WHERE `repository_u2d`.`user_id` = 1 LIMIT 21; args=(1,)
DEBUG 2019-02-19 11:12:51,038 [Thread-23:22428] [django.db.backends:111] [utils:execute] [DEBUG]- (0.006) SELECT @@SQL_AUTO_IS_NULL; args=None
DEBUG 2019-02-19 11:12:51,047 [Thread-23:22428] [django.db.backends:111] [utils:execute] [DEBUG]- (0.002) SET SESSION TRANSACTION ISOLATION LEVEL READ COMMITTED; args=None
DEBUG 2019-02-19 11:12:51,052 [Thread-23:22428] [django.db.backends:111] [utils:execute] [DEBUG]- (0.003) SELECT VERSION(); args=None
DEBUG 2019-02-19 11:12:51,068 [Thread-23:22428] [django.db.backends:111] [utils:execute] [DEBUG]- (0.002) SET SESSION TRANSACTION ISOLATION LEVEL READ COMMITTED; args=None
DEBUG 2019-02-19 11:12:51,080 [Thread-23:22428] [django.db.backends:111] [utils:execute] [DEBUG]- (0.009) SELECT `repository_u2d`.`id`, `repository_u2d`.`user_id`, `repository_u2d`.`dep_id` FROM `repository_u2d` WHERE `repository_u2d`.`user_id` = 1 LIMIT 21; args=(1,)
DEBUG 2019-02-19 11:12:51,145 [Thread-29:2144] [django.db.backends:111] [utils:execute] [DEBUG]- (0.003) SELECT @@SQL_AUTO_IS_NULL; args=None
DEBUG 2019-02-19 11:12:51,149 [Thread-29:2144] [django.db.backends:111] [utils:execute] [DEBUG]- (0.001) SET SESSION TRANSACTION ISOLATION LEVEL READ COMMITTED; args=None
DEBUG 2019-02-19 11:12:51,155 [Thread-29:2144] [django.db.backends:111] [utils:execute] [DEBUG]- (0.003) SELECT VERSION(); args=None
DEBUG 2019-02-19 11:12:51,167 [Thread-29:2144] [django.db.backends:111] [utils:execute] [DEBUG]- (0.001) SET SESSION TRANSACTION ISOLATION LEVEL READ COMMITTED; args=None
DEBUG 2019-02-19 11:12:51,175 [Thread-29:2144] [django.db.backends:111] [utils:execute] [DEBUG]- (0.005) SELECT `repository_u2d`.`id`, `repository_u2d`.`user_id`, `repository_u2d`.`dep_id` FROM `repository_u2d` WHERE `repository_u2d`.`user_id` = 1 LIMIT 21; args=(1,)
DEBUG 2019-02-19 11:12:53,436 [Thread-37:12620] [django.db.backends:111] [utils:execute] [DEBUG]- (0.009) SELECT @@SQL_AUTO_IS_NULL; args=None
DEBUG 2019-02-19 11:12:53,443 [Thread-37:12620] [django.db.backends:111] [utils:execute] [DEBUG]- (0.003) SET SESSION TRANSACTION ISOLATION LEVEL READ COMMITTED; args=None
DEBUG 2019-02-19 11:12:53,455 [Thread-37:12620] [django.db.backends:111] [utils:execute] [DEBUG]- (0.005) SELECT VERSION(); args=None
DEBUG 2019-02-19 11:12:53,477 [Thread-37:12620] [django.db.backends:111] [utils:execute] [DEBUG]- (0.002) SET SESSION TRANSACTION ISOLATION LEVEL READ COMMITTED; args=None
DEBUG 2019-02-19 11:12:53,486 [Thread-37:12620] [django.db.backends:111] [utils:execute] [DEBUG]- (0.006) SELECT `repository_u2d`.`id`, `repository_u2d`.`user_id`, `repository_u2d`.`dep_id` FROM `repository_u2d` WHERE `repository_u2d`.`user_id` = 1 LIMIT 21; args=(1,)
DEBUG 2019-02-19 11:12:53,518 [Thread-44:14340] [django.db.backends:111] [utils:execute] [DEBUG]- (0.004) SELECT @@SQL_AUTO_IS_NULL; args=None
DEBUG 2019-02-19 11:12:53,522 [Thread-44:14340] [django.db.backends:111] [utils:execute] [DEBUG]- (0.001) SET SESSION TRANSACTION ISOLATION LEVEL READ COMMITTED; args=None
DEBUG 2019-02-19 11:12:53,527 [Thread-44:14340] [django.db.backends:111] [utils:execute] [DEBUG]- (0.003) SELECT VERSION(); args=None
DEBUG 2019-02-19 11:12:53,541 [Thread-44:14340] [django.db.backends:111] [utils:execute] [DEBUG]- (0.002) SET SESSION TRANSACTION ISOLATION LEVEL READ COMMITTED; args=None
DEBUG 2019-02-19 11:12:53,546 [Thread-44:14340] [django.db.backends:111] [utils:execute] [DEBUG]- (0.003) SELECT `repository_u2d`.`id`, `repository_u2d`.`user_id`, `repository_u2d`.`dep_id` FROM `repository_u2d` WHERE `repository_u2d`.`user_id` = 1 LIMIT 21; args=(1,)
DEBUG 2019-02-19 11:13:02,970 [Thread-47:15076] [django.db.backends:111] [utils:execute] [DEBUG]- (0.003) SELECT @@SQL_AUTO_IS_NULL; args=None
DEBUG 2019-02-19 11:13:02,974 [Thread-47:15076] [django.db.backends:111] [utils:execute] [DEBUG]- (0.002) SET SESSION TRANSACTION ISOLATION LEVEL READ COMMITTED; args=None
DEBUG 2019-02-19 11:13:02,978 [Thread-47:15076] [django.db.backends:111] [utils:execute] [DEBUG]- (0.003) SELECT VERSION(); args=None
DEBUG 2019-02-19 11:13:02,992 [Thread-47:15076] [django.db.backends:111] [utils:execute] [DEBUG]- (0.001) SET SESSION TRANSACTION ISOLATION LEVEL READ COMMITTED; args=None
DEBUG 2019-02-19 11:13:03,000 [Thread-47:15076] [django.db.backends:111] [utils:execute] [DEBUG]- (0.005) SELECT `repository_u2d`.`id`, `repository_u2d`.`user_id`, `repository_u2d`.`dep_id` FROM `repository_u2d` WHERE `repository_u2d`.`user_id` = 1 LIMIT 21; args=(1,)
DEBUG 2019-02-19 11:13:09,552 [Thread-13:12164] [django.db.backends:111] [utils:execute] [DEBUG]- (0.001) SELECT `repository_u2d`.`id`, `repository_u2d`.`user_id`, `repository_u2d`.`dep_id` FROM `repository_u2d` WHERE `repository_u2d`.`user_id` = 1 LIMIT 21; args=(1,)
DEBUG 2019-02-19 11:13:36,445 [Thread-54:22776] [django.db.backends:111] [utils:execute] [DEBUG]- (0.001) SELECT @@SQL_AUTO_IS_NULL; args=None
DEBUG 2019-02-19 11:13:36,447 [Thread-54:22776] [django.db.backends:111] [utils:execute] [DEBUG]- (0.002) SET SESSION TRANSACTION ISOLATION LEVEL READ COMMITTED; args=None
DEBUG 2019-02-19 11:13:36,454 [Thread-54:22776] [django.db.backends:111] [utils:execute] [DEBUG]- (0.004) SELECT VERSION(); args=None
DEBUG 2019-02-19 11:15:19,464 [Thread-13:12164] [django.db.backends:111] [utils:execute] [DEBUG]- (0.002) SELECT `repository_u2d`.`id`, `repository_u2d`.`user_id`, `repository_u2d`.`dep_id` FROM `repository_u2d` WHERE `repository_u2d`.`user_id` = 1 LIMIT 21; args=(1,)
DEBUG 2019-02-19 11:15:22,197 [Thread-59:5604] [django.db.backends:111] [utils:execute] [DEBUG]- (0.002) SELECT @@SQL_AUTO_IS_NULL; args=None
DEBUG 2019-02-19 11:15:22,201 [Thread-59:5604] [django.db.backends:111] [utils:execute] [DEBUG]- (0.001) SET SESSION TRANSACTION ISOLATION LEVEL READ COMMITTED; args=None
DEBUG 2019-02-19 11:15:22,204 [Thread-59:5604] [django.db.backends:111] [utils:execute] [DEBUG]- (0.002) SELECT VERSION(); args=None
DEBUG 2019-02-19 11:15:37,029 [Thread-13:12164] [django.db.backends:111] [utils:execute] [DEBUG]- (0.002) SELECT `repository_u2d`.`id`, `repository_u2d`.`user_id`, `repository_u2d`.`dep_id` FROM `repository_u2d` WHERE `repository_u2d`.`user_id` = 1 LIMIT 1; args=(1,)
DEBUG 2019-02-19 11:15:45,481 [Thread-13:12164] [django.db.backends:111] [utils:execute] [DEBUG]- (0.001) SELECT `repository_u2d`.`id`, `repository_u2d`.`user_id`, `repository_u2d`.`dep_id` FROM `repository_u2d` WHERE `repository_u2d`.`user_id` = 1 LIMIT 1; args=(1,)
DEBUG 2019-02-19 11:16:03,389 [Thread-13:12164] [django.db.backends:111] [utils:execute] [DEBUG]- (0.001) SELECT `repository_u2d`.`id`, `repository_u2d`.`user_id`, `repository_u2d`.`dep_id` FROM `repository_u2d` WHERE `repository_u2d`.`user_id` = 1 LIMIT 21; args=(1,)
DEBUG 2019-02-19 11:16:31,784 [Dummy-1:22824] [django.db.backends:111] [utils:execute] [DEBUG]- (0.001) SELECT @@SQL_AUTO_IS_NULL; args=None
DEBUG 2019-02-19 11:16:31,785 [Dummy-1:22824] [django.db.backends:111] [utils:execute] [DEBUG]- (0.000) SET SESSION TRANSACTION ISOLATION LEVEL READ COMMITTED; args=None
DEBUG 2019-02-19 11:16:31,786 [Dummy-1:22824] [django.db.backends:111] [utils:execute] [DEBUG]- (0.001) SELECT VERSION(); args=None
DEBUG 2019-02-19 11:16:31,891 [Dummy-1:22824] [django.db.backends:111] [utils:execute] [DEBUG]- (0.000) SET SESSION TRANSACTION ISOLATION LEVEL READ COMMITTED; args=None
DEBUG 2019-02-19 11:16:31,894 [Dummy-1:22824] [django.db.backends:111] [utils:execute] [DEBUG]- (0.004) SHOW FULL TABLES; args=None
DEBUG 2019-02-19 11:16:31,901 [Dummy-1:22824] [django.db.backends:111] [utils:execute] [DEBUG]- (0.001) SELECT `django_migrations`.`app`, `django_migrations`.`name` FROM `django_migrations`; args=()
DEBUG 2019-02-19 11:16:39,231 [Thread-2:20444] [django.db.backends:111] [utils:execute] [DEBUG]- (0.001) SELECT @@SQL_AUTO_IS_NULL; args=None
DEBUG 2019-02-19 11:16:39,232 [Thread-2:20444] [django.db.backends:111] [utils:execute] [DEBUG]- (0.001) SET SESSION TRANSACTION ISOLATION LEVEL READ COMMITTED; args=None
DEBUG 2019-02-19 11:16:39,232 [Thread-2:20444] [django.db.backends:111] [utils:execute] [DEBUG]- (0.000) SELECT VERSION(); args=None
DEBUG 2019-02-19 11:16:39,235 [Thread-2:20444] [django.db.backends:111] [utils:execute] [DEBUG]- (0.000) SET SESSION TRANSACTION ISOLATION LEVEL READ COMMITTED; args=None
DEBUG 2019-02-19 11:16:39,237 [Thread-2:20444] [django.db.backends:111] [utils:execute] [DEBUG]- (0.001) SELECT `django_session`.`session_key`, `django_session`.`session_data`, `django_session`.`expire_date` FROM `django_session` WHERE (`django_session`.`session_key` = '0u5rozh3lc5qezdhht6wcg9rg9gi21ko' AND `django_session`.`expire_date` > '2019-02-19 11:16:39.225689'); args=('0u5rozh3lc5qezdhht6wcg9rg9gi21ko', '2019-02-19 11:16:39.225689')
DEBUG 2019-02-19 11:16:39,247 [Thread-2:20444] [django.db.backends:111] [utils:execute] [DEBUG]- (0.002) SELECT `repository_userprofile`.`password`, `repository_userprofile`.`last_login`, `repository_userprofile`.`is_superuser`, `repository_userprofile`.`username`, `repository_userprofile`.`first_name`, `repository_userprofile`.`last_name`, `repository_userprofile`.`email`, `repository_userprofile`.`is_staff`, `repository_userprofile`.`is_active`, `repository_userprofile`.`date_joined`, `repository_userprofile`.`id`, `repository_userprofile`.`nick_name`, `repository_userprofile`.`create_time`, `repository_userprofile`.`image`, `repository_userprofile`.`models_introdoction`, `repository_userprofile`.`is_admin`, `repository_userprofile`.`is_approver` FROM `repository_userprofile` WHERE `repository_userprofile`.`id` = 1; args=(1,)
DEBUG 2019-02-19 11:16:39,251 [Thread-2:20444] [django.db.backends:111] [utils:execute] [DEBUG]- (0.001) SELECT `repository_u2d`.`id`, `repository_u2d`.`user_id`, `repository_u2d`.`dep_id` FROM `repository_u2d` WHERE `repository_u2d`.`user_id` = 1 LIMIT 1; args=(1,)
DEBUG 2019-02-19 11:16:39,254 [Thread-2:20444] [django.db.backends:111] [utils:execute] [DEBUG]- (0.002) SELECT `repository_file2depmodel`.`id`, `repository_file2depmodel`.`file_id`, `repository_file2depmodel`.`dep_id` FROM `repository_file2depmodel` WHERE `repository_file2depmodel`.`dep_id` = 1 LIMIT 21; args=(1,)
DEBUG 2019-02-19 11:16:39,257 [Thread-2:20444] [django.db.backends:111] [utils:execute] [DEBUG]- (0.002) SELECT `repository_file2depmodel`.`id`, `repository_file2depmodel`.`file_id`, `repository_file2depmodel`.`dep_id` FROM `repository_file2depmodel` WHERE `repository_file2depmodel`.`dep_id` = 1; args=(1,)
DEBUG 2019-02-19 11:16:39,306 [Thread-2:20444] [django.db.backends:111] [utils:execute] [DEBUG]- (0.001) SELECT `repository_projectmodel`.`nid`, `repository_projectmodel`.`Project_name` FROM `repository_projectmodel`; args=()
DEBUG 2019-02-19 11:16:39,316 [Thread-2:20444] [django.db.backends:111] [utils:execute] [DEBUG]- (0.002) SELECT `repository_addfilemodel`.`nid`, `repository_addfilemodel`.`models_Filename`, `repository_addfilemodel`.`models_Filedes`, `repository_addfilemodel`.`read_count`, `repository_addfilemodel`.`models_Fileupload`, `repository_addfilemodel`.`create_time`, `repository_addfilemodel`.`department_id`, `repository_addfilemodel`.`user_id_id`, `repository_addfilemodel`.`models_Filetype_type_id`, `repository_addfilemodel`.`status`, `repository_addfilemodel`.`models_Fileproject_id`, `repository_addfilemodel`.`reason` FROM `repository_addfilemodel` WHERE `repository_addfilemodel`.`nid` = 10; args=(10,)
DEBUG 2019-02-19 11:16:39,317 [Thread-2:20444] [django.template:878] [base:_resolve_lookup] [DEBUG]- Exception while resolving variable 'models_Filedes' in template 'Ace-filelist-transaction-listing.html'.
Traceback (most recent call last):
  File "C:\Python\Webproject\share2\env\lib\site-packages\django\template\base.py", line 835, in _resolve_lookup
    current = current[bit]
TypeError: 'File2DepModel' object is not subscriptable

During handling of the above exception, another exception occurred:

Traceback (most recent call last):
  File "C:\Python\Webproject\share2\env\lib\site-packages\django\template\base.py", line 843, in _resolve_lookup
    current = getattr(current, bit)
AttributeError: 'File2DepModel' object has no attribute 'models_Filedes'

During handling of the above exception, another exception occurred:

Traceback (most recent call last):
  File "C:\Python\Webproject\share2\env\lib\site-packages\django\template\base.py", line 849, in _resolve_lookup
    current = current[int(bit)]
ValueError: invalid literal for int() with base 10: 'models_Filedes'

During handling of the above exception, another exception occurred:

Traceback (most recent call last):
  File "C:\Python\Webproject\share2\env\lib\site-packages\django\template\base.py", line 856, in _resolve_lookup
    (bit, current))  # missing attribute
django.template.base.VariableDoesNotExist: Failed lookup for key [models_Filedes] in <File2DepModel: File2DepModel object (1)>
DEBUG 2019-02-19 11:16:39,322 [Thread-2:20444] [django.db.backends:111] [utils:execute] [DEBUG]- (0.002) SELECT `repository_userprofile`.`password`, `repository_userprofile`.`last_login`, `repository_userprofile`.`is_superuser`, `repository_userprofile`.`username`, `repository_userprofile`.`first_name`, `repository_userprofile`.`last_name`, `repository_userprofile`.`email`, `repository_userprofile`.`is_staff`, `repository_userprofile`.`is_active`, `repository_userprofile`.`date_joined`, `repository_userprofile`.`id`, `repository_userprofile`.`nick_name`, `repository_userprofile`.`create_time`, `repository_userprofile`.`image`, `repository_userprofile`.`models_introdoction`, `repository_userprofile`.`is_admin`, `repository_userprofile`.`is_approver` FROM `repository_userprofile` WHERE `repository_userprofile`.`id` = 6; args=(6,)
DEBUG 2019-02-19 11:16:39,326 [Thread-2:20444] [django.db.backends:111] [utils:execute] [DEBUG]- (0.001) SELECT `repository_projectmodel`.`nid`, `repository_projectmodel`.`Project_name` FROM `repository_projectmodel` WHERE `repository_projectmodel`.`nid` = 1; args=(1,)
DEBUG 2019-02-19 11:16:39,329 [Thread-2:20444] [django.db.backends:111] [utils:execute] [DEBUG]- (0.002) SELECT `repository_addfilemodel`.`nid`, `repository_addfilemodel`.`models_Filename`, `repository_addfilemodel`.`models_Filedes`, `repository_addfilemodel`.`read_count`, `repository_addfilemodel`.`models_Fileupload`, `repository_addfilemodel`.`create_time`, `repository_addfilemodel`.`department_id`, `repository_addfilemodel`.`user_id_id`, `repository_addfilemodel`.`models_Filetype_type_id`, `repository_addfilemodel`.`status`, `repository_addfilemodel`.`models_Fileproject_id`, `repository_addfilemodel`.`reason` FROM `repository_addfilemodel` WHERE `repository_addfilemodel`.`nid` = 11; args=(11,)
DEBUG 2019-02-19 11:16:39,330 [Thread-2:20444] [django.template:878] [base:_resolve_lookup] [DEBUG]- Exception while resolving variable 'models_Filedes' in template 'Ace-filelist-transaction-listing.html'.
Traceback (most recent call last):
  File "C:\Python\Webproject\share2\env\lib\site-packages\django\template\base.py", line 835, in _resolve_lookup
    current = current[bit]
TypeError: 'File2DepModel' object is not subscriptable

During handling of the above exception, another exception occurred:

Traceback (most recent call last):
  File "C:\Python\Webproject\share2\env\lib\site-packages\django\template\base.py", line 843, in _resolve_lookup
    current = getattr(current, bit)
AttributeError: 'File2DepModel' object has no attribute 'models_Filedes'

During handling of the above exception, another exception occurred:

Traceback (most recent call last):
  File "C:\Python\Webproject\share2\env\lib\site-packages\django\template\base.py", line 849, in _resolve_lookup
    current = current[int(bit)]
ValueError: invalid literal for int() with base 10: 'models_Filedes'

During handling of the above exception, another exception occurred:

Traceback (most recent call last):
  File "C:\Python\Webproject\share2\env\lib\site-packages\django\template\base.py", line 856, in _resolve_lookup
    (bit, current))  # missing attribute
django.template.base.VariableDoesNotExist: Failed lookup for key [models_Filedes] in <File2DepModel: File2DepModel object (4)>
DEBUG 2019-02-19 11:16:39,333 [Thread-2:20444] [django.db.backends:111] [utils:execute] [DEBUG]- (0.001) SELECT `repository_userprofile`.`password`, `repository_userprofile`.`last_login`, `repository_userprofile`.`is_superuser`, `repository_userprofile`.`username`, `repository_userprofile`.`first_name`, `repository_userprofile`.`last_name`, `repository_userprofile`.`email`, `repository_userprofile`.`is_staff`, `repository_userprofile`.`is_active`, `repository_userprofile`.`date_joined`, `repository_userprofile`.`id`, `repository_userprofile`.`nick_name`, `repository_userprofile`.`create_time`, `repository_userprofile`.`image`, `repository_userprofile`.`models_introdoction`, `repository_userprofile`.`is_admin`, `repository_userprofile`.`is_approver` FROM `repository_userprofile` WHERE `repository_userprofile`.`id` = 6; args=(6,)
DEBUG 2019-02-19 11:16:39,336 [Thread-2:20444] [django.db.backends:111] [utils:execute] [DEBUG]- (0.001) SELECT `repository_projectmodel`.`nid`, `repository_projectmodel`.`Project_name` FROM `repository_projectmodel` WHERE `repository_projectmodel`.`nid` = 1; args=(1,)
DEBUG 2019-02-19 11:16:39,338 [Thread-2:20444] [django.db.backends:111] [utils:execute] [DEBUG]- (0.001) SELECT `repository_addfilemodel`.`nid`, `repository_addfilemodel`.`models_Filename`, `repository_addfilemodel`.`models_Filedes`, `repository_addfilemodel`.`read_count`, `repository_addfilemodel`.`models_Fileupload`, `repository_addfilemodel`.`create_time`, `repository_addfilemodel`.`department_id`, `repository_addfilemodel`.`user_id_id`, `repository_addfilemodel`.`models_Filetype_type_id`, `repository_addfilemodel`.`status`, `repository_addfilemodel`.`models_Fileproject_id`, `repository_addfilemodel`.`reason` FROM `repository_addfilemodel` WHERE `repository_addfilemodel`.`nid` = 22; args=(22,)
DEBUG 2019-02-19 11:16:39,339 [Thread-2:20444] [django.template:878] [base:_resolve_lookup] [DEBUG]- Exception while resolving variable 'models_Filedes' in template 'Ace-filelist-transaction-listing.html'.
Traceback (most recent call last):
  File "C:\Python\Webproject\share2\env\lib\site-packages\django\template\base.py", line 835, in _resolve_lookup
    current = current[bit]
TypeError: 'File2DepModel' object is not subscriptable

During handling of the above exception, another exception occurred:

Traceback (most recent call last):
  File "C:\Python\Webproject\share2\env\lib\site-packages\django\template\base.py", line 843, in _resolve_lookup
    current = getattr(current, bit)
AttributeError: 'File2DepModel' object has no attribute 'models_Filedes'

During handling of the above exception, another exception occurred:

Traceback (most recent call last):
  File "C:\Python\Webproject\share2\env\lib\site-packages\django\template\base.py", line 849, in _resolve_lookup
    current = current[int(bit)]
ValueError: invalid literal for int() with base 10: 'models_Filedes'

During handling of the above exception, another exception occurred:

Traceback (most recent call last):
  File "C:\Python\Webproject\share2\env\lib\site-packages\django\template\base.py", line 856, in _resolve_lookup
    (bit, current))  # missing attribute
django.template.base.VariableDoesNotExist: Failed lookup for key [models_Filedes] in <File2DepModel: File2DepModel object (17)>
DEBUG 2019-02-19 11:16:39,342 [Thread-2:20444] [django.db.backends:111] [utils:execute] [DEBUG]- (0.001) SELECT `repository_userprofile`.`password`, `repository_userprofile`.`last_login`, `repository_userprofile`.`is_superuser`, `repository_userprofile`.`username`, `repository_userprofile`.`first_name`, `repository_userprofile`.`last_name`, `repository_userprofile`.`email`, `repository_userprofile`.`is_staff`, `repository_userprofile`.`is_active`, `repository_userprofile`.`date_joined`, `repository_userprofile`.`id`, `repository_userprofile`.`nick_name`, `repository_userprofile`.`create_time`, `repository_userprofile`.`image`, `repository_userprofile`.`models_introdoction`, `repository_userprofile`.`is_admin`, `repository_userprofile`.`is_approver` FROM `repository_userprofile` WHERE `repository_userprofile`.`id` = 1; args=(1,)
DEBUG 2019-02-19 11:16:39,345 [Thread-2:20444] [django.db.backends:111] [utils:execute] [DEBUG]- (0.001) SELECT `repository_projectmodel`.`nid`, `repository_projectmodel`.`Project_name` FROM `repository_projectmodel` WHERE `repository_projectmodel`.`nid` = 1; args=(1,)
DEBUG 2019-02-19 11:16:39,347 [Thread-2:20444] [django.db.backends:111] [utils:execute] [DEBUG]- (0.001) SELECT `repository_addfilemodel`.`nid`, `repository_addfilemodel`.`models_Filename`, `repository_addfilemodel`.`models_Filedes`, `repository_addfilemodel`.`read_count`, `repository_addfilemodel`.`models_Fileupload`, `repository_addfilemodel`.`create_time`, `repository_addfilemodel`.`department_id`, `repository_addfilemodel`.`user_id_id`, `repository_addfilemodel`.`models_Filetype_type_id`, `repository_addfilemodel`.`status`, `repository_addfilemodel`.`models_Fileproject_id`, `repository_addfilemodel`.`reason` FROM `repository_addfilemodel` WHERE `repository_addfilemodel`.`nid` = 23; args=(23,)
DEBUG 2019-02-19 11:16:39,348 [Thread-2:20444] [django.template:878] [base:_resolve_lookup] [DEBUG]- Exception while resolving variable 'models_Filedes' in template 'Ace-filelist-transaction-listing.html'.
Traceback (most recent call last):
  File "C:\Python\Webproject\share2\env\lib\site-packages\django\template\base.py", line 835, in _resolve_lookup
    current = current[bit]
TypeError: 'File2DepModel' object is not subscriptable

During handling of the above exception, another exception occurred:

Traceback (most recent call last):
  File "C:\Python\Webproject\share2\env\lib\site-packages\django\template\base.py", line 843, in _resolve_lookup
    current = getattr(current, bit)
AttributeError: 'File2DepModel' object has no attribute 'models_Filedes'

During handling of the above exception, another exception occurred:

Traceback (most recent call last):
  File "C:\Python\Webproject\share2\env\lib\site-packages\django\template\base.py", line 849, in _resolve_lookup
    current = current[int(bit)]
ValueError: invalid literal for int() with base 10: 'models_Filedes'

During handling of the above exception, another exception occurred:

Traceback (most recent call last):
  File "C:\Python\Webproject\share2\env\lib\site-packages\django\template\base.py", line 856, in _resolve_lookup
    (bit, current))  # missing attribute
django.template.base.VariableDoesNotExist: Failed lookup for key [models_Filedes] in <File2DepModel: File2DepModel object (18)>
DEBUG 2019-02-19 11:16:39,352 [Thread-2:20444] [django.db.backends:111] [utils:execute] [DEBUG]- (0.001) SELECT `repository_userprofile`.`password`, `repository_userprofile`.`last_login`, `repository_userprofile`.`is_superuser`, `repository_userprofile`.`username`, `repository_userprofile`.`first_name`, `repository_userprofile`.`last_name`, `repository_userprofile`.`email`, `repository_userprofile`.`is_staff`, `repository_userprofile`.`is_active`, `repository_userprofile`.`date_joined`, `repository_userprofile`.`id`, `repository_userprofile`.`nick_name`, `repository_userprofile`.`create_time`, `repository_userprofile`.`image`, `repository_userprofile`.`models_introdoction`, `repository_userprofile`.`is_admin`, `repository_userprofile`.`is_approver` FROM `repository_userprofile` WHERE `repository_userprofile`.`id` = 1; args=(1,)
DEBUG 2019-02-19 11:16:39,354 [Thread-2:20444] [django.db.backends:111] [utils:execute] [DEBUG]- (0.001) SELECT `repository_projectmodel`.`nid`, `repository_projectmodel`.`Project_name` FROM `repository_projectmodel` WHERE `repository_projectmodel`.`nid` = 1; args=(1,)
DEBUG 2019-02-19 11:16:39,356 [Thread-2:20444] [django.db.backends:111] [utils:execute] [DEBUG]- (0.001) SELECT `repository_addfilemodel`.`nid`, `repository_addfilemodel`.`models_Filename`, `repository_addfilemodel`.`models_Filedes`, `repository_addfilemodel`.`read_count`, `repository_addfilemodel`.`models_Fileupload`, `repository_addfilemodel`.`create_time`, `repository_addfilemodel`.`department_id`, `repository_addfilemodel`.`user_id_id`, `repository_addfilemodel`.`models_Filetype_type_id`, `repository_addfilemodel`.`status`, `repository_addfilemodel`.`models_Fileproject_id`, `repository_addfilemodel`.`reason` FROM `repository_addfilemodel` WHERE `repository_addfilemodel`.`nid` = 48; args=(48,)
DEBUG 2019-02-19 11:16:39,357 [Thread-2:20444] [django.template:878] [base:_resolve_lookup] [DEBUG]- Exception while resolving variable 'models_Filedes' in template 'Ace-filelist-transaction-listing.html'.
Traceback (most recent call last):
  File "C:\Python\Webproject\share2\env\lib\site-packages\django\template\base.py", line 835, in _resolve_lookup
    current = current[bit]
TypeError: 'File2DepModel' object is not subscriptable

During handling of the above exception, another exception occurred:

Traceback (most recent call last):
  File "C:\Python\Webproject\share2\env\lib\site-packages\django\template\base.py", line 843, in _resolve_lookup
    current = getattr(current, bit)
AttributeError: 'File2DepModel' object has no attribute 'models_Filedes'

During handling of the above exception, another exception occurred:

Traceback (most recent call last):
  File "C:\Python\Webproject\share2\env\lib\site-packages\django\template\base.py", line 849, in _resolve_lookup
    current = current[int(bit)]
ValueError: invalid literal for int() with base 10: 'models_Filedes'

During handling of the above exception, another exception occurred:

Traceback (most recent call last):
  File "C:\Python\Webproject\share2\env\lib\site-packages\django\template\base.py", line 856, in _resolve_lookup
    (bit, current))  # missing attribute
django.template.base.VariableDoesNotExist: Failed lookup for key [models_Filedes] in <File2DepModel: File2DepModel object (19)>
DEBUG 2019-02-19 11:16:39,360 [Thread-2:20444] [django.db.backends:111] [utils:execute] [DEBUG]- (0.001) SELECT `repository_userprofile`.`password`, `repository_userprofile`.`last_login`, `repository_userprofile`.`is_superuser`, `repository_userprofile`.`username`, `repository_userprofile`.`first_name`, `repository_userprofile`.`last_name`, `repository_userprofile`.`email`, `repository_userprofile`.`is_staff`, `repository_userprofile`.`is_active`, `repository_userprofile`.`date_joined`, `repository_userprofile`.`id`, `repository_userprofile`.`nick_name`, `repository_userprofile`.`create_time`, `repository_userprofile`.`image`, `repository_userprofile`.`models_introdoction`, `repository_userprofile`.`is_admin`, `repository_userprofile`.`is_approver` FROM `repository_userprofile` WHERE `repository_userprofile`.`id` = 1; args=(1,)
DEBUG 2019-02-19 11:16:39,362 [Thread-2:20444] [django.db.backends:111] [utils:execute] [DEBUG]- (0.001) SELECT `repository_projectmodel`.`nid`, `repository_projectmodel`.`Project_name` FROM `repository_projectmodel` WHERE `repository_projectmodel`.`nid` = 1; args=(1,)
DEBUG 2019-02-19 11:16:39,364 [Thread-2:20444] [django.db.backends:111] [utils:execute] [DEBUG]- (0.001) SELECT `repository_addfilemodel`.`nid`, `repository_addfilemodel`.`models_Filename`, `repository_addfilemodel`.`models_Filedes`, `repository_addfilemodel`.`read_count`, `repository_addfilemodel`.`models_Fileupload`, `repository_addfilemodel`.`create_time`, `repository_addfilemodel`.`department_id`, `repository_addfilemodel`.`user_id_id`, `repository_addfilemodel`.`models_Filetype_type_id`, `repository_addfilemodel`.`status`, `repository_addfilemodel`.`models_Fileproject_id`, `repository_addfilemodel`.`reason` FROM `repository_addfilemodel` WHERE `repository_addfilemodel`.`nid` = 48; args=(48,)
DEBUG 2019-02-19 11:16:39,365 [Thread-2:20444] [django.template:878] [base:_resolve_lookup] [DEBUG]- Exception while resolving variable 'models_Filedes' in template 'Ace-filelist-transaction-listing.html'.
Traceback (most recent call last):
  File "C:\Python\Webproject\share2\env\lib\site-packages\django\template\base.py", line 835, in _resolve_lookup
    current = current[bit]
TypeError: 'File2DepModel' object is not subscriptable

During handling of the above exception, another exception occurred:

Traceback (most recent call last):
  File "C:\Python\Webproject\share2\env\lib\site-packages\django\template\base.py", line 843, in _resolve_lookup
    current = getattr(current, bit)
AttributeError: 'File2DepModel' object has no attribute 'models_Filedes'

During handling of the above exception, another exception occurred:

Traceback (most recent call last):
  File "C:\Python\Webproject\share2\env\lib\site-packages\django\template\base.py", line 849, in _resolve_lookup
    current = current[int(bit)]
ValueError: invalid literal for int() with base 10: 'models_Filedes'

During handling of the above exception, another exception occurred:

Traceback (most recent call last):
  File "C:\Python\Webproject\share2\env\lib\site-packages\django\template\base.py", line 856, in _resolve_lookup
    (bit, current))  # missing attribute
django.template.base.VariableDoesNotExist: Failed lookup for key [models_Filedes] in <File2DepModel: File2DepModel object (20)>
DEBUG 2019-02-19 11:16:39,369 [Thread-2:20444] [django.db.backends:111] [utils:execute] [DEBUG]- (0.001) SELECT `repository_userprofile`.`password`, `repository_userprofile`.`last_login`, `repository_userprofile`.`is_superuser`, `repository_userprofile`.`username`, `repository_userprofile`.`first_name`, `repository_userprofile`.`last_name`, `repository_userprofile`.`email`, `repository_userprofile`.`is_staff`, `repository_userprofile`.`is_active`, `repository_userprofile`.`date_joined`, `repository_userprofile`.`id`, `repository_userprofile`.`nick_name`, `repository_userprofile`.`create_time`, `repository_userprofile`.`image`, `repository_userprofile`.`models_introdoction`, `repository_userprofile`.`is_admin`, `repository_userprofile`.`is_approver` FROM `repository_userprofile` WHERE `repository_userprofile`.`id` = 1; args=(1,)
DEBUG 2019-02-19 11:16:39,371 [Thread-2:20444] [django.db.backends:111] [utils:execute] [DEBUG]- (0.001) SELECT `repository_projectmodel`.`nid`, `repository_projectmodel`.`Project_name` FROM `repository_projectmodel` WHERE `repository_projectmodel`.`nid` = 1; args=(1,)
INFO 2019-02-19 11:16:39,376 [Thread-2:20444] [django.server:124] [basehttp:log_message] [INFO]- "GET /sharefile/filelist/ HTTP/1.1" 200 41972
DEBUG 2019-02-19 11:16:42,640 [Thread-3:10412] [django.db.backends:111] [utils:execute] [DEBUG]- (0.001) SELECT @@SQL_AUTO_IS_NULL; args=None
DEBUG 2019-02-19 11:16:42,641 [Thread-3:10412] [django.db.backends:111] [utils:execute] [DEBUG]- (0.000) SET SESSION TRANSACTION ISOLATION LEVEL READ COMMITTED; args=None
DEBUG 2019-02-19 11:16:42,642 [Thread-3:10412] [django.db.backends:111] [utils:execute] [DEBUG]- (0.001) SELECT VERSION(); args=None
DEBUG 2019-02-19 11:16:42,648 [Thread-3:10412] [django.db.backends:111] [utils:execute] [DEBUG]- (0.001) SET SESSION TRANSACTION ISOLATION LEVEL READ COMMITTED; args=None
DEBUG 2019-02-19 11:16:42,649 [Thread-3:10412] [django.db.backends:111] [utils:execute] [DEBUG]- (0.001) SELECT `django_session`.`session_key`, `django_session`.`session_data`, `django_session`.`expire_date` FROM `django_session` WHERE (`django_session`.`session_key` = '0u5rozh3lc5qezdhht6wcg9rg9gi21ko' AND `django_session`.`expire_date` > '2019-02-19 11:16:42.634259'); args=('0u5rozh3lc5qezdhht6wcg9rg9gi21ko', '2019-02-19 11:16:42.634259')
DEBUG 2019-02-19 11:16:42,652 [Thread-3:10412] [django.db.backends:111] [utils:execute] [DEBUG]- (0.001) SELECT `repository_userprofile`.`password`, `repository_userprofile`.`last_login`, `repository_userprofile`.`is_superuser`, `repository_userprofile`.`username`, `repository_userprofile`.`first_name`, `repository_userprofile`.`last_name`, `repository_userprofile`.`email`, `repository_userprofile`.`is_staff`, `repository_userprofile`.`is_active`, `repository_userprofile`.`date_joined`, `repository_userprofile`.`id`, `repository_userprofile`.`nick_name`, `repository_userprofile`.`create_time`, `repository_userprofile`.`image`, `repository_userprofile`.`models_introdoction`, `repository_userprofile`.`is_admin`, `repository_userprofile`.`is_approver` FROM `repository_userprofile` WHERE `repository_userprofile`.`id` = 1; args=(1,)
DEBUG 2019-02-19 11:16:42,672 [Thread-3:10412] [django.db.backends:111] [utils:execute] [DEBUG]- (0.001) SELECT `repository_dep`.`nid`, `repository_dep`.`title` FROM `repository_dep` LIMIT 21; args=()
DEBUG 2019-02-19 11:16:42,674 [Thread-3:10412] [django.db.backends:111] [utils:execute] [DEBUG]- (0.001) SELECT `repository_projectmodel`.`nid`, `repository_projectmodel`.`Project_name` FROM `repository_projectmodel` LIMIT 21; args=()
DEBUG 2019-02-19 11:16:42,678 [Thread-3:10412] [django.db.backends:111] [utils:execute] [DEBUG]- (0.001) SELECT `repository_dep`.`nid`, `repository_dep`.`title` FROM `repository_dep` LIMIT 21; args=()
DEBUG 2019-02-19 11:16:42,679 [Thread-3:10412] [django.db.backends:111] [utils:execute] [DEBUG]- (0.001) SELECT `repository_projectmodel`.`nid`, `repository_projectmodel`.`Project_name` FROM `repository_projectmodel` LIMIT 21; args=()
DEBUG 2019-02-19 11:16:42,722 [Thread-3:10412] [django.db.backends:111] [utils:execute] [DEBUG]- (0.001) SELECT `repository_dep`.`nid`, `repository_dep`.`title` FROM `repository_dep`; args=()
DEBUG 2019-02-19 11:16:42,725 [Thread-3:10412] [django.db.backends:111] [utils:execute] [DEBUG]- (0.001) SELECT `repository_projectmodel`.`nid`, `repository_projectmodel`.`Project_name` FROM `repository_projectmodel`; args=()
INFO 2019-02-19 11:16:42,729 [Thread-3:10412] [django.server:124] [basehttp:log_message] [INFO]- "GET /sharefile/addfile/ HTTP/1.1" 200 22974
DEBUG 2019-02-19 11:16:42,900 [Thread-4:21452] [django.template:878] [base:_resolve_lookup] [DEBUG]- Exception while resolving variable 'name' in template 'unknown'.
Traceback (most recent call last):
  File "C:\Python\Webproject\share2\env\lib\site-packages\django\core\handlers\exception.py", line 35, in inner
    response = get_response(request)
  File "C:\Python\Webproject\share2\env\lib\site-packages\django\core\handlers\base.py", line 113, in _get_response
    resolver_match = resolver.resolve(request.path_info)
  File "C:\Python\Webproject\share2\env\lib\site-packages\django\urls\resolvers.py", line 523, in resolve
    raise Resolver404({'tried': tried, 'path': new_path})
django.urls.exceptions.Resolver404: {'tried': [[<URLResolver <URLPattern list> (xadmin:xadmin) 'xadmin/'>], [<URLPattern '^$' [name='index']>], [<URLPattern 'index/' [name='index']>], [<URLPattern 'test/' [name='test']>], [<URLPattern 'login/' [name='login']>], [<URLPattern 'logout/' [name='logout']>], [<URLPattern 'register/' [name='register']>], [<URLPattern 'forget/' [name='forget_pwd']>], [<URLPattern 'reset/(?P<active_code>.*)/' [name='reset_pwd']>], [<URLPattern 'modify_pwd/' [name='modify_pwd']>], [<URLResolver <module 'captcha.urls' from 'C:\\Python\\Webproject\\share2\\env\\lib\\site-packages\\captcha\\urls.py'> (None:None) 'captcha/'>], [<URLPattern 'active/(?P<active_code>.*)/' [name='user_active']>], [<URLResolver <module 'sharefile.urls' from 'C:\\Python\\Webproject\\share2\\share2\\share2\\apps\\sharefile\\urls.py'> (sharefile:sharefile) 'sharefile/'>], [<URLResolver <module 'users.urls' from 'C:\\Python\\Webproject\\share2\\share2\\share2\\apps\\users\\urls.py'> (users:users) 'users/'>], [<URLPattern 'media/(?P<path>.*)$'>]], 'path': 'assets/images/custom-select.png'}

During handling of the above exception, another exception occurred:

Traceback (most recent call last):
  File "C:\Python\Webproject\share2\env\lib\site-packages\django\template\base.py", line 835, in _resolve_lookup
    current = current[bit]
TypeError: 'URLResolver' object is not subscriptable

During handling of the above exception, another exception occurred:

Traceback (most recent call last):
  File "C:\Python\Webproject\share2\env\lib\site-packages\django\template\base.py", line 843, in _resolve_lookup
    current = getattr(current, bit)
AttributeError: 'URLResolver' object has no attribute 'name'

During handling of the above exception, another exception occurred:

Traceback (most recent call last):
  File "C:\Python\Webproject\share2\env\lib\site-packages\django\template\base.py", line 849, in _resolve_lookup
    current = current[int(bit)]
ValueError: invalid literal for int() with base 10: 'name'

During handling of the above exception, another exception occurred:

Traceback (most recent call last):
  File "C:\Python\Webproject\share2\env\lib\site-packages\django\template\base.py", line 856, in _resolve_lookup
    (bit, current))  # missing attribute
django.template.base.VariableDoesNotExist: Failed lookup for key [name] in <URLResolver <URLPattern list> (xadmin:xadmin) 'xadmin/'>
DEBUG 2019-02-19 11:16:42,905 [Thread-4:21452] [django.template:878] [base:_resolve_lookup] [DEBUG]- Exception while resolving variable 'name' in template 'unknown'.
Traceback (most recent call last):
  File "C:\Python\Webproject\share2\env\lib\site-packages\django\core\handlers\exception.py", line 35, in inner
    response = get_response(request)
  File "C:\Python\Webproject\share2\env\lib\site-packages\django\core\handlers\base.py", line 113, in _get_response
    resolver_match = resolver.resolve(request.path_info)
  File "C:\Python\Webproject\share2\env\lib\site-packages\django\urls\resolvers.py", line 523, in resolve
    raise Resolver404({'tried': tried, 'path': new_path})
django.urls.exceptions.Resolver404: {'tried': [[<URLResolver <URLPattern list> (xadmin:xadmin) 'xadmin/'>], [<URLPattern '^$' [name='index']>], [<URLPattern 'index/' [name='index']>], [<URLPattern 'test/' [name='test']>], [<URLPattern 'login/' [name='login']>], [<URLPattern 'logout/' [name='logout']>], [<URLPattern 'register/' [name='register']>], [<URLPattern 'forget/' [name='forget_pwd']>], [<URLPattern 'reset/(?P<active_code>.*)/' [name='reset_pwd']>], [<URLPattern 'modify_pwd/' [name='modify_pwd']>], [<URLResolver <module 'captcha.urls' from 'C:\\Python\\Webproject\\share2\\env\\lib\\site-packages\\captcha\\urls.py'> (None:None) 'captcha/'>], [<URLPattern 'active/(?P<active_code>.*)/' [name='user_active']>], [<URLResolver <module 'sharefile.urls' from 'C:\\Python\\Webproject\\share2\\share2\\share2\\apps\\sharefile\\urls.py'> (sharefile:sharefile) 'sharefile/'>], [<URLResolver <module 'users.urls' from 'C:\\Python\\Webproject\\share2\\share2\\share2\\apps\\users\\urls.py'> (users:users) 'users/'>], [<URLPattern 'media/(?P<path>.*)$'>]], 'path': 'assets/images/custom-select.png'}

During handling of the above exception, another exception occurred:

Traceback (most recent call last):
  File "C:\Python\Webproject\share2\env\lib\site-packages\django\template\base.py", line 835, in _resolve_lookup
    current = current[bit]
TypeError: 'URLResolver' object is not subscriptable

During handling of the above exception, another exception occurred:

Traceback (most recent call last):
  File "C:\Python\Webproject\share2\env\lib\site-packages\django\template\base.py", line 843, in _resolve_lookup
    current = getattr(current, bit)
AttributeError: 'URLResolver' object has no attribute 'name'

During handling of the above exception, another exception occurred:

Traceback (most recent call last):
  File "C:\Python\Webproject\share2\env\lib\site-packages\django\template\base.py", line 849, in _resolve_lookup
    current = current[int(bit)]
ValueError: invalid literal for int() with base 10: 'name'

During handling of the above exception, another exception occurred:

Traceback (most recent call last):
  File "C:\Python\Webproject\share2\env\lib\site-packages\django\template\base.py", line 856, in _resolve_lookup
    (bit, current))  # missing attribute
django.template.base.VariableDoesNotExist: Failed lookup for key [name] in <URLResolver <module 'captcha.urls' from 'C:\\Python\\Webproject\\share2\\env\\lib\\site-packages\\captcha\\urls.py'> (None:None) 'captcha/'>
DEBUG 2019-02-19 11:16:42,915 [Thread-4:21452] [django.template:878] [base:_resolve_lookup] [DEBUG]- Exception while resolving variable 'name' in template 'unknown'.
Traceback (most recent call last):
  File "C:\Python\Webproject\share2\env\lib\site-packages\django\core\handlers\exception.py", line 35, in inner
    response = get_response(request)
  File "C:\Python\Webproject\share2\env\lib\site-packages\django\core\handlers\base.py", line 113, in _get_response
    resolver_match = resolver.resolve(request.path_info)
  File "C:\Python\Webproject\share2\env\lib\site-packages\django\urls\resolvers.py", line 523, in resolve
    raise Resolver404({'tried': tried, 'path': new_path})
django.urls.exceptions.Resolver404: {'tried': [[<URLResolver <URLPattern list> (xadmin:xadmin) 'xadmin/'>], [<URLPattern '^$' [name='index']>], [<URLPattern 'index/' [name='index']>], [<URLPattern 'test/' [name='test']>], [<URLPattern 'login/' [name='login']>], [<URLPattern 'logout/' [name='logout']>], [<URLPattern 'register/' [name='register']>], [<URLPattern 'forget/' [name='forget_pwd']>], [<URLPattern 'reset/(?P<active_code>.*)/' [name='reset_pwd']>], [<URLPattern 'modify_pwd/' [name='modify_pwd']>], [<URLResolver <module 'captcha.urls' from 'C:\\Python\\Webproject\\share2\\env\\lib\\site-packages\\captcha\\urls.py'> (None:None) 'captcha/'>], [<URLPattern 'active/(?P<active_code>.*)/' [name='user_active']>], [<URLResolver <module 'sharefile.urls' from 'C:\\Python\\Webproject\\share2\\share2\\share2\\apps\\sharefile\\urls.py'> (sharefile:sharefile) 'sharefile/'>], [<URLResolver <module 'users.urls' from 'C:\\Python\\Webproject\\share2\\share2\\share2\\apps\\users\\urls.py'> (users:users) 'users/'>], [<URLPattern 'media/(?P<path>.*)$'>]], 'path': 'assets/images/custom-select.png'}

During handling of the above exception, another exception occurred:

Traceback (most recent call last):
  File "C:\Python\Webproject\share2\env\lib\site-packages\django\template\base.py", line 835, in _resolve_lookup
    current = current[bit]
TypeError: 'URLResolver' object is not subscriptable

During handling of the above exception, another exception occurred:

Traceback (most recent call last):
  File "C:\Python\Webproject\share2\env\lib\site-packages\django\template\base.py", line 843, in _resolve_lookup
    current = getattr(current, bit)
AttributeError: 'URLResolver' object has no attribute 'name'

During handling of the above exception, another exception occurred:

Traceback (most recent call last):
  File "C:\Python\Webproject\share2\env\lib\site-packages\django\template\base.py", line 849, in _resolve_lookup
    current = current[int(bit)]
ValueError: invalid literal for int() with base 10: 'name'

During handling of the above exception, another exception occurred:

Traceback (most recent call last):
  File "C:\Python\Webproject\share2\env\lib\site-packages\django\template\base.py", line 856, in _resolve_lookup
    (bit, current))  # missing attribute
django.template.base.VariableDoesNotExist: Failed lookup for key [name] in <URLResolver <module 'sharefile.urls' from 'C:\\Python\\Webproject\\share2\\share2\\share2\\apps\\sharefile\\urls.py'> (sharefile:sharefile) 'sharefile/'>
DEBUG 2019-02-19 11:16:42,921 [Thread-4:21452] [django.template:878] [base:_resolve_lookup] [DEBUG]- Exception while resolving variable 'name' in template 'unknown'.
Traceback (most recent call last):
  File "C:\Python\Webproject\share2\env\lib\site-packages\django\core\handlers\exception.py", line 35, in inner
    response = get_response(request)
  File "C:\Python\Webproject\share2\env\lib\site-packages\django\core\handlers\base.py", line 113, in _get_response
    resolver_match = resolver.resolve(request.path_info)
  File "C:\Python\Webproject\share2\env\lib\site-packages\django\urls\resolvers.py", line 523, in resolve
    raise Resolver404({'tried': tried, 'path': new_path})
django.urls.exceptions.Resolver404: {'tried': [[<URLResolver <URLPattern list> (xadmin:xadmin) 'xadmin/'>], [<URLPattern '^$' [name='index']>], [<URLPattern 'index/' [name='index']>], [<URLPattern 'test/' [name='test']>], [<URLPattern 'login/' [name='login']>], [<URLPattern 'logout/' [name='logout']>], [<URLPattern 'register/' [name='register']>], [<URLPattern 'forget/' [name='forget_pwd']>], [<URLPattern 'reset/(?P<active_code>.*)/' [name='reset_pwd']>], [<URLPattern 'modify_pwd/' [name='modify_pwd']>], [<URLResolver <module 'captcha.urls' from 'C:\\Python\\Webproject\\share2\\env\\lib\\site-packages\\captcha\\urls.py'> (None:None) 'captcha/'>], [<URLPattern 'active/(?P<active_code>.*)/' [name='user_active']>], [<URLResolver <module 'sharefile.urls' from 'C:\\Python\\Webproject\\share2\\share2\\share2\\apps\\sharefile\\urls.py'> (sharefile:sharefile) 'sharefile/'>], [<URLResolver <module 'users.urls' from 'C:\\Python\\Webproject\\share2\\share2\\share2\\apps\\users\\urls.py'> (users:users) 'users/'>], [<URLPattern 'media/(?P<path>.*)$'>]], 'path': 'assets/images/custom-select.png'}

During handling of the above exception, another exception occurred:

Traceback (most recent call last):
  File "C:\Python\Webproject\share2\env\lib\site-packages\django\template\base.py", line 835, in _resolve_lookup
    current = current[bit]
TypeError: 'URLResolver' object is not subscriptable

During handling of the above exception, another exception occurred:

Traceback (most recent call last):
  File "C:\Python\Webproject\share2\env\lib\site-packages\django\template\base.py", line 843, in _resolve_lookup
    current = getattr(current, bit)
AttributeError: 'URLResolver' object has no attribute 'name'

During handling of the above exception, another exception occurred:

Traceback (most recent call last):
  File "C:\Python\Webproject\share2\env\lib\site-packages\django\template\base.py", line 849, in _resolve_lookup
    current = current[int(bit)]
ValueError: invalid literal for int() with base 10: 'name'

During handling of the above exception, another exception occurred:

Traceback (most recent call last):
  File "C:\Python\Webproject\share2\env\lib\site-packages\django\template\base.py", line 856, in _resolve_lookup
    (bit, current))  # missing attribute
django.template.base.VariableDoesNotExist: Failed lookup for key [name] in <URLResolver <module 'users.urls' from 'C:\\Python\\Webproject\\share2\\share2\\share2\\apps\\users\\urls.py'> (users:users) 'users/'>
WARNING 2019-02-19 11:16:42,927 [Thread-4:21452] [django.server:124] [basehttp:log_message] [WARNING]- "GET /assets/images/custom-select.png HTTP/1.1" 404 3763
DEBUG 2019-02-19 11:16:58,367 [Thread-8:21284] [django.db.backends:111] [utils:execute] [DEBUG]- (0.002) SELECT @@SQL_AUTO_IS_NULL; args=None
DEBUG 2019-02-19 11:16:58,370 [Thread-8:21284] [django.db.backends:111] [utils:execute] [DEBUG]- (0.001) SET SESSION TRANSACTION ISOLATION LEVEL READ COMMITTED; args=None
DEBUG 2019-02-19 11:16:58,372 [Thread-8:21284] [django.db.backends:111] [utils:execute] [DEBUG]- (0.001) SELECT VERSION(); args=None
DEBUG 2019-02-19 11:16:58,377 [Thread-8:21284] [django.db.backends:111] [utils:execute] [DEBUG]- (0.001) SET SESSION TRANSACTION ISOLATION LEVEL READ COMMITTED; args=None
DEBUG 2019-02-19 11:16:58,380 [Thread-8:21284] [django.db.backends:111] [utils:execute] [DEBUG]- (0.003) SELECT `django_session`.`session_key`, `django_session`.`session_data`, `django_session`.`expire_date` FROM `django_session` WHERE (`django_session`.`session_key` = '0u5rozh3lc5qezdhht6wcg9rg9gi21ko' AND `django_session`.`expire_date` > '2019-02-19 11:16:58.360656'); args=('0u5rozh3lc5qezdhht6wcg9rg9gi21ko', '2019-02-19 11:16:58.360656')
DEBUG 2019-02-19 11:16:58,385 [Thread-8:21284] [django.db.backends:111] [utils:execute] [DEBUG]- (0.003) SELECT `repository_userprofile`.`password`, `repository_userprofile`.`last_login`, `repository_userprofile`.`is_superuser`, `repository_userprofile`.`username`, `repository_userprofile`.`first_name`, `repository_userprofile`.`last_name`, `repository_userprofile`.`email`, `repository_userprofile`.`is_staff`, `repository_userprofile`.`is_active`, `repository_userprofile`.`date_joined`, `repository_userprofile`.`id`, `repository_userprofile`.`nick_name`, `repository_userprofile`.`create_time`, `repository_userprofile`.`image`, `repository_userprofile`.`models_introdoction`, `repository_userprofile`.`is_admin`, `repository_userprofile`.`is_approver` FROM `repository_userprofile` WHERE `repository_userprofile`.`id` = 1; args=(1,)
INFO 2019-02-19 11:16:58,386 [Thread-8:21284] [django:60] [AddfileView:post] [INFO]- user
DEBUG 2019-02-19 11:16:58,389 [Thread-8:21284] [django.db.backends:111] [utils:execute] [DEBUG]- (0.002) SELECT `repository_userprofile`.`password`, `repository_userprofile`.`last_login`, `repository_userprofile`.`is_superuser`, `repository_userprofile`.`username`, `repository_userprofile`.`first_name`, `repository_userprofile`.`last_name`, `repository_userprofile`.`email`, `repository_userprofile`.`is_staff`, `repository_userprofile`.`is_active`, `repository_userprofile`.`date_joined`, `repository_userprofile`.`id`, `repository_userprofile`.`nick_name`, `repository_userprofile`.`create_time`, `repository_userprofile`.`image`, `repository_userprofile`.`models_introdoction`, `repository_userprofile`.`is_admin`, `repository_userprofile`.`is_approver` FROM `repository_userprofile` WHERE `repository_userprofile`.`id` = 1 LIMIT 1; args=(1,)
DEBUG 2019-02-19 11:16:58,409 [Thread-8:21284] [django.db.backends:111] [utils:execute] [DEBUG]- (0.001) SELECT `repository_u2d`.`id`, `repository_u2d`.`user_id`, `repository_u2d`.`dep_id` FROM `repository_u2d` WHERE `repository_u2d`.`user_id` = 1 LIMIT 21; args=(1,)
DEBUG 2019-02-19 11:16:58,427 [Thread-8:21284] [django.db.backends:111] [utils:execute] [DEBUG]- (0.001) SELECT `repository_u2d`.`id`, `repository_u2d`.`user_id`, `repository_u2d`.`dep_id` FROM `repository_u2d` WHERE `repository_u2d`.`user_id` = 1 LIMIT 21; args=(1,)
DEBUG 2019-02-19 11:16:58,429 [Thread-8:21284] [django.db.backends:111] [utils:execute] [DEBUG]- (0.001) SELECT `repository_u2d`.`id`, `repository_u2d`.`user_id`, `repository_u2d`.`dep_id` FROM `repository_u2d` WHERE `repository_u2d`.`user_id` = 1 LIMIT 21; args=(1,)
DEBUG 2019-02-19 11:16:58,439 [Thread-8:21284] [django.db.backends:111] [utils:execute] [DEBUG]- (0.001) SELECT `repository_u2d`.`id`, `repository_u2d`.`user_id`, `repository_u2d`.`dep_id` FROM `repository_u2d` WHERE `repository_u2d`.`user_id` = 1 LIMIT 21; args=(1,)
INFO 2019-02-19 11:16:58,461 [Thread-8:21284] [django:78] [AddfileView:post] [INFO]- 添加文件
INFO 2019-02-19 11:16:58,462 [Thread-8:21284] [django:79] [AddfileView:post] [INFO]- ********************
INFO 2019-02-19 11:16:58,463 [Thread-8:21284] [django:80] [AddfileView:post] [INFO]- <QueryDict: {'filename': ['部门测试'], 'filedes': ['呃 '], 'filetype': ['内部'], 'fileproject': ['测试项目1'], 'csrfmiddlewaretoken': ['vCNOoy0BKofy58bbWKpSIvXLtMEXjhuC3jDpN0QNMmfZ7HKcUzHxBYkPltIWP90y']}>
DEBUG 2019-02-19 11:16:58,479 [Thread-8:21284] [django.db.backends:111] [utils:execute] [DEBUG]- (0.001) SELECT `repository_u2d`.`id`, `repository_u2d`.`user_id`, `repository_u2d`.`dep_id` FROM `repository_u2d` WHERE `repository_u2d`.`user_id` = 1 LIMIT 1; args=(1,)
DEBUG 2019-02-19 11:16:58,492 [Thread-8:21284] [django.db.backends:111] [utils:execute] [DEBUG]- (0.001) SELECT `repository_projectmodel`.`nid`, `repository_projectmodel`.`Project_name` FROM `repository_projectmodel` WHERE `repository_projectmodel`.`Project_name` = '测试项目1'; args=('测试项目1',)
INFO 2019-02-19 11:16:58,505 [Thread-8:21284] [django:127] [AddfileView:post] [INFO]- 1
DEBUG 2019-02-19 11:16:58,515 [Thread-8:21284] [django.db.backends:111] [utils:execute] [DEBUG]- (0.004) INSERT INTO `repository_addfilemodel` (`models_Filename`, `models_Filedes`, `read_count`, `models_Fileupload`, `create_time`, `department_id`, `user_id_id`, `models_Filetype_type_id`, `status`, `models_Fileproject_id`, `reason`) VALUES ('部门测试', '呃 ', 0, 'file/2019/02/Login_QBcFWby.png', '2019-02-19 11:16:58.511055', NULL, 1, 2, '0', 1, '无'); args=['部门测试', '呃 ', 0, 'file/2019/02/Login_QBcFWby.png', '2019-02-19 11:16:58.511055', None, 1, 2, '0', 1, '无']
DEBUG 2019-02-19 11:16:58,668 [Thread-8:21284] [django.db.backends:111] [utils:execute] [DEBUG]- (0.001) SELECT `repository_u2d`.`id`, `repository_u2d`.`user_id`, `repository_u2d`.`dep_id` FROM `repository_u2d` WHERE `repository_u2d`.`user_id` = 1 LIMIT 21; args=(1,)
ERROR 2019-02-19 11:16:59,648 [Thread-8:21284] [django.server:124] [basehttp:log_message] [ERROR]- "POST /sharefile/addfile/ HTTP/1.1" 500 111245
DEBUG 2019-02-19 11:19:08,577 [Dummy-1:2256] [django.db.backends:111] [utils:execute] [DEBUG]- (0.001) SELECT @@SQL_AUTO_IS_NULL; args=None
DEBUG 2019-02-19 11:19:08,577 [Dummy-1:2256] [django.db.backends:111] [utils:execute] [DEBUG]- (0.000) SET SESSION TRANSACTION ISOLATION LEVEL READ COMMITTED; args=None
DEBUG 2019-02-19 11:19:08,578 [Dummy-1:2256] [django.db.backends:111] [utils:execute] [DEBUG]- (0.000) SELECT VERSION(); args=None
DEBUG 2019-02-19 11:19:08,683 [Dummy-1:2256] [django.db.backends:111] [utils:execute] [DEBUG]- (0.000) SET SESSION TRANSACTION ISOLATION LEVEL READ COMMITTED; args=None
DEBUG 2019-02-19 11:19:08,687 [Dummy-1:2256] [django.db.backends:111] [utils:execute] [DEBUG]- (0.003) SHOW FULL TABLES; args=None
DEBUG 2019-02-19 11:19:08,694 [Dummy-1:2256] [django.db.backends:111] [utils:execute] [DEBUG]- (0.001) SELECT `django_migrations`.`app`, `django_migrations`.`name` FROM `django_migrations`; args=()
DEBUG 2019-02-19 11:30:22,214 [Dummy-1:20740] [django.db.backends:111] [utils:execute] [DEBUG]- (0.001) SELECT @@SQL_AUTO_IS_NULL; args=None
DEBUG 2019-02-19 11:30:22,215 [Dummy-1:20740] [django.db.backends:111] [utils:execute] [DEBUG]- (0.000) SET SESSION TRANSACTION ISOLATION LEVEL READ COMMITTED; args=None
DEBUG 2019-02-19 11:30:22,215 [Dummy-1:20740] [django.db.backends:111] [utils:execute] [DEBUG]- (0.001) SELECT VERSION(); args=None
DEBUG 2019-02-19 11:30:22,317 [Dummy-1:20740] [django.db.backends:111] [utils:execute] [DEBUG]- (0.001) SET SESSION TRANSACTION ISOLATION LEVEL READ COMMITTED; args=None
DEBUG 2019-02-19 11:30:22,319 [Dummy-1:20740] [django.db.backends:111] [utils:execute] [DEBUG]- (0.003) SHOW FULL TABLES; args=None
DEBUG 2019-02-19 11:30:22,326 [Dummy-1:20740] [django.db.backends:111] [utils:execute] [DEBUG]- (0.001) SELECT `django_migrations`.`app`, `django_migrations`.`name` FROM `django_migrations`; args=()
DEBUG 2019-02-19 11:30:42,090 [Thread-2:22256] [django.db.backends:111] [utils:execute] [DEBUG]- (0.001) SELECT @@SQL_AUTO_IS_NULL; args=None
DEBUG 2019-02-19 11:30:42,090 [Thread-2:22256] [django.db.backends:111] [utils:execute] [DEBUG]- (0.000) SET SESSION TRANSACTION ISOLATION LEVEL READ COMMITTED; args=None
DEBUG 2019-02-19 11:30:42,091 [Thread-2:22256] [django.db.backends:111] [utils:execute] [DEBUG]- (0.000) SELECT VERSION(); args=None
DEBUG 2019-02-19 11:30:42,094 [Thread-2:22256] [django.db.backends:111] [utils:execute] [DEBUG]- (0.001) SET SESSION TRANSACTION ISOLATION LEVEL READ COMMITTED; args=None
DEBUG 2019-02-19 11:30:42,095 [Thread-2:22256] [django.db.backends:111] [utils:execute] [DEBUG]- (0.001) SELECT `django_session`.`session_key`, `django_session`.`session_data`, `django_session`.`expire_date` FROM `django_session` WHERE (`django_session`.`session_key` = '0u5rozh3lc5qezdhht6wcg9rg9gi21ko' AND `django_session`.`expire_date` > '2019-02-19 11:30:42.085822'); args=('0u5rozh3lc5qezdhht6wcg9rg9gi21ko', '2019-02-19 11:30:42.085822')
DEBUG 2019-02-19 11:30:42,101 [Thread-2:22256] [django.db.backends:111] [utils:execute] [DEBUG]- (0.001) SELECT `repository_userprofile`.`password`, `repository_userprofile`.`last_login`, `repository_userprofile`.`is_superuser`, `repository_userprofile`.`username`, `repository_userprofile`.`first_name`, `repository_userprofile`.`last_name`, `repository_userprofile`.`email`, `repository_userprofile`.`is_staff`, `repository_userprofile`.`is_active`, `repository_userprofile`.`date_joined`, `repository_userprofile`.`id`, `repository_userprofile`.`nick_name`, `repository_userprofile`.`create_time`, `repository_userprofile`.`image`, `repository_userprofile`.`models_introdoction`, `repository_userprofile`.`is_admin`, `repository_userprofile`.`is_approver` FROM `repository_userprofile` WHERE `repository_userprofile`.`id` = 1; args=(1,)
DEBUG 2019-02-19 11:30:42,147 [Thread-2:22256] [django.db.backends:111] [utils:execute] [DEBUG]- (0.001) SELECT `repository_dep`.`nid`, `repository_dep`.`title` FROM `repository_dep` LIMIT 21; args=()
DEBUG 2019-02-19 11:30:42,149 [Thread-2:22256] [django.db.backends:111] [utils:execute] [DEBUG]- (0.001) SELECT `repository_projectmodel`.`nid`, `repository_projectmodel`.`Project_name` FROM `repository_projectmodel` LIMIT 21; args=()
DEBUG 2019-02-19 11:30:42,153 [Thread-2:22256] [django.db.backends:111] [utils:execute] [DEBUG]- (0.001) SELECT `repository_dep`.`nid`, `repository_dep`.`title` FROM `repository_dep` LIMIT 21; args=()
DEBUG 2019-02-19 11:30:42,155 [Thread-2:22256] [django.db.backends:111] [utils:execute] [DEBUG]- (0.002) SELECT `repository_projectmodel`.`nid`, `repository_projectmodel`.`Project_name` FROM `repository_projectmodel` LIMIT 21; args=()
DEBUG 2019-02-19 11:30:42,247 [Thread-2:22256] [django.db.backends:111] [utils:execute] [DEBUG]- (0.001) SELECT `repository_dep`.`nid`, `repository_dep`.`title` FROM `repository_dep`; args=()
DEBUG 2019-02-19 11:30:42,248 [Thread-2:22256] [django.db.backends:111] [utils:execute] [DEBUG]- (0.001) SELECT `repository_projectmodel`.`nid`, `repository_projectmodel`.`Project_name` FROM `repository_projectmodel`; args=()
INFO 2019-02-19 11:30:42,253 [Thread-2:22256] [django.server:124] [basehttp:log_message] [INFO]- "GET /sharefile/addfile/ HTTP/1.1" 200 22974
DEBUG 2019-02-19 11:30:42,593 [Thread-3:14888] [django.template:878] [base:_resolve_lookup] [DEBUG]- Exception while resolving variable 'name' in template 'unknown'.
Traceback (most recent call last):
  File "C:\Python\Webproject\share2\env\lib\site-packages\django\core\handlers\exception.py", line 35, in inner
    response = get_response(request)
  File "C:\Python\Webproject\share2\env\lib\site-packages\django\core\handlers\base.py", line 113, in _get_response
    resolver_match = resolver.resolve(request.path_info)
  File "C:\Python\Webproject\share2\env\lib\site-packages\django\urls\resolvers.py", line 523, in resolve
    raise Resolver404({'tried': tried, 'path': new_path})
django.urls.exceptions.Resolver404: {'tried': [[<URLResolver <URLPattern list> (xadmin:xadmin) 'xadmin/'>], [<URLPattern '^$' [name='index']>], [<URLPattern 'index/' [name='index']>], [<URLPattern 'test/' [name='test']>], [<URLPattern 'login/' [name='login']>], [<URLPattern 'logout/' [name='logout']>], [<URLPattern 'register/' [name='register']>], [<URLPattern 'forget/' [name='forget_pwd']>], [<URLPattern 'reset/(?P<active_code>.*)/' [name='reset_pwd']>], [<URLPattern 'modify_pwd/' [name='modify_pwd']>], [<URLResolver <module 'captcha.urls' from 'C:\\Python\\Webproject\\share2\\env\\lib\\site-packages\\captcha\\urls.py'> (None:None) 'captcha/'>], [<URLPattern 'active/(?P<active_code>.*)/' [name='user_active']>], [<URLResolver <module 'sharefile.urls' from 'C:\\Python\\Webproject\\share2\\share2\\share2\\apps\\sharefile\\urls.py'> (sharefile:sharefile) 'sharefile/'>], [<URLResolver <module 'users.urls' from 'C:\\Python\\Webproject\\share2\\share2\\share2\\apps\\users\\urls.py'> (users:users) 'users/'>], [<URLPattern 'media/(?P<path>.*)$'>]], 'path': 'assets/images/custom-select.png'}

During handling of the above exception, another exception occurred:

Traceback (most recent call last):
  File "C:\Python\Webproject\share2\env\lib\site-packages\django\template\base.py", line 835, in _resolve_lookup
    current = current[bit]
TypeError: 'URLResolver' object is not subscriptable

During handling of the above exception, another exception occurred:

Traceback (most recent call last):
  File "C:\Python\Webproject\share2\env\lib\site-packages\django\template\base.py", line 843, in _resolve_lookup
    current = getattr(current, bit)
AttributeError: 'URLResolver' object has no attribute 'name'

During handling of the above exception, another exception occurred:

Traceback (most recent call last):
  File "C:\Python\Webproject\share2\env\lib\site-packages\django\template\base.py", line 849, in _resolve_lookup
    current = current[int(bit)]
ValueError: invalid literal for int() with base 10: 'name'

During handling of the above exception, another exception occurred:

Traceback (most recent call last):
  File "C:\Python\Webproject\share2\env\lib\site-packages\django\template\base.py", line 856, in _resolve_lookup
    (bit, current))  # missing attribute
django.template.base.VariableDoesNotExist: Failed lookup for key [name] in <URLResolver <URLPattern list> (xadmin:xadmin) 'xadmin/'>
DEBUG 2019-02-19 11:30:42,597 [Thread-3:14888] [django.template:878] [base:_resolve_lookup] [DEBUG]- Exception while resolving variable 'name' in template 'unknown'.
Traceback (most recent call last):
  File "C:\Python\Webproject\share2\env\lib\site-packages\django\core\handlers\exception.py", line 35, in inner
    response = get_response(request)
  File "C:\Python\Webproject\share2\env\lib\site-packages\django\core\handlers\base.py", line 113, in _get_response
    resolver_match = resolver.resolve(request.path_info)
  File "C:\Python\Webproject\share2\env\lib\site-packages\django\urls\resolvers.py", line 523, in resolve
    raise Resolver404({'tried': tried, 'path': new_path})
django.urls.exceptions.Resolver404: {'tried': [[<URLResolver <URLPattern list> (xadmin:xadmin) 'xadmin/'>], [<URLPattern '^$' [name='index']>], [<URLPattern 'index/' [name='index']>], [<URLPattern 'test/' [name='test']>], [<URLPattern 'login/' [name='login']>], [<URLPattern 'logout/' [name='logout']>], [<URLPattern 'register/' [name='register']>], [<URLPattern 'forget/' [name='forget_pwd']>], [<URLPattern 'reset/(?P<active_code>.*)/' [name='reset_pwd']>], [<URLPattern 'modify_pwd/' [name='modify_pwd']>], [<URLResolver <module 'captcha.urls' from 'C:\\Python\\Webproject\\share2\\env\\lib\\site-packages\\captcha\\urls.py'> (None:None) 'captcha/'>], [<URLPattern 'active/(?P<active_code>.*)/' [name='user_active']>], [<URLResolver <module 'sharefile.urls' from 'C:\\Python\\Webproject\\share2\\share2\\share2\\apps\\sharefile\\urls.py'> (sharefile:sharefile) 'sharefile/'>], [<URLResolver <module 'users.urls' from 'C:\\Python\\Webproject\\share2\\share2\\share2\\apps\\users\\urls.py'> (users:users) 'users/'>], [<URLPattern 'media/(?P<path>.*)$'>]], 'path': 'assets/images/custom-select.png'}

During handling of the above exception, another exception occurred:

Traceback (most recent call last):
  File "C:\Python\Webproject\share2\env\lib\site-packages\django\template\base.py", line 835, in _resolve_lookup
    current = current[bit]
TypeError: 'URLResolver' object is not subscriptable

During handling of the above exception, another exception occurred:

Traceback (most recent call last):
  File "C:\Python\Webproject\share2\env\lib\site-packages\django\template\base.py", line 843, in _resolve_lookup
    current = getattr(current, bit)
AttributeError: 'URLResolver' object has no attribute 'name'

During handling of the above exception, another exception occurred:

Traceback (most recent call last):
  File "C:\Python\Webproject\share2\env\lib\site-packages\django\template\base.py", line 849, in _resolve_lookup
    current = current[int(bit)]
ValueError: invalid literal for int() with base 10: 'name'

During handling of the above exception, another exception occurred:

Traceback (most recent call last):
  File "C:\Python\Webproject\share2\env\lib\site-packages\django\template\base.py", line 856, in _resolve_lookup
    (bit, current))  # missing attribute
django.template.base.VariableDoesNotExist: Failed lookup for key [name] in <URLResolver <module 'captcha.urls' from 'C:\\Python\\Webproject\\share2\\env\\lib\\site-packages\\captcha\\urls.py'> (None:None) 'captcha/'>
DEBUG 2019-02-19 11:30:42,606 [Thread-3:14888] [django.template:878] [base:_resolve_lookup] [DEBUG]- Exception while resolving variable 'name' in template 'unknown'.
Traceback (most recent call last):
  File "C:\Python\Webproject\share2\env\lib\site-packages\django\core\handlers\exception.py", line 35, in inner
    response = get_response(request)
  File "C:\Python\Webproject\share2\env\lib\site-packages\django\core\handlers\base.py", line 113, in _get_response
    resolver_match = resolver.resolve(request.path_info)
  File "C:\Python\Webproject\share2\env\lib\site-packages\django\urls\resolvers.py", line 523, in resolve
    raise Resolver404({'tried': tried, 'path': new_path})
django.urls.exceptions.Resolver404: {'tried': [[<URLResolver <URLPattern list> (xadmin:xadmin) 'xadmin/'>], [<URLPattern '^$' [name='index']>], [<URLPattern 'index/' [name='index']>], [<URLPattern 'test/' [name='test']>], [<URLPattern 'login/' [name='login']>], [<URLPattern 'logout/' [name='logout']>], [<URLPattern 'register/' [name='register']>], [<URLPattern 'forget/' [name='forget_pwd']>], [<URLPattern 'reset/(?P<active_code>.*)/' [name='reset_pwd']>], [<URLPattern 'modify_pwd/' [name='modify_pwd']>], [<URLResolver <module 'captcha.urls' from 'C:\\Python\\Webproject\\share2\\env\\lib\\site-packages\\captcha\\urls.py'> (None:None) 'captcha/'>], [<URLPattern 'active/(?P<active_code>.*)/' [name='user_active']>], [<URLResolver <module 'sharefile.urls' from 'C:\\Python\\Webproject\\share2\\share2\\share2\\apps\\sharefile\\urls.py'> (sharefile:sharefile) 'sharefile/'>], [<URLResolver <module 'users.urls' from 'C:\\Python\\Webproject\\share2\\share2\\share2\\apps\\users\\urls.py'> (users:users) 'users/'>], [<URLPattern 'media/(?P<path>.*)$'>]], 'path': 'assets/images/custom-select.png'}

During handling of the above exception, another exception occurred:

Traceback (most recent call last):
  File "C:\Python\Webproject\share2\env\lib\site-packages\django\template\base.py", line 835, in _resolve_lookup
    current = current[bit]
TypeError: 'URLResolver' object is not subscriptable

During handling of the above exception, another exception occurred:

Traceback (most recent call last):
  File "C:\Python\Webproject\share2\env\lib\site-packages\django\template\base.py", line 843, in _resolve_lookup
    current = getattr(current, bit)
AttributeError: 'URLResolver' object has no attribute 'name'

During handling of the above exception, another exception occurred:

Traceback (most recent call last):
  File "C:\Python\Webproject\share2\env\lib\site-packages\django\template\base.py", line 849, in _resolve_lookup
    current = current[int(bit)]
ValueError: invalid literal for int() with base 10: 'name'

During handling of the above exception, another exception occurred:

Traceback (most recent call last):
  File "C:\Python\Webproject\share2\env\lib\site-packages\django\template\base.py", line 856, in _resolve_lookup
    (bit, current))  # missing attribute
django.template.base.VariableDoesNotExist: Failed lookup for key [name] in <URLResolver <module 'sharefile.urls' from 'C:\\Python\\Webproject\\share2\\share2\\share2\\apps\\sharefile\\urls.py'> (sharefile:sharefile) 'sharefile/'>
DEBUG 2019-02-19 11:30:42,609 [Thread-3:14888] [django.template:878] [base:_resolve_lookup] [DEBUG]- Exception while resolving variable 'name' in template 'unknown'.
Traceback (most recent call last):
  File "C:\Python\Webproject\share2\env\lib\site-packages\django\core\handlers\exception.py", line 35, in inner
    response = get_response(request)
  File "C:\Python\Webproject\share2\env\lib\site-packages\django\core\handlers\base.py", line 113, in _get_response
    resolver_match = resolver.resolve(request.path_info)
  File "C:\Python\Webproject\share2\env\lib\site-packages\django\urls\resolvers.py", line 523, in resolve
    raise Resolver404({'tried': tried, 'path': new_path})
django.urls.exceptions.Resolver404: {'tried': [[<URLResolver <URLPattern list> (xadmin:xadmin) 'xadmin/'>], [<URLPattern '^$' [name='index']>], [<URLPattern 'index/' [name='index']>], [<URLPattern 'test/' [name='test']>], [<URLPattern 'login/' [name='login']>], [<URLPattern 'logout/' [name='logout']>], [<URLPattern 'register/' [name='register']>], [<URLPattern 'forget/' [name='forget_pwd']>], [<URLPattern 'reset/(?P<active_code>.*)/' [name='reset_pwd']>], [<URLPattern 'modify_pwd/' [name='modify_pwd']>], [<URLResolver <module 'captcha.urls' from 'C:\\Python\\Webproject\\share2\\env\\lib\\site-packages\\captcha\\urls.py'> (None:None) 'captcha/'>], [<URLPattern 'active/(?P<active_code>.*)/' [name='user_active']>], [<URLResolver <module 'sharefile.urls' from 'C:\\Python\\Webproject\\share2\\share2\\share2\\apps\\sharefile\\urls.py'> (sharefile:sharefile) 'sharefile/'>], [<URLResolver <module 'users.urls' from 'C:\\Python\\Webproject\\share2\\share2\\share2\\apps\\users\\urls.py'> (users:users) 'users/'>], [<URLPattern 'media/(?P<path>.*)$'>]], 'path': 'assets/images/custom-select.png'}

During handling of the above exception, another exception occurred:

Traceback (most recent call last):
  File "C:\Python\Webproject\share2\env\lib\site-packages\django\template\base.py", line 835, in _resolve_lookup
    current = current[bit]
TypeError: 'URLResolver' object is not subscriptable

During handling of the above exception, another exception occurred:

Traceback (most recent call last):
  File "C:\Python\Webproject\share2\env\lib\site-packages\django\template\base.py", line 843, in _resolve_lookup
    current = getattr(current, bit)
AttributeError: 'URLResolver' object has no attribute 'name'

During handling of the above exception, another exception occurred:

Traceback (most recent call last):
  File "C:\Python\Webproject\share2\env\lib\site-packages\django\template\base.py", line 849, in _resolve_lookup
    current = current[int(bit)]
ValueError: invalid literal for int() with base 10: 'name'

During handling of the above exception, another exception occurred:

Traceback (most recent call last):
  File "C:\Python\Webproject\share2\env\lib\site-packages\django\template\base.py", line 856, in _resolve_lookup
    (bit, current))  # missing attribute
django.template.base.VariableDoesNotExist: Failed lookup for key [name] in <URLResolver <module 'users.urls' from 'C:\\Python\\Webproject\\share2\\share2\\share2\\apps\\users\\urls.py'> (users:users) 'users/'>
WARNING 2019-02-19 11:30:42,621 [Thread-3:14888] [django.server:124] [basehttp:log_message] [WARNING]- "GET /assets/images/custom-select.png HTTP/1.1" 404 3763
INFO 2019-02-19 11:30:42,698 [Thread-4:11260] [django.server:124] [basehttp:log_message] [INFO]- "GET /static/images/favicon.png HTTP/1.1" 200 1347
DEBUG 2019-02-19 11:30:50,734 [Thread-5:21884] [django.db.backends:111] [utils:execute] [DEBUG]- (0.000) SELECT @@SQL_AUTO_IS_NULL; args=None
DEBUG 2019-02-19 11:30:50,736 [Thread-5:21884] [django.db.backends:111] [utils:execute] [DEBUG]- (0.001) SET SESSION TRANSACTION ISOLATION LEVEL READ COMMITTED; args=None
DEBUG 2019-02-19 11:30:50,737 [Thread-5:21884] [django.db.backends:111] [utils:execute] [DEBUG]- (0.001) SELECT VERSION(); args=None
DEBUG 2019-02-19 11:30:50,741 [Thread-5:21884] [django.db.backends:111] [utils:execute] [DEBUG]- (0.000) SET SESSION TRANSACTION ISOLATION LEVEL READ COMMITTED; args=None
DEBUG 2019-02-19 11:30:50,742 [Thread-5:21884] [django.db.backends:111] [utils:execute] [DEBUG]- (0.001) SELECT `django_session`.`session_key`, `django_session`.`session_data`, `django_session`.`expire_date` FROM `django_session` WHERE (`django_session`.`session_key` = '0u5rozh3lc5qezdhht6wcg9rg9gi21ko' AND `django_session`.`expire_date` > '2019-02-19 11:30:50.729334'); args=('0u5rozh3lc5qezdhht6wcg9rg9gi21ko', '2019-02-19 11:30:50.729334')
DEBUG 2019-02-19 11:30:50,745 [Thread-5:21884] [django.db.backends:111] [utils:execute] [DEBUG]- (0.002) SELECT `repository_userprofile`.`password`, `repository_userprofile`.`last_login`, `repository_userprofile`.`is_superuser`, `repository_userprofile`.`username`, `repository_userprofile`.`first_name`, `repository_userprofile`.`last_name`, `repository_userprofile`.`email`, `repository_userprofile`.`is_staff`, `repository_userprofile`.`is_active`, `repository_userprofile`.`date_joined`, `repository_userprofile`.`id`, `repository_userprofile`.`nick_name`, `repository_userprofile`.`create_time`, `repository_userprofile`.`image`, `repository_userprofile`.`models_introdoction`, `repository_userprofile`.`is_admin`, `repository_userprofile`.`is_approver` FROM `repository_userprofile` WHERE `repository_userprofile`.`id` = 1; args=(1,)
INFO 2019-02-19 11:30:50,746 [Thread-5:21884] [django:60] [AddfileView:post] [INFO]- user
DEBUG 2019-02-19 11:30:50,750 [Thread-5:21884] [django.db.backends:111] [utils:execute] [DEBUG]- (0.002) SELECT `repository_userprofile`.`password`, `repository_userprofile`.`last_login`, `repository_userprofile`.`is_superuser`, `repository_userprofile`.`username`, `repository_userprofile`.`first_name`, `repository_userprofile`.`last_name`, `repository_userprofile`.`email`, `repository_userprofile`.`is_staff`, `repository_userprofile`.`is_active`, `repository_userprofile`.`date_joined`, `repository_userprofile`.`id`, `repository_userprofile`.`nick_name`, `repository_userprofile`.`create_time`, `repository_userprofile`.`image`, `repository_userprofile`.`models_introdoction`, `repository_userprofile`.`is_admin`, `repository_userprofile`.`is_approver` FROM `repository_userprofile` WHERE `repository_userprofile`.`id` = 1 LIMIT 1; args=(1,)
DEBUG 2019-02-19 11:30:50,896 [Thread-5:21884] [django.db.backends:111] [utils:execute] [DEBUG]- (0.001) SELECT `repository_u2d`.`id`, `repository_u2d`.`user_id`, `repository_u2d`.`dep_id` FROM `repository_u2d` WHERE `repository_u2d`.`user_id` = 1 LIMIT 21; args=(1,)
DEBUG 2019-02-19 11:30:50,903 [Thread-5:21884] [django.db.backends:111] [utils:execute] [DEBUG]- (0.001) SELECT `repository_u2d`.`id`, `repository_u2d`.`user_id`, `repository_u2d`.`dep_id` FROM `repository_u2d` WHERE `repository_u2d`.`user_id` = 1 LIMIT 21; args=(1,)
DEBUG 2019-02-19 11:30:50,905 [Thread-5:21884] [django.db.backends:111] [utils:execute] [DEBUG]- (0.001) SELECT `repository_u2d`.`id`, `repository_u2d`.`user_id`, `repository_u2d`.`dep_id` FROM `repository_u2d` WHERE `repository_u2d`.`user_id` = 1 LIMIT 21; args=(1,)
DEBUG 2019-02-19 11:30:50,910 [Thread-5:21884] [django.db.backends:111] [utils:execute] [DEBUG]- (0.000) SELECT `repository_u2d`.`id`, `repository_u2d`.`user_id`, `repository_u2d`.`dep_id` FROM `repository_u2d` WHERE `repository_u2d`.`user_id` = 1 LIMIT 21; args=(1,)
INFO 2019-02-19 11:30:50,929 [Thread-5:21884] [django:78] [AddfileView:post] [INFO]- 添加文件
INFO 2019-02-19 11:30:50,930 [Thread-5:21884] [django:79] [AddfileView:post] [INFO]- ********************
INFO 2019-02-19 11:30:50,932 [Thread-5:21884] [django:80] [AddfileView:post] [INFO]- <QueryDict: {'filename': ['123'], 'dep': ['信息部'], 'filedes': ['123'], 'filetype': ['内部'], 'fileproject': ['测试项目1'], 'csrfmiddlewaretoken': ['hEdxT4LzxuUMOiyuD0Sd0VwkSP0sQCSC4WOhLM7x6CYpehiFctPh3m02nFjfoun9']}>
DEBUG 2019-02-19 11:30:50,944 [Thread-5:21884] [django.db.backends:111] [utils:execute] [DEBUG]- (0.001) SELECT `repository_dep`.`nid`, `repository_dep`.`title` FROM `repository_dep` WHERE `repository_dep`.`title` = '信息部' LIMIT 21; args=('信息部',)
DEBUG 2019-02-19 11:30:50,946 [Thread-5:21884] [django.db.backends:111] [utils:execute] [DEBUG]- (0.001) SELECT `repository_dep`.`nid`, `repository_dep`.`title` FROM `repository_dep` WHERE `repository_dep`.`title` = '信息部' LIMIT 21; args=('信息部',)
INFO 2019-02-19 11:30:50,943 [Thread-5:21884] [django:102] [AddfileView:post] [INFO]- <QuerySet [<Dep: 信息部>]>
DEBUG 2019-02-19 11:30:50,948 [Thread-5:21884] [django.db.backends:111] [utils:execute] [DEBUG]- (0.001) SELECT `repository_dep`.`nid`, `repository_dep`.`title` FROM `repository_dep` WHERE `repository_dep`.`title` = '信息部' LIMIT 21; args=('信息部',)
DEBUG 2019-02-19 11:30:50,950 [Thread-5:21884] [django.db.backends:111] [utils:execute] [DEBUG]- (0.001) SELECT `repository_dep`.`nid`, `repository_dep`.`title` FROM `repository_dep` WHERE `repository_dep`.`title` = '信息部' LIMIT 1; args=('信息部',)
DEBUG 2019-02-19 11:30:50,978 [Thread-5:21884] [django.db.backends:111] [utils:execute] [DEBUG]- (0.001) SELECT `repository_projectmodel`.`nid`, `repository_projectmodel`.`Project_name` FROM `repository_projectmodel` WHERE `repository_projectmodel`.`Project_name` = '测试项目1'; args=('测试项目1',)
INFO 2019-02-19 11:30:50,999 [Thread-5:21884] [django:127] [AddfileView:post] [INFO]- 1
DEBUG 2019-02-19 11:30:51,009 [Thread-5:21884] [django.db.backends:111] [utils:execute] [DEBUG]- (0.001) INSERT INTO `repository_addfilemodel` (`models_Filename`, `models_Filedes`, `read_count`, `models_Fileupload`, `create_time`, `department_id`, `user_id_id`, `models_Filetype_type_id`, `status`, `models_Fileproject_id`, `reason`) VALUES ('123', '123', 0, 'file/2019/02/Login_r9TN4PI.png', '2019-02-19 11:30:51.007570', NULL, 1, 2, '0', 1, '无'); args=['123', '123', 0, 'file/2019/02/Login_r9TN4PI.png', '2019-02-19 11:30:51.007570', None, 1, 2, '0', 1, '无']
DEBUG 2019-02-19 11:30:51,098 [Thread-5:21884] [django.db.backends:111] [utils:execute] [DEBUG]- (0.001) INSERT INTO `repository_file2depmodel` (`file_id`, `dep_id`) VALUES (81, 2); args=[81, 2]
INFO 2019-02-19 11:30:51,132 [Thread-5:21884] [django.server:124] [basehttp:log_message] [INFO]- "POST /sharefile/addfile/ HTTP/1.1" 302 0
DEBUG 2019-02-19 11:30:51,237 [Thread-6:13196] [django.db.backends:111] [utils:execute] [DEBUG]- (0.001) SELECT @@SQL_AUTO_IS_NULL; args=None
DEBUG 2019-02-19 11:30:51,238 [Thread-6:13196] [django.db.backends:111] [utils:execute] [DEBUG]- (0.001) SET SESSION TRANSACTION ISOLATION LEVEL READ COMMITTED; args=None
DEBUG 2019-02-19 11:30:51,240 [Thread-6:13196] [django.db.backends:111] [utils:execute] [DEBUG]- (0.002) SELECT VERSION(); args=None
DEBUG 2019-02-19 11:30:51,244 [Thread-6:13196] [django.db.backends:111] [utils:execute] [DEBUG]- (0.001) SET SESSION TRANSACTION ISOLATION LEVEL READ COMMITTED; args=None
DEBUG 2019-02-19 11:30:51,246 [Thread-6:13196] [django.db.backends:111] [utils:execute] [DEBUG]- (0.001) SELECT `django_session`.`session_key`, `django_session`.`session_data`, `django_session`.`expire_date` FROM `django_session` WHERE (`django_session`.`session_key` = '0u5rozh3lc5qezdhht6wcg9rg9gi21ko' AND `django_session`.`expire_date` > '2019-02-19 11:30:51.232168'); args=('0u5rozh3lc5qezdhht6wcg9rg9gi21ko', '2019-02-19 11:30:51.232168')
DEBUG 2019-02-19 11:30:51,249 [Thread-6:13196] [django.db.backends:111] [utils:execute] [DEBUG]- (0.001) SELECT `repository_userprofile`.`password`, `repository_userprofile`.`last_login`, `repository_userprofile`.`is_superuser`, `repository_userprofile`.`username`, `repository_userprofile`.`first_name`, `repository_userprofile`.`last_name`, `repository_userprofile`.`email`, `repository_userprofile`.`is_staff`, `repository_userprofile`.`is_active`, `repository_userprofile`.`date_joined`, `repository_userprofile`.`id`, `repository_userprofile`.`nick_name`, `repository_userprofile`.`create_time`, `repository_userprofile`.`image`, `repository_userprofile`.`models_introdoction`, `repository_userprofile`.`is_admin`, `repository_userprofile`.`is_approver` FROM `repository_userprofile` WHERE `repository_userprofile`.`id` = 1; args=(1,)
DEBUG 2019-02-19 11:30:51,255 [Thread-6:13196] [django.db.backends:111] [utils:execute] [DEBUG]- (0.002) SELECT `repository_u2d`.`id`, `repository_u2d`.`user_id`, `repository_u2d`.`dep_id` FROM `repository_u2d` WHERE `repository_u2d`.`user_id` = 1 LIMIT 1; args=(1,)
DEBUG 2019-02-19 11:30:51,258 [Thread-6:13196] [django.db.backends:111] [utils:execute] [DEBUG]- (0.002) SELECT `repository_file2depmodel`.`id`, `repository_file2depmodel`.`file_id`, `repository_file2depmodel`.`dep_id` FROM `repository_file2depmodel` WHERE `repository_file2depmodel`.`dep_id` = 1 LIMIT 21; args=(1,)
DEBUG 2019-02-19 11:30:51,260 [Thread-6:13196] [django.db.backends:111] [utils:execute] [DEBUG]- (0.001) SELECT `repository_file2depmodel`.`id`, `repository_file2depmodel`.`file_id`, `repository_file2depmodel`.`dep_id` FROM `repository_file2depmodel` WHERE `repository_file2depmodel`.`dep_id` = 1; args=(1,)
DEBUG 2019-02-19 11:30:51,274 [Thread-6:13196] [django.db.backends:111] [utils:execute] [DEBUG]- (0.001) SELECT `repository_projectmodel`.`nid`, `repository_projectmodel`.`Project_name` FROM `repository_projectmodel`; args=()
DEBUG 2019-02-19 11:30:51,288 [Thread-6:13196] [django.db.backends:111] [utils:execute] [DEBUG]- (0.004) SELECT `repository_addfilemodel`.`nid`, `repository_addfilemodel`.`models_Filename`, `repository_addfilemodel`.`models_Filedes`, `repository_addfilemodel`.`read_count`, `repository_addfilemodel`.`models_Fileupload`, `repository_addfilemodel`.`create_time`, `repository_addfilemodel`.`department_id`, `repository_addfilemodel`.`user_id_id`, `repository_addfilemodel`.`models_Filetype_type_id`, `repository_addfilemodel`.`status`, `repository_addfilemodel`.`models_Fileproject_id`, `repository_addfilemodel`.`reason` FROM `repository_addfilemodel` WHERE `repository_addfilemodel`.`nid` = 10; args=(10,)
DEBUG 2019-02-19 11:30:51,289 [Thread-6:13196] [django.template:878] [base:_resolve_lookup] [DEBUG]- Exception while resolving variable 'models_Filedes' in template 'Ace-filelist-transaction-listing.html'.
Traceback (most recent call last):
  File "C:\Python\Webproject\share2\env\lib\site-packages\django\template\base.py", line 835, in _resolve_lookup
    current = current[bit]
TypeError: 'File2DepModel' object is not subscriptable

During handling of the above exception, another exception occurred:

Traceback (most recent call last):
  File "C:\Python\Webproject\share2\env\lib\site-packages\django\template\base.py", line 843, in _resolve_lookup
    current = getattr(current, bit)
AttributeError: 'File2DepModel' object has no attribute 'models_Filedes'

During handling of the above exception, another exception occurred:

Traceback (most recent call last):
  File "C:\Python\Webproject\share2\env\lib\site-packages\django\template\base.py", line 849, in _resolve_lookup
    current = current[int(bit)]
ValueError: invalid literal for int() with base 10: 'models_Filedes'

During handling of the above exception, another exception occurred:

Traceback (most recent call last):
  File "C:\Python\Webproject\share2\env\lib\site-packages\django\template\base.py", line 856, in _resolve_lookup
    (bit, current))  # missing attribute
django.template.base.VariableDoesNotExist: Failed lookup for key [models_Filedes] in <File2DepModel: File2DepModel object (1)>
DEBUG 2019-02-19 11:30:51,292 [Thread-6:13196] [django.db.backends:111] [utils:execute] [DEBUG]- (0.002) SELECT `repository_userprofile`.`password`, `repository_userprofile`.`last_login`, `repository_userprofile`.`is_superuser`, `repository_userprofile`.`username`, `repository_userprofile`.`first_name`, `repository_userprofile`.`last_name`, `repository_userprofile`.`email`, `repository_userprofile`.`is_staff`, `repository_userprofile`.`is_active`, `repository_userprofile`.`date_joined`, `repository_userprofile`.`id`, `repository_userprofile`.`nick_name`, `repository_userprofile`.`create_time`, `repository_userprofile`.`image`, `repository_userprofile`.`models_introdoction`, `repository_userprofile`.`is_admin`, `repository_userprofile`.`is_approver` FROM `repository_userprofile` WHERE `repository_userprofile`.`id` = 6; args=(6,)
DEBUG 2019-02-19 11:30:51,294 [Thread-6:13196] [django.db.backends:111] [utils:execute] [DEBUG]- (0.001) SELECT `repository_projectmodel`.`nid`, `repository_projectmodel`.`Project_name` FROM `repository_projectmodel` WHERE `repository_projectmodel`.`nid` = 1; args=(1,)
DEBUG 2019-02-19 11:30:51,297 [Thread-6:13196] [django.db.backends:111] [utils:execute] [DEBUG]- (0.001) SELECT `repository_addfilemodel`.`nid`, `repository_addfilemodel`.`models_Filename`, `repository_addfilemodel`.`models_Filedes`, `repository_addfilemodel`.`read_count`, `repository_addfilemodel`.`models_Fileupload`, `repository_addfilemodel`.`create_time`, `repository_addfilemodel`.`department_id`, `repository_addfilemodel`.`user_id_id`, `repository_addfilemodel`.`models_Filetype_type_id`, `repository_addfilemodel`.`status`, `repository_addfilemodel`.`models_Fileproject_id`, `repository_addfilemodel`.`reason` FROM `repository_addfilemodel` WHERE `repository_addfilemodel`.`nid` = 11; args=(11,)
DEBUG 2019-02-19 11:30:51,298 [Thread-6:13196] [django.template:878] [base:_resolve_lookup] [DEBUG]- Exception while resolving variable 'models_Filedes' in template 'Ace-filelist-transaction-listing.html'.
Traceback (most recent call last):
  File "C:\Python\Webproject\share2\env\lib\site-packages\django\template\base.py", line 835, in _resolve_lookup
    current = current[bit]
TypeError: 'File2DepModel' object is not subscriptable

During handling of the above exception, another exception occurred:

Traceback (most recent call last):
  File "C:\Python\Webproject\share2\env\lib\site-packages\django\template\base.py", line 843, in _resolve_lookup
    current = getattr(current, bit)
AttributeError: 'File2DepModel' object has no attribute 'models_Filedes'

During handling of the above exception, another exception occurred:

Traceback (most recent call last):
  File "C:\Python\Webproject\share2\env\lib\site-packages\django\template\base.py", line 849, in _resolve_lookup
    current = current[int(bit)]
ValueError: invalid literal for int() with base 10: 'models_Filedes'

During handling of the above exception, another exception occurred:

Traceback (most recent call last):
  File "C:\Python\Webproject\share2\env\lib\site-packages\django\template\base.py", line 856, in _resolve_lookup
    (bit, current))  # missing attribute
django.template.base.VariableDoesNotExist: Failed lookup for key [models_Filedes] in <File2DepModel: File2DepModel object (4)>
DEBUG 2019-02-19 11:30:51,304 [Thread-6:13196] [django.db.backends:111] [utils:execute] [DEBUG]- (0.004) SELECT `repository_userprofile`.`password`, `repository_userprofile`.`last_login`, `repository_userprofile`.`is_superuser`, `repository_userprofile`.`username`, `repository_userprofile`.`first_name`, `repository_userprofile`.`last_name`, `repository_userprofile`.`email`, `repository_userprofile`.`is_staff`, `repository_userprofile`.`is_active`, `repository_userprofile`.`date_joined`, `repository_userprofile`.`id`, `repository_userprofile`.`nick_name`, `repository_userprofile`.`create_time`, `repository_userprofile`.`image`, `repository_userprofile`.`models_introdoction`, `repository_userprofile`.`is_admin`, `repository_userprofile`.`is_approver` FROM `repository_userprofile` WHERE `repository_userprofile`.`id` = 6; args=(6,)
DEBUG 2019-02-19 11:30:51,307 [Thread-6:13196] [django.db.backends:111] [utils:execute] [DEBUG]- (0.001) SELECT `repository_projectmodel`.`nid`, `repository_projectmodel`.`Project_name` FROM `repository_projectmodel` WHERE `repository_projectmodel`.`nid` = 1; args=(1,)
DEBUG 2019-02-19 11:30:51,310 [Thread-6:13196] [django.db.backends:111] [utils:execute] [DEBUG]- (0.002) SELECT `repository_addfilemodel`.`nid`, `repository_addfilemodel`.`models_Filename`, `repository_addfilemodel`.`models_Filedes`, `repository_addfilemodel`.`read_count`, `repository_addfilemodel`.`models_Fileupload`, `repository_addfilemodel`.`create_time`, `repository_addfilemodel`.`department_id`, `repository_addfilemodel`.`user_id_id`, `repository_addfilemodel`.`models_Filetype_type_id`, `repository_addfilemodel`.`status`, `repository_addfilemodel`.`models_Fileproject_id`, `repository_addfilemodel`.`reason` FROM `repository_addfilemodel` WHERE `repository_addfilemodel`.`nid` = 22; args=(22,)
DEBUG 2019-02-19 11:30:51,311 [Thread-6:13196] [django.template:878] [base:_resolve_lookup] [DEBUG]- Exception while resolving variable 'models_Filedes' in template 'Ace-filelist-transaction-listing.html'.
Traceback (most recent call last):
  File "C:\Python\Webproject\share2\env\lib\site-packages\django\template\base.py", line 835, in _resolve_lookup
    current = current[bit]
TypeError: 'File2DepModel' object is not subscriptable

During handling of the above exception, another exception occurred:

Traceback (most recent call last):
  File "C:\Python\Webproject\share2\env\lib\site-packages\django\template\base.py", line 843, in _resolve_lookup
    current = getattr(current, bit)
AttributeError: 'File2DepModel' object has no attribute 'models_Filedes'

During handling of the above exception, another exception occurred:

Traceback (most recent call last):
  File "C:\Python\Webproject\share2\env\lib\site-packages\django\template\base.py", line 849, in _resolve_lookup
    current = current[int(bit)]
ValueError: invalid literal for int() with base 10: 'models_Filedes'

During handling of the above exception, another exception occurred:

Traceback (most recent call last):
  File "C:\Python\Webproject\share2\env\lib\site-packages\django\template\base.py", line 856, in _resolve_lookup
    (bit, current))  # missing attribute
django.template.base.VariableDoesNotExist: Failed lookup for key [models_Filedes] in <File2DepModel: File2DepModel object (17)>
DEBUG 2019-02-19 11:30:51,315 [Thread-6:13196] [django.db.backends:111] [utils:execute] [DEBUG]- (0.001) SELECT `repository_userprofile`.`password`, `repository_userprofile`.`last_login`, `repository_userprofile`.`is_superuser`, `repository_userprofile`.`username`, `repository_userprofile`.`first_name`, `repository_userprofile`.`last_name`, `repository_userprofile`.`email`, `repository_userprofile`.`is_staff`, `repository_userprofile`.`is_active`, `repository_userprofile`.`date_joined`, `repository_userprofile`.`id`, `repository_userprofile`.`nick_name`, `repository_userprofile`.`create_time`, `repository_userprofile`.`image`, `repository_userprofile`.`models_introdoction`, `repository_userprofile`.`is_admin`, `repository_userprofile`.`is_approver` FROM `repository_userprofile` WHERE `repository_userprofile`.`id` = 1; args=(1,)
DEBUG 2019-02-19 11:30:51,317 [Thread-6:13196] [django.db.backends:111] [utils:execute] [DEBUG]- (0.001) SELECT `repository_projectmodel`.`nid`, `repository_projectmodel`.`Project_name` FROM `repository_projectmodel` WHERE `repository_projectmodel`.`nid` = 1; args=(1,)
DEBUG 2019-02-19 11:30:51,322 [Thread-6:13196] [django.db.backends:111] [utils:execute] [DEBUG]- (0.001) SELECT `repository_addfilemodel`.`nid`, `repository_addfilemodel`.`models_Filename`, `repository_addfilemodel`.`models_Filedes`, `repository_addfilemodel`.`read_count`, `repository_addfilemodel`.`models_Fileupload`, `repository_addfilemodel`.`create_time`, `repository_addfilemodel`.`department_id`, `repository_addfilemodel`.`user_id_id`, `repository_addfilemodel`.`models_Filetype_type_id`, `repository_addfilemodel`.`status`, `repository_addfilemodel`.`models_Fileproject_id`, `repository_addfilemodel`.`reason` FROM `repository_addfilemodel` WHERE `repository_addfilemodel`.`nid` = 23; args=(23,)
DEBUG 2019-02-19 11:30:51,322 [Thread-6:13196] [django.template:878] [base:_resolve_lookup] [DEBUG]- Exception while resolving variable 'models_Filedes' in template 'Ace-filelist-transaction-listing.html'.
Traceback (most recent call last):
  File "C:\Python\Webproject\share2\env\lib\site-packages\django\template\base.py", line 835, in _resolve_lookup
    current = current[bit]
TypeError: 'File2DepModel' object is not subscriptable

During handling of the above exception, another exception occurred:

Traceback (most recent call last):
  File "C:\Python\Webproject\share2\env\lib\site-packages\django\template\base.py", line 843, in _resolve_lookup
    current = getattr(current, bit)
AttributeError: 'File2DepModel' object has no attribute 'models_Filedes'

During handling of the above exception, another exception occurred:

Traceback (most recent call last):
  File "C:\Python\Webproject\share2\env\lib\site-packages\django\template\base.py", line 849, in _resolve_lookup
    current = current[int(bit)]
ValueError: invalid literal for int() with base 10: 'models_Filedes'

During handling of the above exception, another exception occurred:

Traceback (most recent call last):
  File "C:\Python\Webproject\share2\env\lib\site-packages\django\template\base.py", line 856, in _resolve_lookup
    (bit, current))  # missing attribute
django.template.base.VariableDoesNotExist: Failed lookup for key [models_Filedes] in <File2DepModel: File2DepModel object (18)>
DEBUG 2019-02-19 11:30:51,326 [Thread-6:13196] [django.db.backends:111] [utils:execute] [DEBUG]- (0.002) SELECT `repository_userprofile`.`password`, `repository_userprofile`.`last_login`, `repository_userprofile`.`is_superuser`, `repository_userprofile`.`username`, `repository_userprofile`.`first_name`, `repository_userprofile`.`last_name`, `repository_userprofile`.`email`, `repository_userprofile`.`is_staff`, `repository_userprofile`.`is_active`, `repository_userprofile`.`date_joined`, `repository_userprofile`.`id`, `repository_userprofile`.`nick_name`, `repository_userprofile`.`create_time`, `repository_userprofile`.`image`, `repository_userprofile`.`models_introdoction`, `repository_userprofile`.`is_admin`, `repository_userprofile`.`is_approver` FROM `repository_userprofile` WHERE `repository_userprofile`.`id` = 1; args=(1,)
DEBUG 2019-02-19 11:30:51,328 [Thread-6:13196] [django.db.backends:111] [utils:execute] [DEBUG]- (0.001) SELECT `repository_projectmodel`.`nid`, `repository_projectmodel`.`Project_name` FROM `repository_projectmodel` WHERE `repository_projectmodel`.`nid` = 1; args=(1,)
DEBUG 2019-02-19 11:30:51,331 [Thread-6:13196] [django.db.backends:111] [utils:execute] [DEBUG]- (0.002) SELECT `repository_addfilemodel`.`nid`, `repository_addfilemodel`.`models_Filename`, `repository_addfilemodel`.`models_Filedes`, `repository_addfilemodel`.`read_count`, `repository_addfilemodel`.`models_Fileupload`, `repository_addfilemodel`.`create_time`, `repository_addfilemodel`.`department_id`, `repository_addfilemodel`.`user_id_id`, `repository_addfilemodel`.`models_Filetype_type_id`, `repository_addfilemodel`.`status`, `repository_addfilemodel`.`models_Fileproject_id`, `repository_addfilemodel`.`reason` FROM `repository_addfilemodel` WHERE `repository_addfilemodel`.`nid` = 48; args=(48,)
DEBUG 2019-02-19 11:30:51,331 [Thread-6:13196] [django.template:878] [base:_resolve_lookup] [DEBUG]- Exception while resolving variable 'models_Filedes' in template 'Ace-filelist-transaction-listing.html'.
Traceback (most recent call last):
  File "C:\Python\Webproject\share2\env\lib\site-packages\django\template\base.py", line 835, in _resolve_lookup
    current = current[bit]
TypeError: 'File2DepModel' object is not subscriptable

During handling of the above exception, another exception occurred:

Traceback (most recent call last):
  File "C:\Python\Webproject\share2\env\lib\site-packages\django\template\base.py", line 843, in _resolve_lookup
    current = getattr(current, bit)
AttributeError: 'File2DepModel' object has no attribute 'models_Filedes'

During handling of the above exception, another exception occurred:

Traceback (most recent call last):
  File "C:\Python\Webproject\share2\env\lib\site-packages\django\template\base.py", line 849, in _resolve_lookup
    current = current[int(bit)]
ValueError: invalid literal for int() with base 10: 'models_Filedes'

During handling of the above exception, another exception occurred:

Traceback (most recent call last):
  File "C:\Python\Webproject\share2\env\lib\site-packages\django\template\base.py", line 856, in _resolve_lookup
    (bit, current))  # missing attribute
django.template.base.VariableDoesNotExist: Failed lookup for key [models_Filedes] in <File2DepModel: File2DepModel object (19)>
DEBUG 2019-02-19 11:30:51,337 [Thread-6:13196] [django.db.backends:111] [utils:execute] [DEBUG]- (0.004) SELECT `repository_userprofile`.`password`, `repository_userprofile`.`last_login`, `repository_userprofile`.`is_superuser`, `repository_userprofile`.`username`, `repository_userprofile`.`first_name`, `repository_userprofile`.`last_name`, `repository_userprofile`.`email`, `repository_userprofile`.`is_staff`, `repository_userprofile`.`is_active`, `repository_userprofile`.`date_joined`, `repository_userprofile`.`id`, `repository_userprofile`.`nick_name`, `repository_userprofile`.`create_time`, `repository_userprofile`.`image`, `repository_userprofile`.`models_introdoction`, `repository_userprofile`.`is_admin`, `repository_userprofile`.`is_approver` FROM `repository_userprofile` WHERE `repository_userprofile`.`id` = 1; args=(1,)
DEBUG 2019-02-19 11:30:51,340 [Thread-6:13196] [django.db.backends:111] [utils:execute] [DEBUG]- (0.001) SELECT `repository_projectmodel`.`nid`, `repository_projectmodel`.`Project_name` FROM `repository_projectmodel` WHERE `repository_projectmodel`.`nid` = 1; args=(1,)
DEBUG 2019-02-19 11:30:51,342 [Thread-6:13196] [django.db.backends:111] [utils:execute] [DEBUG]- (0.001) SELECT `repository_addfilemodel`.`nid`, `repository_addfilemodel`.`models_Filename`, `repository_addfilemodel`.`models_Filedes`, `repository_addfilemodel`.`read_count`, `repository_addfilemodel`.`models_Fileupload`, `repository_addfilemodel`.`create_time`, `repository_addfilemodel`.`department_id`, `repository_addfilemodel`.`user_id_id`, `repository_addfilemodel`.`models_Filetype_type_id`, `repository_addfilemodel`.`status`, `repository_addfilemodel`.`models_Fileproject_id`, `repository_addfilemodel`.`reason` FROM `repository_addfilemodel` WHERE `repository_addfilemodel`.`nid` = 48; args=(48,)
DEBUG 2019-02-19 11:30:51,343 [Thread-6:13196] [django.template:878] [base:_resolve_lookup] [DEBUG]- Exception while resolving variable 'models_Filedes' in template 'Ace-filelist-transaction-listing.html'.
Traceback (most recent call last):
  File "C:\Python\Webproject\share2\env\lib\site-packages\django\template\base.py", line 835, in _resolve_lookup
    current = current[bit]
TypeError: 'File2DepModel' object is not subscriptable

During handling of the above exception, another exception occurred:

Traceback (most recent call last):
  File "C:\Python\Webproject\share2\env\lib\site-packages\django\template\base.py", line 843, in _resolve_lookup
    current = getattr(current, bit)
AttributeError: 'File2DepModel' object has no attribute 'models_Filedes'

During handling of the above exception, another exception occurred:

Traceback (most recent call last):
  File "C:\Python\Webproject\share2\env\lib\site-packages\django\template\base.py", line 849, in _resolve_lookup
    current = current[int(bit)]
ValueError: invalid literal for int() with base 10: 'models_Filedes'

During handling of the above exception, another exception occurred:

Traceback (most recent call last):
  File "C:\Python\Webproject\share2\env\lib\site-packages\django\template\base.py", line 856, in _resolve_lookup
    (bit, current))  # missing attribute
django.template.base.VariableDoesNotExist: Failed lookup for key [models_Filedes] in <File2DepModel: File2DepModel object (20)>
DEBUG 2019-02-19 11:30:51,346 [Thread-6:13196] [django.db.backends:111] [utils:execute] [DEBUG]- (0.001) SELECT `repository_userprofile`.`password`, `repository_userprofile`.`last_login`, `repository_userprofile`.`is_superuser`, `repository_userprofile`.`username`, `repository_userprofile`.`first_name`, `repository_userprofile`.`last_name`, `repository_userprofile`.`email`, `repository_userprofile`.`is_staff`, `repository_userprofile`.`is_active`, `repository_userprofile`.`date_joined`, `repository_userprofile`.`id`, `repository_userprofile`.`nick_name`, `repository_userprofile`.`create_time`, `repository_userprofile`.`image`, `repository_userprofile`.`models_introdoction`, `repository_userprofile`.`is_admin`, `repository_userprofile`.`is_approver` FROM `repository_userprofile` WHERE `repository_userprofile`.`id` = 1; args=(1,)
DEBUG 2019-02-19 11:30:51,348 [Thread-6:13196] [django.db.backends:111] [utils:execute] [DEBUG]- (0.001) SELECT `repository_projectmodel`.`nid`, `repository_projectmodel`.`Project_name` FROM `repository_projectmodel` WHERE `repository_projectmodel`.`nid` = 1; args=(1,)
INFO 2019-02-19 11:30:51,354 [Thread-6:13196] [django.server:124] [basehttp:log_message] [INFO]- "GET /sharefile/filelist/ HTTP/1.1" 200 41972
