WARNING 2019-02-19 11:11:24,736 [Thread-8:18884] [django.request:93] [base:get_response] [WARNING]- Not Found: /assets/images/custom-select.png
ERROR 2019-02-19 11:12:02,277 [Thread-13:20224] [django.request:118] [exception:handle_uncaught_exception] [ERROR]- Internal Server Error: /sharefile/addfile/
Traceback (most recent call last):
  File "C:\Python\Webproject\share2\env\lib\site-packages\django\core\handlers\exception.py", line 35, in inner
    response = get_response(request)
  File "C:\Python\Webproject\share2\env\lib\site-packages\django\core\handlers\base.py", line 128, in _get_response
    response = self.process_exception_by_middleware(e, request)
  File "C:\Python\Webproject\share2\env\lib\site-packages\django\core\handlers\base.py", line 126, in _get_response
    response = wrapped_callback(request, *callback_args, **callback_kwargs)
  File "C:\Python\Webproject\share2\env\lib\site-packages\django\views\generic\base.py", line 69, in view
    return self.dispatch(request, *args, **kwargs)
  File "C:\Python\Webproject\share2\env\lib\site-packages\django\utils\decorators.py", line 62, in _wrapper
    return bound_func(*args, **kwargs)
  File "C:\Python\Webproject\share2\env\lib\site-packages\django\contrib\auth\decorators.py", line 21, in _wrapped_view
    return view_func(request, *args, **kwargs)
  File "C:\Python\Webproject\share2\env\lib\site-packages\django\utils\decorators.py", line 58, in bound_func
    return func.__get__(self, type(self))(*args2, **kwargs2)
  File "C:\Python\Webproject\share2\share2\share2\apps\utils\mixin_utils.py", line 14, in dispatch
    return super(LoginRequiredMixin, self).dispatch(request, *args, **kwargs)
  File "C:\Python\Webproject\share2\env\lib\site-packages\django\views\generic\base.py", line 89, in dispatch
    return handler(request, *args, **kwargs)
  File "C:\Python\Webproject\share2\share2\share2\apps\sharefile\views\AddfileView.py", line 142, in post
    file_dep.dep = dep_obj
  File "C:\Python\Webproject\share2\env\lib\site-packages\django\db\models\fields\related_descriptors.py", line 197, in __set__
    self.field.remote_field.model._meta.object_name,
ValueError: Cannot assign "<U2D: U2D object (1)>": "File2DepModel.dep" must be a "Dep" instance.
WARNING 2019-02-19 11:12:03,973 [Thread-45:5840] [django.request:93] [base:get_response] [WARNING]- Not Found: /favicon.ico
WARNING 2019-02-19 11:12:35,012 [Thread-8:20840] [django.request:93] [base:get_response] [WARNING]- Not Found: /assets/images/custom-select.png
WARNING 2019-02-19 11:16:42,924 [Thread-4:21452] [django.request:93] [base:get_response] [WARNING]- Not Found: /assets/images/custom-select.png
ERROR 2019-02-19 11:16:58,570 [Thread-8:21284] [django.request:118] [exception:handle_uncaught_exception] [ERROR]- Internal Server Error: /sharefile/addfile/
Traceback (most recent call last):
  File "C:\Python\Webproject\share2\env\lib\site-packages\django\core\handlers\exception.py", line 35, in inner
    response = get_response(request)
  File "C:\Python\Webproject\share2\env\lib\site-packages\django\core\handlers\base.py", line 128, in _get_response
    response = self.process_exception_by_middleware(e, request)
  File "C:\Python\Webproject\share2\env\lib\site-packages\django\core\handlers\base.py", line 126, in _get_response
    response = wrapped_callback(request, *callback_args, **callback_kwargs)
  File "C:\Python\Webproject\share2\env\lib\site-packages\django\views\generic\base.py", line 69, in view
    return self.dispatch(request, *args, **kwargs)
  File "C:\Python\Webproject\share2\env\lib\site-packages\django\utils\decorators.py", line 62, in _wrapper
    return bound_func(*args, **kwargs)
  File "C:\Python\Webproject\share2\env\lib\site-packages\django\contrib\auth\decorators.py", line 21, in _wrapped_view
    return view_func(request, *args, **kwargs)
  File "C:\Python\Webproject\share2\env\lib\site-packages\django\utils\decorators.py", line 58, in bound_func
    return func.__get__(self, type(self))(*args2, **kwargs2)
  File "C:\Python\Webproject\share2\share2\share2\apps\utils\mixin_utils.py", line 14, in dispatch
    return super(LoginRequiredMixin, self).dispatch(request, *args, **kwargs)
  File "C:\Python\Webproject\share2\env\lib\site-packages\django\views\generic\base.py", line 89, in dispatch
    return handler(request, *args, **kwargs)
  File "C:\Python\Webproject\share2\share2\share2\apps\sharefile\views\AddfileView.py", line 142, in post
    file_dep.dep = dep_obj
  File "C:\Python\Webproject\share2\env\lib\site-packages\django\db\models\fields\related_descriptors.py", line 197, in __set__
    self.field.remote_field.model._meta.object_name,
ValueError: Cannot assign "1": "File2DepModel.dep" must be a "Dep" instance.
ERROR 2019-02-19 11:19:38,107 [Thread-2:10224] [django.request:118] [exception:handle_uncaught_exception] [ERROR]- Internal Server Error: /sharefile/addfile/
Traceback (most recent call last):
  File "C:\Python\Webproject\share2\env\lib\site-packages\django\core\handlers\exception.py", line 35, in inner
    response = get_response(request)
  File "C:\Python\Webproject\share2\env\lib\site-packages\django\core\handlers\base.py", line 128, in _get_response
    response = self.process_exception_by_middleware(e, request)
  File "C:\Python\Webproject\share2\env\lib\site-packages\django\core\handlers\base.py", line 126, in _get_response
    response = wrapped_callback(request, *callback_args, **callback_kwargs)
  File "C:\Python\Webproject\share2\env\lib\site-packages\django\views\generic\base.py", line 69, in view
    return self.dispatch(request, *args, **kwargs)
  File "C:\Python\Webproject\share2\env\lib\site-packages\django\utils\decorators.py", line 62, in _wrapper
    return bound_func(*args, **kwargs)
  File "C:\Python\Webproject\share2\env\lib\site-packages\django\contrib\auth\decorators.py", line 21, in _wrapped_view
    return view_func(request, *args, **kwargs)
  File "C:\Python\Webproject\share2\env\lib\site-packages\django\utils\decorators.py", line 58, in bound_func
    return func.__get__(self, type(self))(*args2, **kwargs2)
  File "C:\Python\Webproject\share2\share2\share2\apps\utils\mixin_utils.py", line 14, in dispatch
    return super(LoginRequiredMixin, self).dispatch(request, *args, **kwargs)
  File "C:\Python\Webproject\share2\env\lib\site-packages\django\views\generic\base.py", line 89, in dispatch
    return handler(request, *args, **kwargs)
  File "C:\Python\Webproject\share2\share2\share2\apps\sharefile\views\AddfileView.py", line 142, in post
    file_dep.dep = dep_obj
  File "C:\Python\Webproject\share2\env\lib\site-packages\django\db\models\fields\related_descriptors.py", line 197, in __set__
    self.field.remote_field.model._meta.object_name,
ValueError: Cannot assign "<QuerySet [<Dep: ²ÆÎñ²¿>]>": "File2DepModel.dep" must be a "Dep" instance.
